Workbook

Sheet Porovnavanie hod
C1: Dátum | D1: Čas | E1: Plán sieť [kWh] | F1: Skutočnosť sieť [kWh] | G1: Marič [kWh] | H1: Plán EE [MW] | I1: Skutočnosť EE [MW] | J1: Cena SK (EUR/MWh) | K1: Tržby výroba EE | L1: Táto farba znamená plán
L2: Táto farba znamená skutočnosť
L3: Zobchodované na intraday
L4: Zmena plánu oproti pôvodnému | M4: Plán EE pôvodný | N4: Zobchodnovanie na intraday
C5: ='Predikcia hod'!A3 -> 45748 | D5: ='Predikcia hod'!B3 -> 00:00:00 | E5: ='Predikcia hod'!G3 -> 2257 | F5: ='DHS2025'!C2 -> 0 | G5: ='DHS2025'!D2 -> 0 | I5: ='DHS2025'!E2/1000 -> 0 | J5: ='Predikcia hod'!R3 -> 0 | K5: =(J5*0.99-1.9)*I5 -> 0 | M5: ='Predikcia hod'!K3 -> 1
C6: ='Predikcia hod'!A4 -> 45748 | D6: ='Predikcia hod'!B4 -> 01:00:00 | E6: ='Predikcia hod'!G4 -> 2222.75 | F6: ='DHS2025'!C3 -> 0 | G6: ='DHS2025'!D3 -> 0 | I6: ='DHS2025'!E3/1000 -> 0 | J6: ='Predikcia hod'!R4 -> 0 | K6: =(J6*0.99-1.9)*I6 -> 0 | M6: ='Predikcia hod'!K4 -> 1
C7: ='Predikcia hod'!A5 -> 45748 | D7: ='Predikcia hod'!B5 -> 02:00:00 | E7: ='Predikcia hod'!G5 -> 2270.75 | F7: ='DHS2025'!C4 -> 0 | G7: ='DHS2025'!D4 -> 0 | I7: ='DHS2025'!E4/1000 -> 0 | J7: ='Predikcia hod'!R5 -> 0 | K7: =(J7*0.99-1.9)*I7 -> 0 | M7: ='Predikcia hod'!K5 -> 1
C8: ='Predikcia hod'!A6 -> 45748 | D8: ='Predikcia hod'!B6 -> 03:00:00 | E8: ='Predikcia hod'!G6 -> 2657.75 | F8: ='DHS2025'!C5 -> 0 | G8: ='DHS2025'!D5 -> 0 | I8: ='DHS2025'!E5/1000 -> 0 | J8: ='Predikcia hod'!R6 -> 0 | K8: =(J8*0.99-1.9)*I8 -> 0 | M8: ='Predikcia hod'!K6 -> 1
C9: ='Predikcia hod'!A7 -> 45748 | D9: ='Predikcia hod'!B7 -> 04:00:00 | E9: ='Predikcia hod'!G7 -> 7543.75 | F9: ='DHS2025'!C6 -> 0 | G9: ='DHS2025'!D6 -> 0 | I9: ='DHS2025'!E6/1000 -> 0 | J9: ='Predikcia hod'!R7 -> 0 | K9: =(J9*0.99-1.9)*I9 -> 0 | M9: ='Predikcia hod'!K7 -> 3
C10: ='Predikcia hod'!A8 -> 45748 | D10: ='Predikcia hod'!B8 -> 05:00:00 | E10: ='Predikcia hod'!G8 -> 13018.25 | F10: ='DHS2025'!C7 -> 0 | G10: ='DHS2025'!D7 -> 0 | I10: ='DHS2025'!E7/1000 -> 0 | J10: ='Predikcia hod'!R8 -> 0 | K10: =(J10*0.99-1.9)*I10 -> 0 | M10: ='Predikcia hod'!K8 -> 5
C11: ='Predikcia hod'!A9 -> 45748 | D11: ='Predikcia hod'!B9 -> 06:00:00 | E11: ='Predikcia hod'!G9 -> 11879 | F11: ='DHS2025'!C8 -> 0 | G11: ='DHS2025'!D8 -> 0 | I11: ='DHS2025'!E8/1000 -> 0 | J11: ='Predikcia hod'!R9 -> 0 | K11: =(J11*0.99-1.9)*I11 -> 0 | M11: ='Predikcia hod'!K9 -> 4
C12: ='Predikcia hod'!A10 -> 45748 | D12: ='Predikcia hod'!B10 -> 07:00:00 | E12: ='Predikcia hod'!G10 -> 10703.5 | F12: ='DHS2025'!C9 -> 0 | G12: ='DHS2025'!D9 -> 0 | I12: ='DHS2025'!E9/1000 -> 0 | J12: ='Predikcia hod'!R10 -> 0 | K12: =(J12*0.99-1.9)*I12 -> 0 | M12: ='Predikcia hod'!K10 -> 4
C13: ='Predikcia hod'!A11 -> 45748 | D13: ='Predikcia hod'!B11 -> 08:00:00 | E13: ='Predikcia hod'!G11 -> 9836.5 | F13: ='DHS2025'!C10 -> 0 | G13: ='DHS2025'!D10 -> 0 | I13: ='DHS2025'!E10/1000 -> 0 | J13: ='Predikcia hod'!R11 -> 0 | K13: =(J13*0.99-1.9)*I13 -> 0 | M13: ='Predikcia hod'!K11 -> 4
C14: ='Predikcia hod'!A12 -> 45748 | D14: ='Predikcia hod'!B12 -> 09:00:00 | E14: ='Predikcia hod'!G12 -> 9773.25 | F14: ='DHS2025'!C11 -> 0 | G14: ='DHS2025'!D11 -> 0 | I14: ='DHS2025'!E11/1000 -> 0 | J14: ='Predikcia hod'!R12 -> 0 | K14: =(J14*0.99-1.9)*I14 -> 0 | M14: ='Predikcia hod'!K12 -> 4
C15: ='Predikcia hod'!A13 -> 45748 | D15: ='Predikcia hod'!B13 -> 10:00:00 | E15: ='Predikcia hod'!G13 -> 9351.5 | F15: ='DHS2025'!C12 -> 0 | G15: ='DHS2025'!D12 -> 0 | I15: ='DHS2025'!E12/1000 -> 0 | J15: ='Predikcia hod'!R13 -> 0 | K15: =(J15*0.99-1.9)*I15 -> 0 | M15: ='Predikcia hod'!K13 -> 4
C16: ='Predikcia hod'!A14 -> 45748 | D16: ='Predikcia hod'!B14 -> 11:00:00 | E16: ='Predikcia hod'!G14 -> 8746 | F16: ='DHS2025'!C13 -> 0 | G16: ='DHS2025'!D13 -> 0 | I16: ='DHS2025'!E13/1000 -> 0 | J16: ='Predikcia hod'!R14 -> 0 | K16: =(J16*0.99-1.9)*I16 -> 0 | M16: ='Predikcia hod'!K14 -> 3
... C724: ='Predikcia hod'!A722 -> 45777 | D724: ='Predikcia hod'!B722 -> 23:00:00 | E724: ='Predikcia hod'!G722 -> 4662.25 | F724: ='DHS2025'!C721 -> 0 | G724: ='DHS2025'!D721 -> 0 | I724: ='DHS2025'!E721/1000 -> 0 | J724: ='Predikcia hod'!R722 -> 0 | K724: =(J724*0.99-1.9)*I724 -> 0 | M724: ='Predikcia hod'!K722 -> 2
K725: =SUM(K5:K724) -> 0

Sheet Porovnavanie 15min
C1: Dátum | D1: Čas | E1: Plán sieť [kW/15min] | F1: Skutočnosť sieť [kW/15min] | G1: Marič [kW/15min] | H1: Plán EE [MW] | I1: Skutočnosť EE [MW] | J1: Cena SK (EUR/MW/15min) | K1: Tržby výroba EE | L1: Táto farba znamená plán
L2: Táto farba znamená skutočnosť
L3: Zobchodované na intraday
L4: Zmena plánu oproti pôvodnému
L5: Použitie redučky/bypasu | M5: Plán EE pôvodný | N5: Zobchodnovanie na intraday
C6: ='Predikcia 15min'!A3 -> 45748 | D6: ='Predikcia 15min'!B3 -> 00:00:00 | E6: ='Predikcia 15min'!G3 -> 2257 | F6: ='Predikcia 15min'!O3 -> 2506 | G6: ='Predikcia 15min'!P3 -> 6321 | H6: 2 | I6: ='DHS2025'!L2/1000 -> 2.05 | J6: ='Predikcia 15min'!R3 -> 102.23 | K6: =(J6*0.99-1.9)*I6 -> 203.58078 | M6: ='Predikcia 15min'!K3 -> 1 | N6: 2
C7: ='Predikcia 15min'!A4 -> 45748 | D7: ='Predikcia 15min'!B4 -> 0.010416667 | E7: ='Predikcia 15min'!G4 -> 2300.5 | F7: ='Predikcia 15min'!O4 -> 1888 | G7: ='Predikcia 15min'!P4 -> 6043 | H7: 2 | I7: ='DHS2025'!L3/1000 -> 2.049 | J7: ='Predikcia 15min'!R4 -> 102.23 | K7: =(J7*0.99-1.9)*I7 -> 203.48148 | M7: ='Predikcia 15min'!K4 -> 1 | N7: 2
C8: ='Predikcia 15min'!A5 -> 45748 | D8: ='Predikcia 15min'!B5 -> 0.020833333 | E8: ='Predikcia 15min'!G5 -> 2170 | F8: ='Predikcia 15min'!O5 -> 1943 | G8: ='Predikcia 15min'!P5 -> 6585 | H8: 2 | I8: ='DHS2025'!L4/1000 -> 2.056 | J8: ='Predikcia 15min'!R5 -> 102.23 | K8: =(J8*0.99-1.9)*I8 -> 204.17663 | M8: ='Predikcia 15min'!K5 -> 1 | N8: 2
C9: ='Predikcia 15min'!A6 -> 45748 | D9: ='Predikcia 15min'!B6 -> 0.03125 | E9: ='Predikcia 15min'!G6 -> 2201.5 | F9: ='Predikcia 15min'!O6 -> 1889 | G9: ='Predikcia 15min'!P6 -> 6274 | H9: 2 | I9: ='DHS2025'!L5/1000 -> 2.054 | J9: ='Predikcia 15min'!R6 -> 102.23 | K9: =(J9*0.99-1.9)*I9 -> 203.97802 | M9: ='Predikcia 15min'!K6 -> 1 | N9: 2
C10: ='Predikcia 15min'!A7 -> 45748 | D10: ='Predikcia 15min'!B7 -> 0.041666667 | E10: ='Predikcia 15min'!G7 -> 2222.75 | F10: ='Predikcia 15min'!O7 -> 1683 | G10: ='Predikcia 15min'!P7 -> 6122 | H10: 2 | I10: ='DHS2025'!L6/1000 -> 2.034 | J10: ='Predikcia 15min'!R7 -> 96.15 | K10: =(J10*0.99-1.9)*I10 -> 189.74881 | M10: ='Predikcia 15min'!K7 -> 1 | N10: 2
C11: ='Predikcia 15min'!A8 -> 45748 | D11: ='Predikcia 15min'!B8 -> 0.052083333 | E11: ='Predikcia 15min'!G8 -> 2297 | F11: ='Predikcia 15min'!O8 -> 1530 | G11: ='Predikcia 15min'!P8 -> 6689 | H11: 2 | I11: ='DHS2025'!L7/1000 -> 2.054 | J11: ='Predikcia 15min'!R8 -> 96.15 | K11: =(J11*0.99-1.9)*I11 -> 191.61458 | M11: ='Predikcia 15min'!K8 -> 1 | N11: 2
C12: ='Predikcia 15min'!A9 -> 45748 | D12: ='Predikcia 15min'!B9 -> 0.0625 | E12: ='Predikcia 15min'!G9 -> 2194.25 | F12: ='Predikcia 15min'!O9 -> 1591 | G12: ='Predikcia 15min'!P9 -> 6682 | H12: 2 | I12: ='DHS2025'!L8/1000 -> 2.065 | J12: ='Predikcia 15min'!R9 -> 96.15 | K12: =(J12*0.99-1.9)*I12 -> 192.64075 | M12: ='Predikcia 15min'!K9 -> 1 | N12: 2
C13: ='Predikcia 15min'!A10 -> 45748 | D13: ='Predikcia 15min'!B10 -> 0.072916667 | E13: ='Predikcia 15min'!G10 -> 2272.25 | F13: ='Predikcia 15min'!O10 -> 1813 | G13: ='Predikcia 15min'!P10 -> 6415 | H13: 2 | I13: ='DHS2025'!L9/1000 -> 2.048 | J13: ='Predikcia 15min'!R10 -> 96.15 | K13: =(J13*0.99-1.9)*I13 -> 191.05485 | M13: ='Predikcia 15min'!K10 -> 1 | N13: 2
C14: ='Predikcia 15min'!A11 -> 45748 | D14: ='Predikcia 15min'!B11 -> 0.083333333 | E14: ='Predikcia 15min'!G11 -> 2270.75 | F14: ='Predikcia 15min'!O11 -> 1697 | G14: ='Predikcia 15min'!P11 -> 6343 | H14: 2 | I14: ='DHS2025'!L10/1000 -> 2.039 | J14: ='Predikcia 15min'!R11 -> 94.17 | K14: =(J14*0.99-1.9)*I14 -> 186.2184 | M14: ='Predikcia 15min'!K11 -> 1 | N14: 2
C15: ='Predikcia 15min'!A12 -> 45748 | D15: ='Predikcia 15min'!B12 -> 0.09375 | E15: ='Predikcia 15min'!G12 -> 2119 | F15: ='Predikcia 15min'!O12 -> 1797 | G15: ='Predikcia 15min'!P12 -> 6549 | H15: 2 | I15: ='DHS2025'!L11/1000 -> 2.049 | J15: ='Predikcia 15min'!R12 -> 94.17 | K15: =(J15*0.99-1.9)*I15 -> 187.13169 | M15: ='Predikcia 15min'!K12 -> 1 | N15: 2
C16: ='Predikcia 15min'!A13 -> 45748 | D16: ='Predikcia 15min'!B13 -> 0.10416667 | E16: ='Predikcia 15min'!G13 -> 2339 | F16: ='Predikcia 15min'!O13 -> 2065 | G16: ='Predikcia 15min'!P13 -> 6433 | H16: 2 | I16: ='DHS2025'!L12/1000 -> 2.055 | J16: ='Predikcia 15min'!R13 -> 94.17 | K16: =(J16*0.99-1.9)*I16 -> 187.67966 | M16: ='Predikcia 15min'!K13 -> 1 | N16: 2
C17: ='Predikcia 15min'!A14 -> 45748 | D17: ='Predikcia 15min'!B14 -> 0.11458333 | E17: ='Predikcia 15min'!G14 -> 2507 | F17: ='Predikcia 15min'!O14 -> 2190 | G17: ='Predikcia 15min'!P14 -> 5808 | H17: 2 | I17: ='DHS2025'!L13/1000 -> 2.043 | J17: ='Predikcia 15min'!R14 -> 94.17 | K17: =(J17*0.99-1.9)*I17 -> 186.58372 | M17: ='Predikcia 15min'!K14 -> 1 | N17: 2
... C2885: ='Predikcia 15min'!A2882 -> 45777 | D2885: ='Predikcia 15min'!B2882 -> 29.989583 | E2885: ='Predikcia 15min'!G2882 -> 2060.5 | F2885: ='Predikcia 15min'!O2882 -> 1473 | G2885: ='Predikcia 15min'!P2882 -> 4037 | H2885: 1 | I2885: ='DHS2025'!L2881/1000 -> 1.041 | J2885: ='Predikcia 15min'!R2882 -> 99.36 | K2885: =(J2885*0.99-1.9)*I2885 -> 100.42152 | M2885: ='Predikcia 15min'!K2882 -> 1 | N2885: 1

Sheet Predikcia hod
N1: Marič | O1: 2025 Skutočnosť
A2: $Date | B2: $Time | C2: 2021 | D2: 2022 | E2: 2023 | F2: 2024 | G2: Ø | H2: MW EE | I2: Marič | J2: ∑ | K2: PLÁN | L2: koef | M2: 3 | N2: 0 | O2: Sieť [kWh] | P2: Marič [kWh] | Q2: EE [kW] | R2: Cena SK (EUR/MWh) | S2: Tržby výroba EE
A3: 45748 | B3: 00:00:00 | C3: ='DHS2021'!C2 -> 1657 | D3: ='DHS2022'!C2 -> 3209 | E3: ='DHS2023'!C2 -> 2507 | F3: ='DHS2024'!C2 -> 1655 | G3: =AVERAGE(C3:F3) -> 2257 | H3: =G3/$M$2/1000 -> 0.75233333 | I3: =$N$2 -> 0 | J3: =H3+I3 -> 0.75233333 | K3: =ROUNDUP(J3,0) -> 1 | O3: ='DHS2025'!C2 -> 0 | P3: ='DHS2025'!D2 -> 0 | Q3: ='DHS2025'!E2 -> 0
A4: =$A$3+INT((ROW()-3)/24) -> 45748 | B4: 01:00:00 | C4: ='DHS2021'!C3 -> 1445 | D4: ='DHS2022'!C3 -> 3451 | E4: ='DHS2023'!C3 -> 2258 | F4: ='DHS2024'!C3 -> 1737 | G4: =AVERAGE(C4:F4) -> 2222.75 | H4: =G4/$M$2/1000 -> 0.74091667 | I4: =$N$2 -> 0 | J4: =H4+I4 -> 0.74091667 | K4: =ROUNDUP(J4,0) -> 1 | O4: ='DHS2025'!C3 -> 0 | P4: ='DHS2025'!D3 -> 0 | Q4: ='DHS2025'!E3 -> 0
A5: =$A$3+INT((ROW()-3)/24) -> 45748 | B5: 02:00:00 | C5: ='DHS2021'!C4 -> 1230 | D5: ='DHS2022'!C4 -> 3073 | E5: ='DHS2023'!C4 -> 2473 | F5: ='DHS2024'!C4 -> 2307 | G5: =AVERAGE(C5:F5) -> 2270.75 | H5: =G5/$M$2/1000 -> 0.75691667 | I5: =$N$2 -> 0 | J5: =H5+I5 -> 0.75691667 | K5: =ROUNDUP(J5,0) -> 1 | O5: ='DHS2025'!C4 -> 0 | P5: ='DHS2025'!D4 -> 0 | Q5: ='DHS2025'!E4 -> 0
A6: =$A$3+INT((ROW()-3)/24) -> 45748 | B6: 03:00:00 | C6: ='DHS2021'!C5 -> 1583 | D6: ='DHS2022'!C5 -> 3873 | E6: ='DHS2023'!C5 -> 2922 | F6: ='DHS2024'!C5 -> 2253 | G6: =AVERAGE(C6:F6) -> 2657.75 | H6: =G6/$M$2/1000 -> 0.88591667 | I6: =$N$2 -> 0 | J6: =H6+I6 -> 0.88591667 | K6: =ROUNDUP(J6,0) -> 1 | O6: ='DHS2025'!C5 -> 0 | P6: ='DHS2025'!D5 -> 0 | Q6: ='DHS2025'!E5 -> 0
A7: =$A$3+INT((ROW()-3)/24) -> 45748 | B7: 04:00:00 | C7: ='DHS2021'!C6 -> 6606 | D7: ='DHS2022'!C6 -> 12762 | E7: ='DHS2023'!C6 -> 6803 | F7: ='DHS2024'!C6 -> 4004 | G7: =AVERAGE(C7:F7) -> 7543.75 | H7: =G7/$M$2/1000 -> 2.5145833 | I7: =$N$2 -> 0 | J7: =H7+I7 -> 2.5145833 | K7: =ROUNDUP(J7,0) -> 3 | O7: ='DHS2025'!C6 -> 0 | P7: ='DHS2025'!D6 -> 0 | Q7: ='DHS2025'!E6 -> 0
A8: =$A$3+INT((ROW()-3)/24) -> 45748 | B8: 05:00:00 | C8: ='DHS2021'!C7 -> 14010 | D8: ='DHS2022'!C7 -> 17649 | E8: ='DHS2023'!C7 -> 12061 | F8: ='DHS2024'!C7 -> 8353 | G8: =AVERAGE(C8:F8) -> 13018.25 | H8: =G8/$M$2/1000 -> 4.3394167 | I8: =$N$2 -> 0 | J8: =H8+I8 -> 4.3394167 | K8: =ROUNDUP(J8,0) -> 5 | O8: ='DHS2025'!C7 -> 0 | P8: ='DHS2025'!D7 -> 0 | Q8: ='DHS2025'!E7 -> 0
A9: =$A$3+INT((ROW()-3)/24) -> 45748 | B9: 06:00:00 | C9: ='DHS2021'!C8 -> 14744 | D9: ='DHS2022'!C8 -> 14159 | E9: ='DHS2023'!C8 -> 12826 | F9: ='DHS2024'!C8 -> 5787 | G9: =AVERAGE(C9:F9) -> 11879 | H9: =G9/$M$2/1000 -> 3.9596667 | I9: =$N$2 -> 0 | J9: =H9+I9 -> 3.9596667 | K9: =ROUNDUP(J9,0) -> 4 | O9: ='DHS2025'!C8 -> 0 | P9: ='DHS2025'!D8 -> 0 | Q9: ='DHS2025'!E8 -> 0
A10: =$A$3+INT((ROW()-3)/24) -> 45748 | B10: 07:00:00 | C10: ='DHS2021'!C9 -> 11320 | D10: ='DHS2022'!C9 -> 14095 | E10: ='DHS2023'!C9 -> 12762 | F10: ='DHS2024'!C9 -> 4637 | G10: =AVERAGE(C10:F10) -> 10703.5 | H10: =G10/$M$2/1000 -> 3.5678333 | I10: =$N$2 -> 0 | J10: =H10+I10 -> 3.5678333 | K10: =ROUNDUP(J10,0) -> 4 | O10: ='DHS2025'!C9 -> 0 | P10: ='DHS2025'!D9 -> 0 | Q10: ='DHS2025'!E9 -> 0
A11: =$A$3+INT((ROW()-3)/24) -> 45748 | B11: 08:00:00 | C11: ='DHS2021'!C10 -> 10554 | D11: ='DHS2022'!C10 -> 13234 | E11: ='DHS2023'!C10 -> 10405 | F11: ='DHS2024'!C10 -> 5153 | G11: =AVERAGE(C11:F11) -> 9836.5 | H11: =G11/$M$2/1000 -> 3.2788333 | I11: =$N$2 -> 0 | J11: =H11+I11 -> 3.2788333 | K11: =ROUNDUP(J11,0) -> 4 | O11: ='DHS2025'!C10 -> 0 | P11: ='DHS2025'!D10 -> 0 | Q11: ='DHS2025'!E10 -> 0
A12: =$A$3+INT((ROW()-3)/24) -> 45748 | B12: 09:00:00 | C12: ='DHS2021'!C11 -> 9617 | D12: ='DHS2022'!C11 -> 13413 | E12: ='DHS2023'!C11 -> 11345 | F12: ='DHS2024'!C11 -> 4718 | G12: =AVERAGE(C12:F12) -> 9773.25 | H12: =G12/$M$2/1000 -> 3.25775 | I12: =$N$2 -> 0 | J12: =H12+I12 -> 3.25775 | K12: =ROUNDUP(J12,0) -> 4 | O12: ='DHS2025'!C11 -> 0 | P12: ='DHS2025'!D11 -> 0 | Q12: ='DHS2025'!E11 -> 0
A13: =$A$3+INT((ROW()-3)/24) -> 45748 | B13: 10:00:00 | C13: ='DHS2021'!C12 -> 8993 | D13: ='DHS2022'!C12 -> 13639 | E13: ='DHS2023'!C12 -> 10337 | F13: ='DHS2024'!C12 -> 4437 | G13: =AVERAGE(C13:F13) -> 9351.5 | H13: =G13/$M$2/1000 -> 3.1171667 | I13: =$N$2 -> 0 | J13: =H13+I13 -> 3.1171667 | K13: =ROUNDUP(J13,0) -> 4 | O13: ='DHS2025'!C12 -> 0 | P13: ='DHS2025'!D12 -> 0 | Q13: ='DHS2025'!E12 -> 0
A14: =$A$3+INT((ROW()-3)/24) -> 45748 | B14: 11:00:00 | C14: ='DHS2021'!C13 -> 8305 | D14: ='DHS2022'!C13 -> 12322 | E14: ='DHS2023'!C13 -> 9369 | F14: ='DHS2024'!C13 -> 4988 | G14: =AVERAGE(C14:F14) -> 8746 | H14: =G14/$M$2/1000 -> 2.9153333 | I14: =$N$2 -> 0 | J14: =H14+I14 -> 2.9153333 | K14: =ROUNDUP(J14,0) -> 3 | O14: ='DHS2025'!C13 -> 0 | P14: ='DHS2025'!D13 -> 0 | Q14: ='DHS2025'!E13 -> 0
A15: =$A$3+INT((ROW()-3)/24) -> 45748 | B15: 12:00:00 | C15: ='DHS2021'!C14 -> 6816 | D15: ='DHS2022'!C14 -> 12505 | E15: ='DHS2023'!C14 -> 9276 | F15: ='DHS2024'!C14 -> 4533 | G15: =AVERAGE(C15:F15) -> 8282.5 | H15: =G15/$M$2/1000 -> 2.7608333 | I15: =$N$2 -> 0 | J15: =H15+I15 -> 2.7608333 | K15: =ROUNDUP(J15,0) -> 3 | O15: ='DHS2025'!C14 -> 0 | P15: ='DHS2025'!D14 -> 0 | Q15: ='DHS2025'!E14 -> 0
... A722: =$A$3+INT((ROW()-3)/24) -> 45777 | B722: 23:00:00 | C722: ='DHS2021'!C721 -> 5856 | D722: ='DHS2022'!C721 -> 3819 | E722: ='DHS2023'!C721 -> 4325 | F722: ='DHS2024'!C721 -> 4649 | G722: =AVERAGE(C722:F722) -> 4662.25 | H722: =G722/$M$2/1000 -> 1.5540833 | I722: =$N$2 -> 0 | J722: =H722+I722 -> 1.5540833 | K722: =ROUNDUP(J722,0) -> 2 | O722: ='DHS2025'!C721 -> 0 | P722: ='DHS2025'!D721 -> 0 | Q722: ='DHS2025'!E721 -> 0
G723: =SUM(G3:G722)/1000 -> 6414.2225 | H723: =SUM(H3:H722) -> 2138.0742 | I723: =SUM(I3:I722) -> 0 | J723: =SUM(J3:J722) -> 2138.0742 | K723: =SUM(K3:K722) -> 2496 | S723: =SUM(S3:S722) -> 0

Sheet Predikcia 15min
N1: Marič | O1: 2025 Skutočnosť
A2: $Date | B2: $Time | C2: 2021 | D2: 2022 | E2: 2023 | F2: 2024 | G2: Ø | H2: MW EE | I2: Marič | J2: ∑ | K2: PLÁN | L2: koef | M2: 3 | N2: 0 | O2: Sieť [kWh] | P2: Marič [kWh] | Q2: EE [kW] | R2: Cena SK (EUR/MWh) | S2: Tržby výroba EE | U2: Cena EE v hodinovom intervale
A3: 45748 | B3: 00:00:00 | C3: ='DHS2021'!J2 -> 1657 | D3: ='DHS2022'!J2 -> 3209 | E3: ='DHS2023'!J2 -> 2507 | F3: ='DHS2024'!J2 -> 1655 | G3: =AVERAGE(C3:F3) -> 2257 | H3: =G3/$M$2/1000 -> 0.75233333 | I3: =$N$2 -> 0 | J3: =H3+I3 -> 0.75233333 | K3: =ROUNDUP(J3,0) -> 1 | O3: ='DHS2025'!J2 -> 2506 | P3: ='DHS2025'!K2 -> 6321 | Q3: ='DHS2025'!L2 -> 2050 | R3: =INDEX(U$3:U$1048576,INT((ROW()-3)/4)+1) -> 102.23 | S3: =(R3*0.99-1.9)*(Q3/1000) -> 203.58078 | U3: 102.23
A4: =$A$3+INT((ROW()-3)/96) -> 45748 | B4: =B3+TIME(0,15,0) -> 0.010416667 | C4: ='DHS2021'!J3 -> 1733 | D4: ='DHS2022'!J3 -> 3482 | E4: ='DHS2023'!J3 -> 2361 | F4: ='DHS2024'!J3 -> 1626 | G4: =AVERAGE(C4:F4) -> 2300.5 | H4: =G4/$M$2/1000 -> 0.76683333 | I4: =$N$2 -> 0 | J4: =H4+I4 -> 0.76683333 | K4: =ROUNDUP(J4,0) -> 1 | O4: ='DHS2025'!J3 -> 1888 | P4: ='DHS2025'!K3 -> 6043 | Q4: ='DHS2025'!L3 -> 2049 | R4: =INDEX(U$3:U$1048576,INT((ROW()-3)/4)+1) -> 102.23 | S4: =(R4*0.99-1.9)*(Q4/1000) -> 203.48148 | U4: 96.15
A5: =$A$3+INT((ROW()-3)/96) -> 45748 | B5: =B4+TIME(0,15,0) -> 0.020833333 | C5: ='DHS2021'!J4 -> 1489 | D5: ='DHS2022'!J4 -> 3483 | E5: ='DHS2023'!J4 -> 1995 | F5: ='DHS2024'!J4 -> 1713 | G5: =AVERAGE(C5:F5) -> 2170 | H5: =G5/$M$2/1000 -> 0.72333333 | I5: =$N$2 -> 0 | J5: =H5+I5 -> 0.72333333 | K5: =ROUNDUP(J5,0) -> 1 | O5: ='DHS2025'!J4 -> 1943 | P5: ='DHS2025'!K4 -> 6585 | Q5: ='DHS2025'!L4 -> 2056 | R5: =INDEX(U$3:U$1048576,INT((ROW()-3)/4)+1) -> 102.23 | S5: =(R5*0.99-1.9)*(Q5/1000) -> 204.17663 | U5: 94.17
A6: =$A$3+INT((ROW()-3)/96) -> 45748 | B6: =B5+TIME(0,15,0) -> 0.03125 | C6: ='DHS2021'!J5 -> 1336 | D6: ='DHS2022'!J5 -> 3404 | E6: ='DHS2023'!J5 -> 2213 | F6: ='DHS2024'!J5 -> 1853 | G6: =AVERAGE(C6:F6) -> 2201.5 | H6: =G6/$M$2/1000 -> 0.73383333 | I6: =$N$2 -> 0 | J6: =H6+I6 -> 0.73383333 | K6: =ROUNDUP(J6,0) -> 1 | O6: ='DHS2025'!J5 -> 1889 | P6: ='DHS2025'!K5 -> 6274 | Q6: ='DHS2025'!L5 -> 2054 | R6: =INDEX(U$3:U$1048576,INT((ROW()-3)/4)+1) -> 102.23 | S6: =(R6*0.99-1.9)*(Q6/1000) -> 203.97802 | U6: 95.33
A7: =$A$3+INT((ROW()-3)/96) -> 45748 | B7: =B6+TIME(0,15,0) -> 0.041666667 | C7: ='DHS2021'!J6 -> 1445 | D7: ='DHS2022'!J6 -> 3451 | E7: ='DHS2023'!J6 -> 2258 | F7: ='DHS2024'!J6 -> 1737 | G7: =AVERAGE(C7:F7) -> 2222.75 | H7: =G7/$M$2/1000 -> 0.74091667 | I7: =$N$2 -> 0 | J7: =H7+I7 -> 0.74091667 | K7: =ROUNDUP(J7,0) -> 1 | O7: ='DHS2025'!J6 -> 1683 | P7: ='DHS2025'!K6 -> 6122 | Q7: ='DHS2025'!L6 -> 2034 | R7: =INDEX(U$3:U$1048576,INT((ROW()-3)/4)+1) -> 96.15 | S7: =(R7*0.99-1.9)*(Q7/1000) -> 189.74881 | U7: 93.08
A8: =$A$3+INT((ROW()-3)/96) -> 45748 | B8: =B7+TIME(0,15,0) -> 0.052083333 | C8: ='DHS2021'!J7 -> 1355 | D8: ='DHS2022'!J7 -> 3532 | E8: ='DHS2023'!J7 -> 2284 | F8: ='DHS2024'!J7 -> 2017 | G8: =AVERAGE(C8:F8) -> 2297 | H8: =G8/$M$2/1000 -> 0.76566667 | I8: =$N$2 -> 0 | J8: =H8+I8 -> 0.76566667 | K8: =ROUNDUP(J8,0) -> 1 | O8: ='DHS2025'!J7 -> 1530 | P8: ='DHS2025'!K7 -> 6689 | Q8: ='DHS2025'!L7 -> 2054 | R8: =INDEX(U$3:U$1048576,INT((ROW()-3)/4)+1) -> 96.15 | S8: =(R8*0.99-1.9)*(Q8/1000) -> 191.61458 | U8: 102.58
A9: =$A$3+INT((ROW()-3)/96) -> 45748 | B9: =B8+TIME(0,15,0) -> 0.0625 | C9: ='DHS2021'!J8 -> 1261 | D9: ='DHS2022'!J8 -> 3651 | E9: ='DHS2023'!J8 -> 2327 | F9: ='DHS2024'!J8 -> 1538 | G9: =AVERAGE(C9:F9) -> 2194.25 | H9: =G9/$M$2/1000 -> 0.73141667 | I9: =$N$2 -> 0 | J9: =H9+I9 -> 0.73141667 | K9: =ROUNDUP(J9,0) -> 1 | O9: ='DHS2025'!J8 -> 1591 | P9: ='DHS2025'!K8 -> 6682 | Q9: ='DHS2025'!L8 -> 2065 | R9: =INDEX(U$3:U$1048576,INT((ROW()-3)/4)+1) -> 96.15 | S9: =(R9*0.99-1.9)*(Q9/1000) -> 192.64075 | U9: 131.44
A10: =$A$3+INT((ROW()-3)/96) -> 45748 | B10: =B9+TIME(0,15,0) -> 0.072916667 | C10: ='DHS2021'!J9 -> 1320 | D10: ='DHS2022'!J9 -> 3253 | E10: ='DHS2023'!J9 -> 2133 | F10: ='DHS2024'!J9 -> 2383 | G10: =AVERAGE(C10:F10) -> 2272.25 | H10: =G10/$M$2/1000 -> 0.75741667 | I10: =$N$2 -> 0 | J10: =H10+I10 -> 0.75741667 | K10: =ROUNDUP(J10,0) -> 1 | O10: ='DHS2025'!J9 -> 1813 | P10: ='DHS2025'!K9 -> 6415 | Q10: ='DHS2025'!L9 -> 2048 | R10: =INDEX(U$3:U$1048576,INT((ROW()-3)/4)+1) -> 96.15 | S10: =(R10*0.99-1.9)*(Q10/1000) -> 191.05485 | U10: 177.65
A11: =$A$3+INT((ROW()-3)/96) -> 45748 | B11: =B10+TIME(0,15,0) -> 0.083333333 | C11: ='DHS2021'!J10 -> 1230 | D11: ='DHS2022'!J10 -> 3073 | E11: ='DHS2023'!J10 -> 2473 | F11: ='DHS2024'!J10 -> 2307 | G11: =AVERAGE(C11:F11) -> 2270.75 | H11: =G11/$M$2/1000 -> 0.75691667 | I11: =$N$2 -> 0 | J11: =H11+I11 -> 0.75691667 | K11: =ROUNDUP(J11,0) -> 1 | O11: ='DHS2025'!J10 -> 1697 | P11: ='DHS2025'!K10 -> 6343 | Q11: ='DHS2025'!L10 -> 2039 | R11: =INDEX(U$3:U$1048576,INT((ROW()-3)/4)+1) -> 94.17 | S11: =(R11*0.99-1.9)*(Q11/1000) -> 186.2184 | U11: 159.37
A12: =$A$3+INT((ROW()-3)/96) -> 45748 | B12: =B11+TIME(0,15,0) -> 0.09375 | C12: ='DHS2021'!J11 -> 1165 | D12: ='DHS2022'!J11 -> 3411 | E12: ='DHS2023'!J11 -> 2158 | F12: ='DHS2024'!J11 -> 1742 | G12: =AVERAGE(C12:F12) -> 2119 | H12: =G12/$M$2/1000 -> 0.70633333 | I12: =$N$2 -> 0 | J12: =H12+I12 -> 0.70633333 | K12: =ROUNDUP(J12,0) -> 1 | O12: ='DHS2025'!J11 -> 1797 | P12: ='DHS2025'!K11 -> 6549 | Q12: ='DHS2025'!L11 -> 2049 | R12: =INDEX(U$3:U$1048576,INT((ROW()-3)/4)+1) -> 94.17 | S12: =(R12*0.99-1.9)*(Q12/1000) -> 187.13169 | U12: 109.59
A13: =$A$3+INT((ROW()-3)/96) -> 45748 | B13: =B12+TIME(0,15,0) -> 0.10416667 | C13: ='DHS2021'!J12 -> 1151 | D13: ='DHS2022'!J12 -> 3829 | E13: ='DHS2023'!J12 -> 2494 | F13: ='DHS2024'!J12 -> 1882 | G13: =AVERAGE(C13:F13) -> 2339 | H13: =G13/$M$2/1000 -> 0.77966667 | I13: =$N$2 -> 0 | J13: =H13+I13 -> 0.77966667 | K13: =ROUNDUP(J13,0) -> 1 | O13: ='DHS2025'!J12 -> 2065 | P13: ='DHS2025'!K12 -> 6433 | Q13: ='DHS2025'!L12 -> 2055 | R13: =INDEX(U$3:U$1048576,INT((ROW()-3)/4)+1) -> 94.17 | S13: =(R13*0.99-1.9)*(Q13/1000) -> 187.67966 | U13: 88.29
A14: =$A$3+INT((ROW()-3)/96) -> 45748 | B14: =B13+TIME(0,15,0) -> 0.11458333 | C14: ='DHS2021'!J13 -> 1157 | D14: ='DHS2022'!J13 -> 3502 | E14: ='DHS2023'!J13 -> 2780 | F14: ='DHS2024'!J13 -> 2589 | G14: =AVERAGE(C14:F14) -> 2507 | H14: =G14/$M$2/1000 -> 0.83566667 | I14: =$N$2 -> 0 | J14: =H14+I14 -> 0.83566667 | K14: =ROUNDUP(J14,0) -> 1 | O14: ='DHS2025'!J13 -> 2190 | P14: ='DHS2025'!K13 -> 5808 | Q14: ='DHS2025'!L13 -> 2043 | R14: =INDEX(U$3:U$1048576,INT((ROW()-3)/4)+1) -> 94.17 | S14: =(R14*0.99-1.9)*(Q14/1000) -> 186.58372 | U14: 75.04
A15: =$A$3+INT((ROW()-3)/96) -> 45748 | B15: =B14+TIME(0,15,0) -> 0.125 | C15: ='DHS2021'!J14 -> 1583 | D15: ='DHS2022'!J14 -> 3873 | E15: ='DHS2023'!J14 -> 2922 | F15: ='DHS2024'!J14 -> 2253 | G15: =AVERAGE(C15:F15) -> 2657.75 | H15: =G15/$M$2/1000 -> 0.88591667 | I15: =$N$2 -> 0 | J15: =H15+I15 -> 0.88591667 | K15: =ROUNDUP(J15,0) -> 1 | O15: ='DHS2025'!J14 -> 2389 | P15: ='DHS2025'!K14 -> 7491 | Q15: ='DHS2025'!L14 -> 2540 | R15: =INDEX(U$3:U$1048576,INT((ROW()-3)/4)+1) -> 95.33 | S15: =(R15*0.99-1.9)*(Q15/1000) -> 234.89082 | U15: 63
... A722: =$A$3+INT((ROW()-3)/96) -> 45755 | B722: =B721+TIME(0,15,0) -> 7.4895833 | C722: ='DHS2021'!J721 -> 13178 | D722: ='DHS2022'!J721 -> 8504 | E722: ='DHS2023'!J721 -> 11980 | F722: ='DHS2024'!J721 -> 4801 | G722: =AVERAGE(C722:F722) -> 9615.75 | H722: =G722/$M$2/1000 -> 3.20525 | I722: =$N$2 -> 0 | J722: =H722+I722 -> 3.20525 | K722: =ROUNDUP(J722,0) -> 4 | O722: ='DHS2025'!J721 -> 10901 | P722: ='DHS2025'!K721 -> 156 | Q722: ='DHS2025'!L721 -> 3064 | R722: =INDEX(U$3:U$1048576,INT((ROW()-3)/4)+1) -> 66.5 | S722: =(R722*0.99-1.9)*(Q722/1000) -> 195.89684 | U722: 99.36
A723: =$A$3+INT((ROW()-3)/96) -> 45755 | B723: =B722+TIME(0,15,0) -> 7.5 | C723: ='DHS2021'!J722 -> 12635 | D723: ='DHS2022'!J722 -> 7796 | E723: ='DHS2023'!J722 -> 12124 | F723: ='DHS2024'!J722 -> 3920 | G723: =AVERAGE(C723:F723) -> 9118.75 | H723: =G723/$M$2/1000 -> 3.0395833 | I723: =$N$2 -> 0 | J723: =H723+I723 -> 3.0395833 | K723: =ROUNDUP(J723,0) -> 4 | O723: ='DHS2025'!J722 -> 10686 | P723: ='DHS2025'!K722 -> 67 | Q723: ='DHS2025'!L722 -> 3052 | R723: =INDEX(U$3:U$1048576,INT((ROW()-3)/4)+1) -> 15.61 | S723: =(R723*0.99-1.9)*(Q723/1000) -> 41.366503
A724: =$A$3+INT((ROW()-3)/96) -> 45755 | B724: =B723+TIME(0,15,0) -> 7.5104167 | C724: ='DHS2021'!J723 -> 12244 | D724: ='DHS2022'!J723 -> 7762 | E724: ='DHS2023'!J723 -> 11880 | F724: ='DHS2024'!J723 -> 3069 | G724: =AVERAGE(C724:F724) -> 8738.75 | H724: =G724/$M$2/1000 -> 2.9129167 | I724: =$N$2 -> 0 | J724: =H724+I724 -> 2.9129167 | K724: =ROUNDUP(J724,0) -> 3 | O724: ='DHS2025'!J723 -> 10939 | P724: ='DHS2025'!K723 -> 95 | Q724: ='DHS2025'!L723 -> 3056 | R724: =INDEX(U$3:U$1048576,INT((ROW()-3)/4)+1) -> 15.61 | S724: =(R724*0.99-1.9)*(Q724/1000) -> 41.420718
A725: =$A$3+INT((ROW()-3)/96) -> 45755 | B725: =B724+TIME(0,15,0) -> 7.5208333 | C725: ='DHS2021'!J724 -> 11832 | D725: ='DHS2022'!J724 -> 7734 | E725: ='DHS2023'!J724 -> 11759 | F725: ='DHS2024'!J724 -> 3025 | G725: =AVERAGE(C725:F725) -> 8587.5 | H725: =G725/$M$2/1000 -> 2.8625 | I725: =$N$2 -> 0 | J725: =H725+I725 -> 2.8625 | K725: =ROUNDUP(J725,0) -> 3 | O725: ='DHS2025'!J724 -> 10831 | P725: ='DHS2025'!K724 -> 151 | Q725: ='DHS2025'!L724 -> 3049 | R725: =INDEX(U$3:U$1048576,INT((ROW()-3)/4)+1) -> 15.61 | S725: =(R725*0.99-1.9)*(Q725/1000) -> 41.325841
A726: =$A$3+INT((ROW()-3)/96) -> 45755 | B726: =B725+TIME(0,15,0) -> 7.53125 | C726: ='DHS2021'!J725 -> 12042 | D726: ='DHS2022'!J725 -> 7999 | E726: ='DHS2023'!J725 -> 11627 | F726: ='DHS2024'!J725 -> 3450 | G726: =AVERAGE(C726:F726) -> 8779.5 | H726: =G726/$M$2/1000 -> 2.9265 | I726: =$N$2 -> 0 | J726: =H726+I726 -> 2.9265 | K726: =ROUNDUP(J726,0) -> 3 | O726: ='DHS2025'!J725 -> 10896 | P726: ='DHS2025'!K725 -> 27 | Q726: ='DHS2025'!L725 -> 3066 | R726: =INDEX(U$3:U$1048576,INT((ROW()-3)/4)+1) -> 15.61 | S726: =(R726*0.99-1.9)*(Q726/1000) -> 41.556257
A727: =$A$3+INT((ROW()-3)/96) -> 45755 | B727: =B726+TIME(0,15,0) -> 7.5416667 | C727: ='DHS2021'!J726 -> 12676 | D727: ='DHS2022'!J726 -> 8872 | E727: ='DHS2023'!J726 -> 11944 | F727: ='DHS2024'!J726 -> 2788 | G727: =AVERAGE(C727:F727) -> 9070 | H727: =G727/$M$2/1000 -> 3.0233333 | I727: =$N$2 -> 0 | J727: =H727+I727 -> 3.0233333 | K727: =ROUNDUP(J727,0) -> 4 | O727: ='DHS2025'!J726 -> 11100 | P727: ='DHS2025'!K726 -> 241 | Q727: ='DHS2025'!L726 -> 3063 | R727: =INDEX(U$3:U$1048576,INT((ROW()-3)/4)+1) -> 16.22 | S727: =(R727*0.99-1.9)*(Q727/1000) -> 43.365341
A728: =$A$3+INT((ROW()-3)/96) -> 45755 | B728: =B727+TIME(0,15,0) -> 7.5520833 | C728: ='DHS2021'!J727 -> 13045 | D728: ='DHS2022'!J727 -> 8976 | E728: ='DHS2023'!J727 -> 11926 | F728: ='DHS2024'!J727 -> 3313 | G728: =AVERAGE(C728:F728) -> 9315 | H728: =G728/$M$2/1000 -> 3.105 | I728: =$N$2 -> 0 | J728: =H728+I728 -> 3.105 | K728: =ROUNDUP(J728,0) -> 4 | O728: ='DHS2025'!J727 -> 10818 | P728: ='DHS2025'!K727 -> 100 | Q728: ='DHS2025'!L727 -> 3050 | R728: =INDEX(U$3:U$1048576,INT((ROW()-3)/4)+1) -> 16.22 | S728: =(R728*0.99-1.9)*(Q728/1000) -> 43.18129
A729: =$A$3+INT((ROW()-3)/96) -> 45755 | B729: =B728+TIME(0,15,0) -> 7.5625 | C729: ='DHS2021'!J728 -> 13195 | D729: ='DHS2022'!J728 -> 6793 | E729: ='DHS2023'!J728 -> 12283 | F729: ='DHS2024'!J728 -> 2688 | G729: =AVERAGE(C729:F729) -> 8739.75 | H729: =G729/$M$2/1000 -> 2.91325 | I729: =$N$2 -> 0 | J729: =H729+I729 -> 2.91325 | K729: =ROUNDUP(J729,0) -> 3 | O729: ='DHS2025'!J728 -> 10893 | P729: ='DHS2025'!K728 -> 118 | Q729: ='DHS2025'!L728 -> 3056 | R729: =INDEX(U$3:U$1048576,INT((ROW()-3)/4)+1) -> 16.22 | S729: =(R729*0.99-1.9)*(Q729/1000) -> 43.266237
A730: =$A$3+INT((ROW()-3)/96) -> 45755 | B730: =B729+TIME(0,15,0) -> 7.5729167 | C730: ='DHS2021'!J729 -> 13276 | D730: ='DHS2022'!J729 -> 6991 | E730: ='DHS2023'!J729 -> 11912 | F730: ='DHS2024'!J729 -> 3265 | G730: =AVERAGE(C730:F730) -> 8861 | H730: =G730/$M$2/1000 -> 2.9536667 | I730: =$N$2 -> 0 | J730: =H730+I730 -> 2.9536667 | K730: =ROUNDUP(J730,0) -> 3 | O730: ='DHS2025'!J729 -> 10879 | P730: ='DHS2025'!K729 -> 123 | Q730: ='DHS2025'!L729 -> 3070 | R730: =INDEX(U$3:U$1048576,INT((ROW()-3)/4)+1) -> 16.22 | S730: =(R730*0.99-1.9)*(Q730/1000) -> 43.464446
A731: =$A$3+INT((ROW()-3)/96) -> 45755 | B731: =B730+TIME(0,15,0) -> 7.5833333 | C731: ='DHS2021'!J730 -> 13720 | D731: ='DHS2022'!J730 -> 6519 | E731: ='DHS2023'!J730 -> 11614 | F731: ='DHS2024'!J730 -> 3141 | G731: =AVERAGE(C731:F731) -> 8748.5 | H731: =G731/$M$2/1000 -> 2.9161667 | I731: =$N$2 -> 0 | J731: =H731+I731 -> 2.9161667 | K731: =ROUNDUP(J731,0) -> 3 | O731: ='DHS2025'!J730 -> 11119 | P731: ='DHS2025'!K730 -> 193 | Q731: ='DHS2025'!L730 -> 3061 | R731: =INDEX(U$3:U$1048576,INT((ROW()-3)/4)+1) -> 41.01 | S731: =(R731*0.99-1.9)*(Q731/1000) -> 118.46039
A732: =$A$3+INT((ROW()-3)/96) -> 45755 | B732: =B731+TIME(0,15,0) -> 7.59375 | C732: ='DHS2021'!J731 -> 13222 | D732: ='DHS2022'!J731 -> 7014 | E732: ='DHS2023'!J731 -> 11500 | F732: ='DHS2024'!J731 -> 2954 | G732: =AVERAGE(C732:F732) -> 8672.5 | H732: =G732/$M$2/1000 -> 2.8908333 | I732: =$N$2 -> 0 | J732: =H732+I732 -> 2.8908333 | K732: =ROUNDUP(J732,0) -> 3 | O732: ='DHS2025'!J731 -> 13098 | P732: ='DHS2025'!K731 -> 101 | Q732: ='DHS2025'!L731 -> 4056 | R732: =INDEX(U$3:U$1048576,INT((ROW()-3)/4)+1) -> 41.01 | S732: =(R732*0.99-1.9)*(Q732/1000) -> 156.96679
A733: =$A$3+INT((ROW()-3)/96) -> 45755 | B733: =B732+TIME(0,15,0) -> 7.6041667 | C733: ='DHS2021'!J732 -> 13286 | D733: ='DHS2022'!J732 -> 8424 | E733: ='DHS2023'!J732 -> 11919 | F733: ='DHS2024'!J732 -> 1791 | G733: =AVERAGE(C733:F733) -> 8855 | H733: =G733/$M$2/1000 -> 2.9516667 | I733: =$N$2 -> 0 | J733: =H733+I733 -> 2.9516667 | K733: =ROUNDUP(J733,0) -> 3 | O733: ='DHS2025'!J732 -> 13344 | P733: ='DHS2025'!K732 -> 226 | Q733: ='DHS2025'!L732 -> 4070 | R733: =INDEX(U$3:U$1048576,INT((ROW()-3)/4)+1) -> 41.01 | S733: =(R733*0.99-1.9)*(Q733/1000) -> 157.50859
A734: =$A$3+INT((ROW()-3)/96) -> 45755 | B734: =B733+TIME(0,15,0) -> 7.6145833 | C734: ='DHS2021'!J733 -> 12508 | D734: ='DHS2022'!J733 -> 8241 | E734: ='DHS2023'!J733 -> 12063 | F734: ='DHS2024'!J733 -> 2745 | G734: =AVERAGE(C734:F734) -> 8889.25 | H734: =G734/$M$2/1000 -> 2.9630833 | I734: =$N$2 -> 0 | J734: =H734+I734 -> 2.9630833 | K734: =ROUNDUP(J734,0) -> 3 | O734: ='DHS2025'!J733 -> 13023 | P734: ='DHS2025'!K733 -> 186 | Q734: ='DHS2025'!L733 -> 4075 | R734: =INDEX(U$3:U$1048576,INT((ROW()-3)/4)+1) -> 41.01 | S734: =(R734*0.99-1.9)*(Q734/1000) -> 157.70209
... A2882: =$A$3+INT((ROW()-3)/96) -> 45777 | B2882: =B2881+TIME(0,15,0) -> 29.989583 | C2882: ='DHS2021'!J2881 -> 1869 | D2882: ='DHS2022'!J2881 -> 2693 | E2882: ='DHS2023'!J2881 -> 1850 | F2882: ='DHS2024'!J2881 -> 1830 | G2882: =AVERAGE(C2882:F2882) -> 2060.5 | H2882: =G2882/$M$2/1000 -> 0.68683333 | I2882: =$N$2 -> 0 | J2882: =H2882+I2882 -> 0.68683333 | K2882: =ROUNDUP(J2882,0) -> 1 | O2882: ='DHS2025'!J2881 -> 1473 | P2882: ='DHS2025'!K2881 -> 4037 | Q2882: ='DHS2025'!L2881 -> 1041 | R2882: =INDEX(U$3:U$1048576,INT((ROW()-3)/4)+1) -> 99.36 | S2882: =(R2882*0.99-1.9)*(Q2882/1000) -> 100.42152

Sheet DHS2021
A1: $Date | B1: $Time | C1: IIN_LEISTUNG-NETZ | D1: IIN_LEISTUNG-REGELKUEHLKREIS | E1: IIAN_DTU_GEN_WIRKLEISTUNG | G1: 15 min | H1: $Date | I1: $Time | J1: IIN_LEISTUNG-NETZ | K1: IIN_LEISTUNG-REGELKUEHLKREIS | L1: IIAN_DTU_GEN_WIRKLEISTUNG
A2: 01//21 | B2: 00:00:00 | C2: 1657 | D2: 21519 | E2: 8198 | H2: 04/01/21 | I2: 00:00:00 | J2: 1657 | K2: 21519 | L2: 8198
A3: 01//21 | B3: 01:00:00 | C3: 1445 | D3: 21585 | E3: 7995 | H3: 04/01/21 | I3: 00:15:00 | J3: 1733 | K3: 21486 | L3: 8153
A4: 01//21 | B4: 02:00:00 | C4: 1230 | D4: 22365 | E4: 8197 | H4: 04/01/21 | I4: 00:30:00 | J4: 1489 | K4: 21248 | L4: 8071
A5: 01//21 | B5: 03:00:00 | C5: 1583 | D5: 21721 | E5: 8208 | H5: 04/01/21 | I5: 00:45:00 | J5: 1336 | K5: 21449 | L5: 8056
A6: 01//21 | B6: 04:00:00 | C6: 6606 | D6: 15836 | E6: 8205 | H6: 04/01/21 | I6: 01:00:00 | J6: 1445 | K6: 21585 | L6: 7995
A7: 01//21 | B7: 05:00:00 | C7: 14010 | D7: 9104 | E7: 8197 | H7: 04/01/21 | I7: 01:15:00 | J7: 1355 | K7: 21872 | L7: 8210
A8: 01//21 | B8: 06:00:00 | C8: 14744 | D8: 8694 | E8: 8207 | H8: 04/01/21 | I8: 01:30:00 | J8: 1261 | K8: 22289 | L8: 8204
A9: 01//21 | B9: 07:00:00 | C9: 11320 | D9: 11192 | E9: 8203 | H9: 04/01/21 | I9: 01:45:00 | J9: 1320 | K9: 22259 | L9: 8200
A10: 01//21 | B10: 08:00:00 | C10: 10554 | D10: 12938 | E10: 8184 | H10: 04/01/21 | I10: 02:00:00 | J10: 1230 | K10: 22365 | L10: 8197
A11: 01//21 | B11: 09:00:00 | C11: 9617 | D11: 13680 | E11: 8134 | H11: 04/01/21 | I11: 02:15:00 | J11: 1165 | K11: 22220 | L11: 8199
A12: 01//21 | B12: 10:00:00 | C12: 8993 | D12: 14027 | E12: 7951 | H12: 04/01/21 | I12: 02:30:00 | J12: 1151 | K12: 22302 | L12: 8199
A13: 01//21 | B13: 11:00:00 | C13: 8305 | D13: 14883 | E13: 8195 | H13: 04/01/21 | I13: 02:45:00 | J13: 1157 | K13: 22029 | L13: 8198
... A722: 31//21 | B722: 00:00:00 | C722: 1427 | D722: 22127 | E722: 8004 | H722: 04/08/21 | I722: 12:00:00 | J722: 12635 | K722: 11165 | L722: 8164
A723: 31//21 | B723: 01:00:00 | H723: 04/08/21 | I723: 12:15:00 | J723: 12244 | K723: 11411 | L723: 8090
A724: 31//21 | B724: 02:00:00 | H724: 04/08/21 | I724: 12:30:00 | J724: 11832 | K724: 10884 | L724: 7992
A725: 31//21 | B725: 03:00:00 | H725: 04/08/21 | I725: 12:45:00 | J725: 12042 | K725: 10960 | L725: 7981
A726: 31//21 | B726: 04:00:00 | H726: 04/08/21 | I726: 13:00:00 | J726: 12676 | K726: 10250 | L726: 8010
A727: 31//21 | B727: 05:00:00 | H727: 04/08/21 | I727: 13:15:00 | J727: 13045 | K727: 9809 | L727: 7912
A728: 31//21 | B728: 06:00:00 | H728: 04/08/21 | I728: 13:30:00 | J728: 13195 | K728: 10409 | L728: 8083
A729: 31//21 | B729: 07:00:00 | H729: 04/08/21 | I729: 13:45:00 | J729: 13276 | K729: 10421 | L729: 8214
A730: 31//21 | B730: 08:00:00 | H730: 04/08/21 | I730: 14:00:00 | J730: 13720 | K730: 10095 | L730: 8206
A731: 31//21 | B731: 09:00:00 | H731: 04/08/21 | I731: 14:15:00 | J731: 13222 | K731: 9879 | L731: 8199
A732: 31//21 | B732: 10:00:00 | H732: 04/08/21 | I732: 14:30:00 | J732: 13286 | K732: 10932 | L732: 8212
A733: 31//21 | B733: 11:00:00 | H733: 04/08/21 | I733: 14:45:00 | J733: 12508 | K733: 11504 | L733: 8202
A734: 31//21 | B734: 12:00:00 | H734: 04/08/21 | I734: 15:00:00 | J734: 12201 | K734: 11794 | L734: 8204
... A745: 31//21 | B745: 23:00:00 | H745: 04/08/21 | I745: 17:45:00 | J745: 13801 | K745: 9896 | L745: 8187
H746: 04/08/21 | I746: 18:00:00 | J746: 13327 | K746: 10579 | L746: 8200
H747: 04/08/21 | I747: 18:15:00 | J747: 12879 | K747: 9937 | L747: 8202
H748: 04/08/21 | I748: 18:30:00 | J748: 13179 | K748: 9880 | L748: 8186
H749: 04/08/21 | I749: 18:45:00 | J749: 13640 | K749: 9958 | L749: 8203
H750: 04/08/21 | I750: 19:00:00 | J750: 13610 | K750: 10085 | L750: 8203
H751: 04/08/21 | I751: 19:15:00 | J751: 14280 | K751: 9302 | L751: 8210
H752: 04/08/21 | I752: 19:30:00 | J752: 14740 | K752: 8201 | L752: 8194
H753: 04/08/21 | I753: 19:45:00 | J753: 15405 | K753: 7689 | L753: 8197
H754: 04/08/21 | I754: 20:00:00 | J754: 16561 | K754: 6916 | L754: 8197
H755: 04/08/21 | I755: 20:15:00 | J755: 16156 | K755: 7514 | L755: 8201
H756: 04/08/21 | I756: 20:30:00 | J756: 16129 | K756: 7567 | L756: 8214
H757: 04/08/21 | I757: 20:45:00 | J757: 16040 | K757: 6465 | L757: 8197
... H2882: 05/01/21 | I2882: 00:00:00 | J2882: 1427 | K2882: 22127 | L2882: 8004

Sheet DHS2022
A1: $Date | B1: $Time | C1: IIN_LEISTUNG-NETZ | D1: IIN_LEISTUNG-REGELKUEHLKREIS | E1: IIAN_DTU_GEN_WIRKLEISTUNG | G1: 15 min | H1: $Date | I1: $Time | J1: IIN_LEISTUNG-NETZ | K1: IIN_LEISTUNG-REGELKUEHLKREIS | L1: IIAN_DTU_GEN_WIRKLEISTUNG
A2: 01//22 | B2: 00:00:00 | C2: 3209 | D2: 8846 | E2: 3495 | H2: 04/01/22 | I2: 00:00:00 | J2: 3209 | K2: 8846 | L2: 3495
A3: 01//22 | B3: 01:00:00 | C3: 3451 | D3: 9071 | E3: 3992 | H3: 04/01/22 | I3: 00:15:00 | J3: 3482 | K3: 9160 | L3: 3997
A4: 01//22 | B4: 02:00:00 | C4: 3073 | D4: 10189 | E4: 4013 | H4: 04/01/22 | I4: 00:30:00 | J4: 3483 | K4: 8955 | L4: 3990
A5: 01//22 | B5: 03:00:00 | C5: 3873 | D5: 9374 | E5: 4000 | H5: 04/01/22 | I5: 00:45:00 | J5: 3404 | K5: 9141 | L5: 3991
A6: 01//22 | B6: 04:00:00 | C6: 12762 | D6: 5630 | E6: 6001 | H6: 04/01/22 | I6: 01:00:00 | J6: 3451 | K6: 9071 | L6: 3992
A7: 01//22 | B7: 05:00:00 | C7: 17649 | D7: 224 | E7: 5995 | H7: 04/01/22 | I7: 01:15:00 | J7: 3532 | K7: 9123 | L7: 3894
A8: 01//22 | B8: 06:00:00 | C8: 14159 | D8: 3874 | E8: 5992 | H8: 04/01/22 | I8: 01:30:00 | J8: 3651 | K8: 8661 | L8: 3504
A9: 01//22 | B9: 07:00:00 | C9: 14095 | D9: 4283 | E9: 5996 | H9: 04/01/22 | I9: 01:45:00 | J9: 3253 | K9: 8319 | L9: 3508
A10: 01//22 | B10: 08:00:00 | C10: 13234 | D10: 4320 | E10: 5990 | H10: 04/01/22 | I10: 02:00:00 | J10: 3073 | K10: 10189 | L10: 4013
A11: 01//22 | B11: 09:00:00 | C11: 13413 | D11: 4151 | E11: 5996 | H11: 04/01/22 | I11: 02:15:00 | J11: 3411 | K11: 9620 | L11: 4003
A12: 01//22 | B12: 10:00:00 | C12: 13639 | D12: 244 | E12: 4000 | H12: 04/01/22 | I12: 02:30:00 | J12: 3829 | K12: 9101 | L12: 3998
A13: 01//22 | B13: 11:00:00 | C13: 12322 | D13: 170 | E13: 3999 | H13: 04/01/22 | I13: 02:45:00 | J13: 3502 | K13: 8963 | L13: 4000
... A722: 31//22 | B722: 00:00:00 | C722: 2745 | D722: 65 | E722: 0 | H722: 04/08/22 | I722: 12:00:00 | J722: 7796 | K722: 57 | L722: 0
A723: 31//22 | B723: 01:00:00 | H723: 04/08/22 | I723: 12:15:00 | J723: 7762 | K723: 61 | L723: 0
A724: 31//22 | B724: 02:00:00 | H724: 04/08/22 | I724: 12:30:00 | J724: 7734 | K724: 97 | L724: 0
A725: 31//22 | B725: 03:00:00 | H725: 04/08/22 | I725: 12:45:00 | J725: 7999 | K725: 73 | L725: 0
A726: 31//22 | B726: 04:00:00 | H726: 04/08/22 | I726: 13:00:00 | J726: 8872 | K726: 49 | L726: 0
A727: 31//22 | B727: 05:00:00 | H727: 04/08/22 | I727: 13:15:00 | J727: 8976 | K727: 78 | L727: 0
A728: 31//22 | B728: 06:00:00 | H728: 04/08/22 | I728: 13:30:00 | J728: 6793 | K728: 28 | L728: 0
A729: 31//22 | B729: 07:00:00 | H729: 04/08/22 | I729: 13:45:00 | J729: 6991 | K729: 51 | L729: 0
A730: 31//22 | B730: 08:00:00 | H730: 04/08/22 | I730: 14:00:00 | J730: 6519 | K730: 90 | L730: 0
A731: 31//22 | B731: 09:00:00 | H731: 04/08/22 | I731: 14:15:00 | J731: 7014 | K731: 98 | L731: 0
A732: 31//22 | B732: 10:00:00 | H732: 04/08/22 | I732: 14:30:00 | J732: 8424 | K732: 69 | L732: 0
A733: 31//22 | B733: 11:00:00 | H733: 04/08/22 | I733: 14:45:00 | J733: 8241 | K733: 51 | L733: 0
A734: 31//22 | B734: 12:00:00 | H734: 04/08/22 | I734: 15:00:00 | J734: 7557 | K734: 71 | L734: 0
... A745: 31//22 | B745: 23:00:00 | H745: 04/08/22 | I745: 17:45:00 | J745: 7001 | K745: 77 | L745: 0
H746: 04/08/22 | I746: 18:00:00 | J746: 6721 | K746: 79 | L746: 0
H747: 04/08/22 | I747: 18:15:00 | J747: 7174 | K747: 73 | L747: 0
H748: 04/08/22 | I748: 18:30:00 | J748: 8628 | K748: 25 | L748: 0
H749: 04/08/22 | I749: 18:45:00 | J749: 8846 | K749: 68 | L749: 0
H750: 04/08/22 | I750: 19:00:00 | J750: 7948 | K750: 101 | L750: 0
H751: 04/08/22 | I751: 19:15:00 | J751: 7658 | K751: 96 | L751: 0
H752: 04/08/22 | I752: 19:30:00 | J752: 8640 | K752: 83 | L752: 0
H753: 04/08/22 | I753: 19:45:00 | J753: 9234 | K753: 89 | L753: 0
H754: 04/08/22 | I754: 20:00:00 | J754: 9129 | K754: 71 | L754: 0
H755: 04/08/22 | I755: 20:15:00 | J755: 8860 | K755: 107 | L755: 0
H756: 04/08/22 | I756: 20:30:00 | J756: 8846 | K756: 25 | L756: 0
H757: 04/08/22 | I757: 20:45:00 | J757: 8944 | K757: 52 | L757: 0
... H2882: 05/01/22 | I2882: 00:00:00 | J2882: 2745 | K2882: 65 | L2882: 0

Sheet DHS2023
A1: $Date | B1: $Time | C1: IIN_LEISTUNG-NETZ | D1: IIN_LEISTUNG-REGELKUEHLKREIS | E1: IIAN_DTU_GEN_WIRKLEISTUNG | G1: 15 min | H1: $Date | I1: $Time | J1: IIN_LEISTUNG-NETZ | K1: IIN_LEISTUNG-REGELKUEHLKREIS | L1: IIAN_DTU_GEN_WIRKLEISTUNG
A2: 01//23 | B2: 00:00:00 | C2: 2507 | D2: 69 | E2: 0 | H2: 04/01/23 | I2: 00:00:00 | J2: 2507 | K2: 69 | L2: 0
A3: 01//23 | B3: 01:00:00 | C3: 2258 | D3: 62 | E3: 0 | H3: 04/01/23 | I3: 00:15:00 | J3: 2361 | K3: 87 | L3: 0
A4: 01//23 | B4: 02:00:00 | C4: 2473 | D4: 217 | E4: 0 | H4: 04/01/23 | I4: 00:30:00 | J4: 1995 | K4: 30 | L4: 0
A5: 01//23 | B5: 03:00:00 | C5: 2922 | D5: 160 | E5: 0 | H5: 04/01/23 | I5: 00:45:00 | J5: 2213 | K5: 66 | L5: 0
A6: 01//23 | B6: 04:00:00 | C6: 6803 | D6: 83 | E6: 0 | H6: 04/01/23 | I6: 01:00:00 | J6: 2258 | K6: 62 | L6: 0
A7: 01//23 | B7: 05:00:00 | C7: 12061 | D7: 98 | E7: 0 | H7: 04/01/23 | I7: 01:15:00 | J7: 2284 | K7: 25 | L7: 0
A8: 01//23 | B8: 06:00:00 | C8: 12826 | D8: 27 | E8: 0 | H8: 04/01/23 | I8: 01:30:00 | J8: 2327 | K8: 27 | L8: 0
A9: 01//23 | B9: 07:00:00 | C9: 12762 | D9: 176 | E9: 0 | H9: 04/01/23 | I9: 01:45:00 | J9: 2133 | K9: 29 | L9: 0
A10: 01//23 | B10: 08:00:00 | C10: 10405 | D10: 78 | E10: 0 | H10: 04/01/23 | I10: 02:00:00 | J10: 2473 | K10: 217 | L10: 0
A11: 01//23 | B11: 09:00:00 | C11: 11345 | D11: 117 | E11: 0 | H11: 04/01/23 | I11: 02:15:00 | J11: 2158 | K11: 109 | L11: 0
A12: 01//23 | B12: 10:00:00 | C12: 10337 | D12: 73 | E12: 0 | H12: 04/01/23 | I12: 02:30:00 | J12: 2494 | K12: 66 | L12: 0
A13: 01//23 | B13: 11:00:00 | C13: 9369 | D13: 79 | E13: 0 | H13: 04/01/23 | I13: 02:45:00 | J13: 2780 | K13: 36 | L13: 0
... A722: 31//23 | B722: 00:00:00 | C722: 1808 | D722: 8947 | E722: 3020 | H722: 04/08/23 | I722: 12:00:00 | J722: 12124 | K722: 88 | L722: 0
A723: 31//23 | B723: 01:00:00 | H723: 04/08/23 | I723: 12:15:00 | J723: 11880 | K723: 56 | L723: 0
A724: 31//23 | B724: 02:00:00 | H724: 04/08/23 | I724: 12:30:00 | J724: 11759 | K724: 32 | L724: 0
A725: 31//23 | B725: 03:00:00 | H725: 04/08/23 | I725: 12:45:00 | J725: 11627 | K725: 23 | L725: 0
A726: 31//23 | B726: 04:00:00 | H726: 04/08/23 | I726: 13:00:00 | J726: 11944 | K726: 83 | L726: 0
A727: 31//23 | B727: 05:00:00 | H727: 04/08/23 | I727: 13:15:00 | J727: 11926 | K727: 25 | L727: 0
A728: 31//23 | B728: 06:00:00 | H728: 04/08/23 | I728: 13:30:00 | J728: 12283 | K728: 25 | L728: 0
A729: 31//23 | B729: 07:00:00 | H729: 04/08/23 | I729: 13:45:00 | J729: 11912 | K729: 27 | L729: 0
A730: 31//23 | B730: 08:00:00 | H730: 04/08/23 | I730: 14:00:00 | J730: 11614 | K730: 66 | L730: 0
A731: 31//23 | B731: 09:00:00 | H731: 04/08/23 | I731: 14:15:00 | J731: 11500 | K731: 92 | L731: 0
A732: 31//23 | B732: 10:00:00 | H732: 04/08/23 | I732: 14:30:00 | J732: 11919 | K732: 137 | L732: 0
A733: 31//23 | B733: 11:00:00 | H733: 04/08/23 | I733: 14:45:00 | J733: 12063 | K733: 120 | L733: 0
A734: 31//23 | B734: 12:00:00 | H734: 04/08/23 | I734: 15:00:00 | J734: 12027 | K734: 25 | L734: 0
... A745: 31//23 | B745: 23:00:00 | H745: 04/08/23 | I745: 17:45:00 | J745: 12191 | K745: 78 | L745: 0
H746: 04/08/23 | I746: 18:00:00 | J746: 12354 | K746: 130 | L746: 0
H747: 04/08/23 | I747: 18:15:00 | J747: 12475 | K747: 73 | L747: 0
H748: 04/08/23 | I748: 18:30:00 | J748: 12453 | K748: 80 | L748: 0
H749: 04/08/23 | I749: 18:45:00 | J749: 12620 | K749: 81 | L749: 0
H750: 04/08/23 | I750: 19:00:00 | J750: 12440 | K750: 25 | L750: 0
H751: 04/08/23 | I751: 19:15:00 | J751: 12847 | K751: 126 | L751: 0
H752: 04/08/23 | I752: 19:30:00 | J752: 12883 | K752: 71 | L752: 0
H753: 04/08/23 | I753: 19:45:00 | J753: 13249 | K753: 77 | L753: 0
H754: 04/08/23 | I754: 20:00:00 | J754: 13415 | K754: 97 | L754: 0
H755: 04/08/23 | I755: 20:15:00 | J755: 13731 | K755: 157 | L755: 0
H756: 04/08/23 | I756: 20:30:00 | J756: 13891 | K756: 203 | L756: 0
H757: 04/08/23 | I757: 20:45:00 | J757: 13754 | K757: 22 | L757: 0
... H2882: 05/01/23 | I2882: 00:00:00 | J2882: 1808 | K2882: 8947 | L2882: 3020

Sheet DHS2024
A1: $Date | B1: $Time | C1: IIN_LEISTUNG-NETZ | D1: IIN_LEISTUNG-REGELKUEHLKREIS | E1: IIAN_DTU_GEN_WIRKLEISTUNG | G1: 15 min | H1: $Date | I1: $Time | J1: IIN_LEISTUNG-NETZ | K1: IIN_LEISTUNG-REGELKUEHLKREIS | L1: IIAN_DTU_GEN_WIRKLEISTUNG
A2: 01//24 | B2: 00:00:00 | C2: 1655 | D2: 122 | E2: 0 | H2: 04/01/24 | I2: 00:00:00 | J2: 1655 | K2: 122 | L2: 0
A3: 01//24 | B3: 01:00:00 | C3: 1737 | D3: 37 | E3: 0 | H3: 04/01/24 | I3: 00:15:00 | J3: 1626 | K3: 32 | L3: 0
A4: 01//24 | B4: 02:00:00 | C4: 2307 | D4: 89 | E4: 0 | H4: 04/01/24 | I4: 00:30:00 | J4: 1713 | K4: 85 | L4: 0
A5: 01//24 | B5: 03:00:00 | C5: 2253 | D5: 95 | E5: 0 | H5: 04/01/24 | I5: 00:45:00 | J5: 1853 | K5: 30 | L5: 0
A6: 01//24 | B6: 04:00:00 | C6: 4004 | D6: 38 | E6: 0 | H6: 04/01/24 | I6: 01:00:00 | J6: 1737 | K6: 37 | L6: 0
A7: 01//24 | B7: 05:00:00 | C7: 8353 | D7: 65 | E7: 0 | H7: 04/01/24 | I7: 01:15:00 | J7: 2017 | K7: 129 | L7: 0
A8: 01//24 | B8: 06:00:00 | C8: 5787 | D8: 31 | E8: 0 | H8: 04/01/24 | I8: 01:30:00 | J8: 1538 | K8: 79 | L8: 0
A9: 01//24 | B9: 07:00:00 | C9: 4637 | D9: 90 | E9: 0 | H9: 04/01/24 | I9: 01:45:00 | J9: 2383 | K9: 39 | L9: 0
A10: 01//24 | B10: 08:00:00 | C10: 5153 | D10: 103 | E10: 0 | H10: 04/01/24 | I10: 02:00:00 | J10: 2307 | K10: 89 | L10: 0
A11: 01//24 | B11: 09:00:00 | C11: 4718 | D11: 88 | E11: 0 | H11: 04/01/24 | I11: 02:15:00 | J11: 1742 | K11: 65 | L11: 0
A12: 01//24 | B12: 10:00:00 | C12: 4437 | D12: 79 | E12: 0 | H12: 04/01/24 | I12: 02:30:00 | J12: 1882 | K12: 243 | L12: 0
A13: 01//24 | B13: 11:00:00 | C13: 4988 | D13: 59 | E13: 0 | H13: 04/01/24 | I13: 02:45:00 | J13: 2589 | K13: 112 | L13: 0
... A722: 31//24 | B722: 00:00:00 | C722: 1850 | D722: 86 | E722: 0 | H722: 04/08/24 | I722: 12:00:00 | J722: 3920 | K722: 64 | L722: 0
A723: 31//24 | B723: 01:00:00 | H723: 04/08/24 | I723: 12:15:00 | J723: 3069 | K723: 26 | L723: 0
A724: 31//24 | B724: 02:00:00 | H724: 04/08/24 | I724: 12:30:00 | J724: 3025 | K724: 54 | L724: 0
A725: 31//24 | B725: 03:00:00 | H725: 04/08/24 | I725: 12:45:00 | J725: 3450 | K725: 130 | L725: 0
A726: 31//24 | B726: 04:00:00 | H726: 04/08/24 | I726: 13:00:00 | J726: 2788 | K726: 46 | L726: 0
A727: 31//24 | B727: 05:00:00 | H727: 04/08/24 | I727: 13:15:00 | J727: 3313 | K727: 26 | L727: 0
A728: 31//24 | B728: 06:00:00 | H728: 04/08/24 | I728: 13:30:00 | J728: 2688 | K728: 55 | L728: 0
A729: 31//24 | B729: 07:00:00 | H729: 04/08/24 | I729: 13:45:00 | J729: 3265 | K729: 89 | L729: 0
A730: 31//24 | B730: 08:00:00 | H730: 04/08/24 | I730: 14:00:00 | J730: 3141 | K730: 65 | L730: 0
A731: 31//24 | B731: 09:00:00 | H731: 04/08/24 | I731: 14:15:00 | J731: 2954 | K731: 83 | L731: 0
A732: 31//24 | B732: 10:00:00 | H732: 04/08/24 | I732: 14:30:00 | J732: 1791 | K732: 157 | L732: 0
A733: 31//24 | B733: 11:00:00 | H733: 04/08/24 | I733: 14:45:00 | J733: 2745 | K733: 30 | L733: 0
A734: 31//24 | B734: 12:00:00 | H734: 04/08/24 | I734: 15:00:00 | J734: 3529 | K734: 44 | L734: 0
... A745: 31//24 | B745: 23:00:00 | H745: 04/08/24 | I745: 17:45:00 | J745: 3760 | K745: 86 | L745: 0
H746: 04/08/24 | I746: 18:00:00 | J746: 4125 | K746: 32 | L746: 0
H747: 04/08/24 | I747: 18:15:00 | J747: 4153 | K747: 85 | L747: 0
H748: 04/08/24 | I748: 18:30:00 | J748: 3918 | K748: 98 | L748: 0
H749: 04/08/24 | I749: 18:45:00 | J749: 4000 | K749: 89 | L749: 0
H750: 04/08/24 | I750: 19:00:00 | J750: 4461 | K750: 94 | L750: 0
H751: 04/08/24 | I751: 19:15:00 | J751: 3971 | K751: 80 | L751: 0
H752: 04/08/24 | I752: 19:30:00 | J752: 4105 | K752: 84 | L752: 0
H753: 04/08/24 | I753: 19:45:00 | J753: 4428 | K753: 76 | L753: 0
H754: 04/08/24 | I754: 20:00:00 | J754: 4157 | K754: 89 | L754: 0
H755: 04/08/24 | I755: 20:15:00 | J755: 4672 | K755: 103 | L755: 0
H756: 04/08/24 | I756: 20:30:00 | J756: 4390 | K756: 111 | L756: 0
H757: 04/08/24 | I757: 20:45:00 | J757: 4156 | K757: 90 | L757: 0
... H2882: 05/01/24 | I2882: 00:00:00 | J2882: 1850 | K2882: 86 | L2882: 0

Sheet DHS2025
A1: $Date | B1: $Time | C1: IIN_LEISTUNG-NETZ | D1: IIN_LEISTUNG-REGELKUEHLKREIS | E1: IIAN_DTU_GEN_WIRKLEISTUNG | G1: 15 min | H1: $Date | I1: $Time | J1: IIN_LEISTUNG-NETZ | K1: IIN_LEISTUNG-REGELKUEHLKREIS | L1: IIAN_DTU_GEN_WIRKLEISTUNG
H2: 04/01/25 | I2: 00:00:00 | J2: 2506 | K2: 6321 | L2: 2050
H3: 04/01/25 | I3: 00:15:00 | J3: 1888 | K3: 6043 | L3: 2049
H4: 04/01/25 | I4: 00:30:00 | J4: 1943 | K4: 6585 | L4: 2056
H5: 04/01/25 | I5: 00:45:00 | J5: 1889 | K5: 6274 | L5: 2054
H6: 04/01/25 | I6: 01:00:00 | J6: 1683 | K6: 6122 | L6: 2034
H7: 04/01/25 | I7: 01:15:00 | J7: 1530 | K7: 6689 | L7: 2054
H8: 04/01/25 | I8: 01:30:00 | J8: 1591 | K8: 6682 | L8: 2065
H9: 04/01/25 | I9: 01:45:00 | J9: 1813 | K9: 6415 | L9: 2048
H10: 04/01/25 | I10: 02:00:00 | J10: 1697 | K10: 6343 | L10: 2039
H11: 04/01/25 | I11: 02:15:00 | J11: 1797 | K11: 6549 | L11: 2049
H12: 04/01/25 | I12: 02:30:00 | J12: 2065 | K12: 6433 | L12: 2055
H13: 04/01/25 | I13: 02:45:00 | J13: 2190 | K13: 5808 | L13: 2043
... H34: 04/01/25 | I34: 08:00:00 | J34: 12939 | K34: 10642 | L34: 8044
H35: 04/01/25 | I35: 08:15:00
H36: 04/01/25 | I36: 08:30:00 | J36: 12026 | K36: 11634 | L36: 8049
H37: 04/01/25 | I37: 08:45:00 | J37: 12014 | K37: 11558 | L37: 8080
H38: 04/01/25 | I38: 09:00:00 | J38: 12324 | K38: 8340 | L38: 6817
H39: 04/01/25 | I39: 09:15:00 | J39: 12105 | K39: 5480 | L39: 5547
H40: 04/01/25 | I40: 09:30:00 | J40: 11712 | K40: 1642 | L40: 4065
H41: 04/01/25 | I41: 09:45:00 | J41: 12453 | K41: 1110 | L41: 4074
H42: 04/01/25 | I42: 10:00:00 | J42: 12253 | K42: 1558 | L42: 4075
H43: 04/01/25 | I43: 10:15:00 | J43: 12228 | K43: 1828 | L43: 4069
H44: 04/01/25 | I44: 10:30:00 | J44: 11906 | K44: 1062 | L44: 4059
H45: 04/01/25 | I45: 10:45:00 | J45: 13237 | K45: 51 | L45: 4067
H46: 04/01/25 | I46: 11:00:00 | J46: 10732 | K46: 78 | L46: 2257
H47: 04/01/25 | I47: 11:15:00 | J47: 8630 | K47: 47 | L47: 2052
... H821: 04/09/25 | I821: 12:45:00 | J821: 8182 | K821: 24 | L821: 2051
H822: 04/09/25 | I822: 13:00:00
H823: 04/09/25 | I823: 13:15:00 | J823: 8093 | K823: 89 | L823: 2047
H824: 04/09/25 | I824: 13:30:00 | J824: 7998 | K824: 55 | L824: 2051
H825: 04/09/25 | I825: 13:45:00 | J825: 8225 | K825: 82 | L825: 2046
H826: 04/09/25 | I826: 14:00:00 | J826: 9777 | K826: 91 | L826: 3496
H827: 04/09/25 | I827: 14:15:00 | J827: 12717 | K827: 115 | L827: 4052
H828: 04/09/25 | I828: 14:30:00 | J828: 12798 | K828: 74 | L828: 4048
H829: 04/09/25 | I829: 14:45:00 | J829: 12870 | K829: 81 | L829: 4049
H830: 04/09/25 | I830: 15:00:00 | J830: 13071 | K830: 124 | L830: 4053
H831: 04/09/25 | I831: 15:15:00 | J831: 12753 | K831: 22 | L831: 4057
H832: 04/09/25 | I832: 15:30:00 | J832: 13077 | K832: 193 | L832: 4044
H833: 04/09/25 | I833: 15:45:00 | J833: 12388 | K833: 164 | L833: 4048
...

Sheet Marža
D1: kWh | E1: MWh | G1: MW | I1: MW | J1: S maričom | M1: Bez maričov
A2: Cena EE v hodinovom intervale | B2: Dátum | C2: Cena EE v 15min intervale | D2: Požiadavok na dodavku tepla zo siete | E2: Požiadavok na dodavku tepla zo siete | F2: Nakladova cena na 1 MWh | G2: Výrobena EE | H2: Vyroba EE bez maričov | I2: Vyroba EE bez maričov (výkon 2MW min. pre 2 kotly) | J2: Tržba výroby EE | K2: Náklad | L2: Marža | M2: Tržba výroby EE | N2: Náklad | O2: Marža | P2: Porovnanie
A3: ='Predikcia 15min'!U3 -> 102.23 | B3: ='Predikcia 15min'!A3 -> 45748 | C3: ='Porovnavanie 15min'!J6 -> 102.23 | D3: ='Porovnavanie 15min'!F6 -> 2506 | E3: =D3/1000 -> 2.506 | F3: 40 | G3: ='DHS2025'!L2/1000 -> 2.05 | H3: =D3/3000 -> 0.83533333 | I3: =IF(H3=0, 0, MAX(ROUND(H3, 0), 2)) -> 2 | J3: ='Porovnavanie 15min'!K6 -> 203.58078 | K3: =$F$3*G3 -> 82 | L3: =J3-K3 -> 121.58078 | M3: =(C3*0.99-1.9)*I3 -> 198.6154 | N3: =$F$3*I3 -> 80 | O3: =M3-N3 -> 118.6154 | P3: =L3-O3 -> 2.965385
A4: ='Predikcia 15min'!U4 -> 96.15 | B4: ='Predikcia 15min'!A4 -> 45748 | C4: ='Porovnavanie 15min'!J7 -> 102.23 | D4: ='Porovnavanie 15min'!F7 -> 1888 | E4: =D4/1000 -> 1.888 | G4: ='DHS2025'!L3/1000 -> 2.049 | H4: =D4/3000 -> 0.62933333 | I4: =IF(H4=0, 0, MAX(ROUND(H4, 0), 2)) -> 2 | J4: ='Porovnavanie 15min'!K7 -> 203.48148 | K4: =$F$3*G4 -> 81.96 | L4: =J4-K4 -> 121.52148 | M4: =(C4*0.99-1.9)*I4 -> 198.6154 | N4: =$F$3*I4 -> 80 | O4: =M4-N4 -> 118.6154 | P4: =L4-O4 -> 2.9060773
A5: ='Predikcia 15min'!U5 -> 94.17 | B5: ='Predikcia 15min'!A5 -> 45748 | C5: ='Porovnavanie 15min'!J8 -> 102.23 | D5: ='Porovnavanie 15min'!F8 -> 1943 | E5: =D5/1000 -> 1.943 | G5: ='DHS2025'!L4/1000 -> 2.056 | H5: =D5/3000 -> 0.64766667 | I5: =IF(H5=0, 0, MAX(ROUND(H5, 0), 2)) -> 2 | J5: ='Porovnavanie 15min'!K8 -> 204.17663 | K5: =$F$3*G5 -> 82.24 | L5: =J5-K5 -> 121.93663 | M5: =(C5*0.99-1.9)*I5 -> 198.6154 | N5: =$F$3*I5 -> 80 | O5: =M5-N5 -> 118.6154 | P5: =L5-O5 -> 3.3212312
A6: ='Predikcia 15min'!U6 -> 95.33 | B6: ='Predikcia 15min'!A6 -> 45748 | C6: ='Porovnavanie 15min'!J9 -> 102.23 | D6: ='Porovnavanie 15min'!F9 -> 1889 | E6: =D6/1000 -> 1.889 | G6: ='DHS2025'!L5/1000 -> 2.054 | H6: =D6/3000 -> 0.62966667 | I6: =IF(H6=0, 0, MAX(ROUND(H6, 0), 2)) -> 2 | J6: ='Porovnavanie 15min'!K9 -> 203.97802 | K6: =$F$3*G6 -> 82.16 | L6: =J6-K6 -> 121.81802 | M6: =(C6*0.99-1.9)*I6 -> 198.6154 | N6: =$F$3*I6 -> 80 | O6: =M6-N6 -> 118.6154 | P6: =L6-O6 -> 3.2026158
A7: ='Predikcia 15min'!U7 -> 93.08 | B7: ='Predikcia 15min'!A7 -> 45748 | C7: ='Porovnavanie 15min'!J10 -> 96.15 | D7: ='Porovnavanie 15min'!F10 -> 1683 | E7: =D7/1000 -> 1.683 | G7: ='DHS2025'!L6/1000 -> 2.034 | H7: =D7/3000 -> 0.561 | I7: =IF(H7=0, 0, MAX(ROUND(H7, 0), 2)) -> 2 | J7: ='Porovnavanie 15min'!K10 -> 189.74881 | K7: =$F$3*G7 -> 81.36 | L7: =J7-K7 -> 108.38881 | M7: =(C7*0.99-1.9)*I7 -> 186.577 | N7: =$F$3*I7 -> 80 | O7: =M7-N7 -> 106.577 | P7: =L7-O7 -> 1.811809
A8: ='Predikcia 15min'!U8 -> 102.58 | B8: ='Predikcia 15min'!A8 -> 45748 | C8: ='Porovnavanie 15min'!J11 -> 96.15 | D8: ='Porovnavanie 15min'!F11 -> 1530 | E8: =D8/1000 -> 1.53 | G8: ='DHS2025'!L7/1000 -> 2.054 | H8: =D8/3000 -> 0.51 | I8: =IF(H8=0, 0, MAX(ROUND(H8, 0), 2)) -> 2 | J8: ='Porovnavanie 15min'!K11 -> 191.61458 | K8: =$F$3*G8 -> 82.16 | L8: =J8-K8 -> 109.45458 | M8: =(C8*0.99-1.9)*I8 -> 186.577 | N8: =$F$3*I8 -> 80 | O8: =M8-N8 -> 106.577 | P8: =L8-O8 -> 2.877579
A9: ='Predikcia 15min'!U9 -> 131.44 | B9: ='Predikcia 15min'!A9 -> 45748 | C9: ='Porovnavanie 15min'!J12 -> 96.15 | D9: ='Porovnavanie 15min'!F12 -> 1591 | E9: =D9/1000 -> 1.591 | G9: ='DHS2025'!L8/1000 -> 2.065 | H9: =D9/3000 -> 0.53033333 | I9: =IF(H9=0, 0, MAX(ROUND(H9, 0), 2)) -> 2 | J9: ='Porovnavanie 15min'!K12 -> 192.64075 | K9: =$F$3*G9 -> 82.6 | L9: =J9-K9 -> 110.04075 | M9: =(C9*0.99-1.9)*I9 -> 186.577 | N9: =$F$3*I9 -> 80 | O9: =M9-N9 -> 106.577 | P9: =L9-O9 -> 3.4637525
A10: ='Predikcia 15min'!U10 -> 177.65 | B10: ='Predikcia 15min'!A10 -> 45748 | C10: ='Porovnavanie 15min'!J13 -> 96.15 | D10: ='Porovnavanie 15min'!F13 -> 1813 | E10: =D10/1000 -> 1.813 | G10: ='DHS2025'!L9/1000 -> 2.048 | H10: =D10/3000 -> 0.60433333 | I10: =IF(H10=0, 0, MAX(ROUND(H10, 0), 2)) -> 2 | J10: ='Porovnavanie 15min'!K13 -> 191.05485 | K10: =$F$3*G10 -> 81.92 | L10: =J10-K10 -> 109.13485 | M10: =(C10*0.99-1.9)*I10 -> 186.577 | N10: =$F$3*I10 -> 80 | O10: =M10-N10 -> 106.577 | P10: =L10-O10 -> 2.557848
A11: ='Predikcia 15min'!U11 -> 159.37 | B11: ='Predikcia 15min'!A11 -> 45748 | C11: ='Porovnavanie 15min'!J14 -> 94.17 | D11: ='Porovnavanie 15min'!F14 -> 1697 | E11: =D11/1000 -> 1.697 | G11: ='DHS2025'!L10/1000 -> 2.039 | H11: =D11/3000 -> 0.56566667 | I11: =IF(H11=0, 0, MAX(ROUND(H11, 0), 2)) -> 2 | J11: ='Porovnavanie 15min'!K14 -> 186.2184 | K11: =$F$3*G11 -> 81.56 | L11: =J11-K11 -> 104.6584 | M11: =(C11*0.99-1.9)*I11 -> 182.6566 | N11: =$F$3*I11 -> 80 | O11: =M11-N11 -> 102.6566 | P11: =L11-O11 -> 2.0018037
A12: ='Predikcia 15min'!U12 -> 109.59 | B12: ='Predikcia 15min'!A12 -> 45748 | C12: ='Porovnavanie 15min'!J15 -> 94.17 | D12: ='Porovnavanie 15min'!F15 -> 1797 | E12: =D12/1000 -> 1.797 | G12: ='DHS2025'!L11/1000 -> 2.049 | H12: =D12/3000 -> 0.599 | I12: =IF(H12=0, 0, MAX(ROUND(H12, 0), 2)) -> 2 | J12: ='Porovnavanie 15min'!K15 -> 187.13169 | K12: =$F$3*G12 -> 81.96 | L12: =J12-K12 -> 105.17169 | M12: =(C12*0.99-1.9)*I12 -> 182.6566 | N12: =$F$3*I12 -> 80 | O12: =M12-N12 -> 102.6566 | P12: =L12-O12 -> 2.5150867
A13: ='Predikcia 15min'!U13 -> 88.29 | B13: ='Predikcia 15min'!A13 -> 45748 | C13: ='Porovnavanie 15min'!J16 -> 94.17 | D13: ='Porovnavanie 15min'!F16 -> 2065 | E13: =D13/1000 -> 2.065 | G13: ='DHS2025'!L12/1000 -> 2.055 | H13: =D13/3000 -> 0.68833333 | I13: =IF(H13=0, 0, MAX(ROUND(H13, 0), 2)) -> 2 | J13: ='Porovnavanie 15min'!K16 -> 187.67966 | K13: =$F$3*G13 -> 82.2 | L13: =J13-K13 -> 105.47966 | M13: =(C13*0.99-1.9)*I13 -> 182.6566 | N13: =$F$3*I13 -> 80 | O13: =M13-N13 -> 102.6566 | P13: =L13-O13 -> 2.8230565
A14: ='Predikcia 15min'!U14 -> 75.04 | B14: ='Predikcia 15min'!A14 -> 45748 | C14: ='Porovnavanie 15min'!J17 -> 94.17 | D14: ='Porovnavanie 15min'!F17 -> 2190 | E14: =D14/1000 -> 2.19 | G14: ='DHS2025'!L13/1000 -> 2.043 | H14: =D14/3000 -> 0.73 | I14: =IF(H14=0, 0, MAX(ROUND(H14, 0), 2)) -> 2 | J14: ='Porovnavanie 15min'!K17 -> 186.58372 | K14: =$F$3*G14 -> 81.72 | L14: =J14-K14 -> 104.86372 | M14: =(C14*0.99-1.9)*I14 -> 182.6566 | N14: =$F$3*I14 -> 80 | O14: =M14-N14 -> 102.6566 | P14: =L14-O14 -> 2.2071169
A15: ='Predikcia 15min'!U15 -> 63 | B15: ='Predikcia 15min'!A15 -> 45748 | C15: ='Porovnavanie 15min'!J18 -> 95.33 | D15: ='Porovnavanie 15min'!F18 -> 2389 | E15: =D15/1000 -> 2.389 | G15: ='DHS2025'!L14/1000 -> 2.54 | H15: =D15/3000 -> 0.79633333 | I15: =IF(H15=0, 0, MAX(ROUND(H15, 0), 2)) -> 2 | J15: ='Porovnavanie 15min'!K18 -> 234.89082 | K15: =$F$3*G15 -> 101.6 | L15: =J15-K15 -> 133.29082 | M15: =(C15*0.99-1.9)*I15 -> 184.9534 | N15: =$F$3*I15 -> 80 | O15: =M15-N15 -> 104.9534 | P15: =L15-O15 -> 28.337418
... A1304: ='Predikcia 15min'!U1304 -> 0 | B1304: ='Predikcia 15min'!A1304 -> 45761 | C1304: ='Porovnavanie 15min'!J1307 -> 107.33 | D1304: ='Porovnavanie 15min'!F1307 -> 6052 | E1304: =D1304/1000 -> 6.052 | G1304: ='DHS2025'!L1303/1000 -> 3.039 | H1304: =D1304/3000 -> 2.0173333 | I1304: =IF(H1304=0, 0, MAX(ROUND(H1304, 0), 2)) -> 2 | J1304: ='Porovnavanie 15min'!K1307 -> 317.14001 | K1304: =$F$3*G1304 -> 121.56 | L1304: =J1304-K1304 -> 195.58001 | M1304: =(C1304*0.99-1.9)*I1304 -> 208.7134 | N1304: =$F$3*I1304 -> 80 | O1304: =M1304-N1304 -> 128.7134 | P1304: =L1304-O1304 -> 66.866611
B1305: ='Predikcia 15min'!A1305 -> 45761 | C1305: ='Porovnavanie 15min'!J1308 -> 107.33 | D1305: ='Porovnavanie 15min'!F1308 -> 6588 | E1305: =D1305/1000 -> 6.588 | G1305: ='DHS2025'!L1304/1000 -> 3.043 | H1305: =D1305/3000 -> 2.196 | I1305: =IF(H1305=0, 0, MAX(ROUND(H1305, 0), 2)) -> 2 | J1305: ='Porovnavanie 15min'!K1308 -> 317.55744 | K1305: =$F$3*G1305 -> 121.72 | L1305: =J1305-K1305 -> 195.83744 | M1305: =(C1305*0.99-1.9)*I1305 -> 208.7134 | N1305: =$F$3*I1305 -> 80 | O1305: =M1305-N1305 -> 128.7134 | P1305: =L1305-O1305 -> 67.124038
B1306: ='Predikcia 15min'!A1306 -> 45761 | C1306: ='Porovnavanie 15min'!J1309 -> 107.33 | D1306: ='Porovnavanie 15min'!F1309 -> 6932 | E1306: =D1306/1000 -> 6.932 | G1306: ='DHS2025'!L1305/1000 -> 3.047 | H1306: =D1306/3000 -> 2.3106667 | I1306: =IF(H1306=0, 0, MAX(ROUND(H1306, 0), 2)) -> 2 | J1306: ='Porovnavanie 15min'!K1309 -> 317.97486 | K1306: =$F$3*G1306 -> 121.88 | L1306: =J1306-K1306 -> 196.09486 | M1306: =(C1306*0.99-1.9)*I1306 -> 208.7134 | N1306: =$F$3*I1306 -> 80 | O1306: =M1306-N1306 -> 128.7134 | P1306: =L1306-O1306 -> 67.381465
B1307: ='Predikcia 15min'!A1307 -> 45761 | C1307: ='Porovnavanie 15min'!J1310 -> 89.51 | D1307: ='Porovnavanie 15min'!F1310 -> 7483 | E1307: =D1307/1000 -> 7.483 | G1307: ='DHS2025'!L1306/1000 -> 3.06 | H1307: =D1307/3000 -> 2.4943333 | I1307: =IF(H1307=0, 0, MAX(ROUND(H1307, 0), 2)) -> 2 | J1307: ='Porovnavanie 15min'!K1310 -> 265.34759 | K1307: =$F$3*G1307 -> 122.4 | L1307: =J1307-K1307 -> 142.94759 | M1307: =(C1307*0.99-1.9)*I1307 -> 173.4298 | N1307: =$F$3*I1307 -> 80 | O1307: =M1307-N1307 -> 93.4298 | P1307: =L1307-O1307 -> 49.517794
B1308: ='Predikcia 15min'!A1308 -> 45761 | C1308: ='Porovnavanie 15min'!J1311 -> 89.51 | D1308: ='Porovnavanie 15min'!F1311 -> 7091 | E1308: =D1308/1000 -> 7.091 | G1308: ='DHS2025'!L1307/1000 -> 3.049 | H1308: =D1308/3000 -> 2.3636667 | I1308: =IF(H1308=0, 0, MAX(ROUND(H1308, 0), 2)) -> 2 | J1308: ='Porovnavanie 15min'!K1311 -> 264.39373 | K1308: =$F$3*G1308 -> 121.96 | L1308: =J1308-K1308 -> 142.43373 | M1308: =(C1308*0.99-1.9)*I1308 -> 173.4298 | N1308: =$F$3*I1308 -> 80 | O1308: =M1308-N1308 -> 93.4298 | P1308: =L1308-O1308 -> 49.00393
B1309: ='Predikcia 15min'!A1309 -> 45761 | C1309: ='Porovnavanie 15min'!J1312 -> 89.51 | D1309: ='Porovnavanie 15min'!F1312 -> 6656 | E1309: =D1309/1000 -> 6.656 | G1309: ='DHS2025'!L1308/1000 -> 3.049 | H1309: =D1309/3000 -> 2.2186667 | I1309: =IF(H1309=0, 0, MAX(ROUND(H1309, 0), 2)) -> 2 | J1309: ='Porovnavanie 15min'!K1312 -> 264.39373 | K1309: =$F$3*G1309 -> 121.96 | L1309: =J1309-K1309 -> 142.43373 | M1309: =(C1309*0.99-1.9)*I1309 -> 173.4298 | N1309: =$F$3*I1309 -> 80 | O1309: =M1309-N1309 -> 93.4298 | P1309: =L1309-O1309 -> 49.00393
