Workbook

Sheet Porovnanie
C1: Dátum | D1: Čas | E1: Plán sieť [kWh] | F1: Skutočnosť sieť [kWh] | G1: Marič [kWh] | H1: Plán EE [MW] | I1: Skutočnosť EE [MW] | J1: Cena SK (EUR/MWh) | K1: Tržby výroba EE | L1: Táto farba znamená plán
L2: Táto farba znamená skutočnosť
L3: Zobchodované na intraday
L4: Zmena plánu oproti pôvodnému
C5: =predikcia!A3 -> 45658 | D5: =predikcia!B3 -> 00:00:00 | E5: =predikcia!G3 -> 5010.5 | F5: ='DHS25'!C2 -> 9904 | G5: ='DHS25'!D2 -> 4296 | H5: 3 | I5: ='DHS25'!E2/1000 -> 4.043 | J5: =predikcia!R3 -> 180 | K5: =(J5*0.99-1.9)*I5 -> 712.7809 | M5: 3 | N5: 3
C6: =predikcia!A4 -> 45658 | D6: =predikcia!B4 -> 01:00:00 | E6: =predikcia!G4 -> 5542.25 | F6: ='DHS25'!C3 -> 9949 | G6: ='DHS25'!D3 -> 1848 | H6: 3 | I6: ='DHS25'!E3/1000 -> 3.007 | J6: =predikcia!R4 -> 138.56 | K6: =(J6*0.99-1.9)*I6 -> 406.77012 | M6: 3 | N6: 3
C7: =predikcia!A5 -> 45658 | D7: =predikcia!B5 -> 02:00:00 | E7: =predikcia!G5 -> 6725 | F7: ='DHS25'!C4 -> 11129 | G7: ='DHS25'!D4 -> 309 | H7: 3 | I7: ='DHS25'!E4/1000 -> 2.996 | J7: =predikcia!R5 -> 127.12 | K7: =(J7*0.99-1.9)*I7 -> 371.3506 | M7: 3 | N7: 3
C8: =predikcia!A6 -> 45658 | D8: =predikcia!B6 -> 03:00:00 | E8: =predikcia!G6 -> 7629.25 | F8: ='DHS25'!C5 -> 11442 | G8: ='DHS25'!D5 -> 49 | H8: 3 | I8: ='DHS25'!E5/1000 -> 3 | J8: =predikcia!R6 -> 64.8 | K8: =(J8*0.99-1.9)*I8 -> 186.756 | M8: 3 | N8: 3
C9: =predikcia!A7 -> 45658 | D9: =predikcia!B7 -> 04:00:00 | E9: =predikcia!G7 -> 14498.25 | F9: ='DHS25'!C6 -> 16527 | G9: ='DHS25'!D6 -> 89 | H9: 5 | I9: ='DHS25'!E6/1000 -> 4.991 | J9: =predikcia!R7 -> 71.09 | K9: =(J9*0.99-1.9)*I9 -> 341.77919 | M9: 5 | N9: 5
C10: =predikcia!A8 -> 45658 | D10: =predikcia!B8 -> 05:00:00 | E10: =predikcia!G8 -> 16509.5 | F10: ='DHS25'!C7 -> 19516 | G10: ='DHS25'!D7 -> 60 | H10: 6 | I10: ='DHS25'!E7/1000 -> 5.988 | J10: =predikcia!R8 -> 3 | K10: =(J10*0.99-1.9)*I10 -> 6.40716 | M10: 6 | N10: 6
C11: =predikcia!A9 -> 45658 | D11: =predikcia!B9 -> 06:00:00 | E11: =predikcia!G9 -> 16696.75 | F11: ='DHS25'!C8 -> 19152 | G11: ='DHS25'!D8 -> 25 | H11: 6 | I11: ='DHS25'!E8/1000 -> 6.004 | J11: =predikcia!R9 -> -3.67 | K11: =(J11*0.99-1.9)*I11 -> -33.221933 | M11: 6 | N11: 6
C12: =predikcia!A10 -> 45658 | D12: =predikcia!B10 -> 07:00:00 | E12: =predikcia!G10 -> 13328.5 | F12: ='DHS25'!C9 -> 19102 | G12: ='DHS25'!D9 -> 111 | H12: 5 | I12: ='DHS25'!E9/1000 -> 5.888 | J12: =predikcia!R10 -> -5.71 | K12: =(J12*0.99-1.9)*I12 -> -44.471475 | M12: 5 | N12: 5
C13: =predikcia!A11 -> 45658 | D13: =predikcia!B11 -> 08:00:00 | E13: =predikcia!G11 -> 12737.5 | F13: ='DHS25'!C10 -> 16175 | G13: ='DHS25'!D10 -> 80 | H13: 5 | I13: ='DHS25'!E10/1000 -> 5 | J13: =predikcia!R11 -> 18.94 | K13: =(J13*0.99-1.9)*I13 -> 84.253 | M13: 5 | N13: 5
C14: =predikcia!A12 -> 45658 | D14: =predikcia!B12 -> 09:00:00 | E14: =predikcia!G12 -> 13901.75 | F14: ='DHS25'!C11 -> 15994 | G14: ='DHS25'!D11 -> 28 | H14: 5 | I14: ='DHS25'!E11/1000 -> 5.001 | J14: =predikcia!R12 -> 26.27 | K14: =(J14*0.99-1.9)*I14 -> 120.56061 | M14: 5 | N14: 5
C15: =predikcia!A13 -> 45658 | D15: =predikcia!B13 -> 10:00:00 | E15: =predikcia!G13 -> 13734.25 | F15: ='DHS25'!C12 -> 17102 | G15: ='DHS25'!D12 -> 69 | H15: 5 | I15: ='DHS25'!E12/1000 -> 5.503 | J15: =predikcia!R13 -> 13 | K15: =(J15*0.99-1.9)*I15 -> 60.36791 | M15: 5 | N15: 5
C16: =predikcia!A14 -> 45658 | D16: =predikcia!B14 -> 11:00:00 | E16: =predikcia!G14 -> 13889.25 | F16: ='DHS25'!C13 -> 18129 | G16: ='DHS25'!D13 -> 115 | H16: 5 | I16: ='DHS25'!E13/1000 -> 5.695 | J16: =predikcia!R14 -> 17 | K16: =(J16*0.99-1.9)*I16 -> 85.02635 | M16: 5 | N16: 5
... C748: =predikcia!A746 -> 45688 | D748: =predikcia!B746 -> 23:00:00 | E748: =predikcia!G746 -> 9011.5 | F748: ='DHS25'!C745 -> 7665 | G748: ='DHS25'!D745 -> 4758 | H748: 2 | I748: ='DHS25'!E745/1000 -> 3.932 | J748: =predikcia!R746 -> 134.18 | K748: =(J748*0.99-1.9)*I748 -> 514.849 | M748: 4 | N748: 2
K749: =SUM(K5:K748) -> 685142.24

Sheet predikcia
O1: 2025 Skutočnosť
A2: $Date | B2: $Time | C2: 2020 | D2: 2021 | E2: 2023 | F2: 2024 | G2: Ø | H2: MW EE | I2: Marič | J2: ∑ | K2: PLÁN | L2: koef | M2: 4 | O2: Sieť [kWh] | P2: Marič [kWh] | Q2: EE [kW] | R2: Cena SK (EUR/MWh) | S2: Tržby výroba EE
A3: 45658 | B3: 00:00:00 | C3: 6127 | D3: 7558 | E3: 2689 | F3: 3668 | G3: =AVERAGE(C3:F3) -> 5010.5 | H3: =G3/$M$2/1000 -> 1.252625 | I3: 1 | J3: =H3+I3 -> 2.252625 | K3: =ROUNDUP(J3,0) -> 3 | O3: ='DHS25'!C2 -> 9904 | P3: ='DHS25'!D2 -> 4296 | Q3: ='DHS25'!E2 -> 4043 | R3: 180 | S3: =(Q3/1000)*R3 -> 727.74
A4: 45658 | B4: 01:00:00 | C4: 7742 | D4: 7830 | E4: 2551 | F4: 4046 | G4: =AVERAGE(C4:F4) -> 5542.25 | H4: =G4/$M$2/1000 -> 1.3855625 | I4: =I3 -> 1 | J4: =H4+I4 -> 2.3855625 | K4: =ROUNDUP(J4,0) -> 3 | L4: cena štiepky €/ATT | M4: 110 | O4: ='DHS25'!C3 -> 9949 | P4: ='DHS25'!D3 -> 1848 | Q4: ='DHS25'!E3 -> 3007 | R4: 138.56 | S4: =(Q4/1000)*R4 -> 416.64992
A5: 45658 | B5: 02:00:00 | C5: 9368 | D5: 9217 | E5: 4289 | F5: 4026 | G5: =AVERAGE(C5:F5) -> 6725 | H5: =G5/$M$2/1000 -> 1.68125 | I5: =I4 -> 1 | J5: =H5+I5 -> 2.68125 | K5: =ROUNDUP(J5,0) -> 3 | L5: spotreba štiepky ATT | M5: =M8*1.1 -> 4364.8 | O5: ='DHS25'!C4 -> 11129 | P5: ='DHS25'!D4 -> 309 | Q5: ='DHS25'!E4 -> 2996 | R5: 127.12 | S5: =(Q5/1000)*R5 -> 380.85152
A6: 45658 | B6: 03:00:00 | C6: 11370 | D6: 9580 | E6: 3060 | F6: 6507 | G6: =AVERAGE(C6:F6) -> 7629.25 | H6: =G6/$M$2/1000 -> 1.9073125 | I6: =I5 -> 1 | J6: =H6+I6 -> 2.9073125 | K6: =ROUNDUP(J6,0) -> 3 | L6: náklad štiepka € | M6: =M4*M5 -> 480128 | O6: ='DHS25'!C5 -> 11442 | P6: ='DHS25'!D5 -> 49 | Q6: ='DHS25'!E5 -> 3000 | R6: 64.8 | S6: =(Q6/1000)*R6 -> 194.4
A7: 45658 | B7: 04:00:00 | C7: 20378 | D7: 16424 | E7: 11925 | F7: 9266 | G7: =AVERAGE(C7:F7) -> 14498.25 | H7: =G7/$M$2/1000 -> 3.6245625 | I7: =I6 -> 1 | J7: =H7+I7 -> 4.6245625 | K7: =ROUNDUP(J7,0) -> 5 | L7: teplo dodávka MWh | M7: =G747 -> 11321.178 | O7: ='DHS25'!C6 -> 16527 | P7: ='DHS25'!D6 -> 89 | Q7: ='DHS25'!E6 -> 4991 | R7: 71.09 | S7: =(Q7/1000)*R7 -> 354.81019
A8: 45658 | B8: 05:00:00 | C8: 20060 | D8: 18327 | E8: 11649 | F8: 16002 | G8: =AVERAGE(C8:F8) -> 16509.5 | H8: =G8/$M$2/1000 -> 4.127375 | I8: =I7 -> 1 | J8: =H8+I8 -> 5.127375 | K8: =ROUNDUP(J8,0) -> 6 | L8: EE dodávka MWh | M8: =K747 -> 3968 | O8: ='DHS25'!C7 -> 19516 | P8: ='DHS25'!D7 -> 60 | Q8: ='DHS25'!E7 -> 5988 | R8: 3 | S8: =(Q8/1000)*R8 -> 17.964
A9: 45658 | B9: 06:00:00 | C9: 19128 | D9: 17300 | E9: 15412 | F9: 14947 | G9: =AVERAGE(C9:F9) -> 16696.75 | H9: =G9/$M$2/1000 -> 4.1741875 | I9: =I8 -> 1 | J9: =H9+I9 -> 5.1741875 | K9: =ROUNDUP(J9,0) -> 6 | L9: tržba VZ teplo | M9: =M4/5/0.787*M7 -> 316475.11 | O9: ='DHS25'!C8 -> 19152 | P9: ='DHS25'!D8 -> 25 | Q9: ='DHS25'!E8 -> 6004 | R9: -3.67 | S9: =(Q9/1000)*R9 -> -22.03468
A10: 45658 | B10: 07:00:00 | C10: 15697 | D10: 14123 | E10: 11700 | F10: 11794 | G10: =AVERAGE(C10:F10) -> 13328.5 | H10: =G10/$M$2/1000 -> 3.332125 | I10: =I9 -> 1 | J10: =H10+I10 -> 4.332125 | K10: =ROUNDUP(J10,0) -> 5 | L10: EE náklad na štiepku €/MWh | M10: =(M6-M9)/M8 -> 41.243168 | O10: ='DHS25'!C9 -> 19102 | P10: ='DHS25'!D9 -> 111 | Q10: ='DHS25'!E9 -> 5888 | R10: -5.71 | S10: =(Q10/1000)*R10 -> -33.62048
A11: 45658 | B11: 08:00:00 | C11: 16072 | D11: 15030 | E11: 9900 | F11: 9948 | G11: =AVERAGE(C11:F11) -> 12737.5 | H11: =G11/$M$2/1000 -> 3.184375 | I11: =I10 -> 1 | J11: =H11+I11 -> 4.184375 | K11: =ROUNDUP(J11,0) -> 5 | O11: ='DHS25'!C10 -> 16175 | P11: ='DHS25'!D10 -> 80 | Q11: ='DHS25'!E10 -> 5000 | R11: 18.94 | S11: =(Q11/1000)*R11 -> 94.7
A12: 45658 | B12: 09:00:00 | C12: 16398 | D12: 14735 | E12: 11947 | F12: 12527 | G12: =AVERAGE(C12:F12) -> 13901.75 | H12: =G12/$M$2/1000 -> 3.4754375 | I12: =I11 -> 1 | J12: =H12+I12 -> 4.4754375 | K12: =ROUNDUP(J12,0) -> 5 | O12: ='DHS25'!C11 -> 15994 | P12: ='DHS25'!D11 -> 28 | Q12: ='DHS25'!E11 -> 5001 | R12: 26.27 | S12: =(Q12/1000)*R12 -> 131.37627
A13: 45658 | B13: 10:00:00 | C13: 15771 | D13: 15635 | E13: 11512 | F13: 12019 | G13: =AVERAGE(C13:F13) -> 13734.25 | H13: =G13/$M$2/1000 -> 3.4335625 | I13: =I12 -> 1 | J13: =H13+I13 -> 4.4335625 | K13: =ROUNDUP(J13,0) -> 5 | O13: ='DHS25'!C12 -> 17102 | P13: ='DHS25'!D12 -> 69 | Q13: ='DHS25'!E12 -> 5503 | R13: 13 | S13: =(Q13/1000)*R13 -> 71.539
A14: 45658 | B14: 11:00:00 | C14: 15834 | D14: 14780 | E14: 10799 | F14: 14144 | G14: =AVERAGE(C14:F14) -> 13889.25 | H14: =G14/$M$2/1000 -> 3.4723125 | I14: =I13 -> 1 | J14: =H14+I14 -> 4.4723125 | K14: =ROUNDUP(J14,0) -> 5 | O14: ='DHS25'!C13 -> 18129 | P14: ='DHS25'!D13 -> 115 | Q14: ='DHS25'!E13 -> 5695 | R14: 17 | S14: =(Q14/1000)*R14 -> 96.815
A15: 45658 | B15: 12:00:00 | C15: 16020 | D15: 15205 | E15: 11834 | F15: 14230 | G15: =AVERAGE(C15:F15) -> 14322.25 | H15: =G15/$M$2/1000 -> 3.5805625 | I15: =I14 -> 1 | J15: =H15+I15 -> 4.5805625 | K15: =ROUNDUP(J15,0) -> 5 | O15: ='DHS25'!C14 -> 18592 | P15: ='DHS25'!D14 -> 83 | Q15: ='DHS25'!E14 -> 5708 | R15: 13.62 | S15: =(Q15/1000)*R15 -> 77.74296
A16: 45658 | B16: 13:00:00 | C16: 16600 | D16: 14878 | E16: 11645 | F16: 13460 | G16: =AVERAGE(C16:F16) -> 14145.75 | H16: =G16/$M$2/1000 -> 3.5364375 | I16: =I15 -> 1 | J16: =H16+I16 -> 4.5364375 | K16: =ROUNDUP(J16,0) -> 5 | O16: ='DHS25'!C15 -> 17759 | P16: ='DHS25'!D15 -> 103 | Q16: ='DHS25'!E15 -> 5401 | R16: 23 | S16: =(Q16/1000)*R16 -> 124.223
A17: 45658 | B17: 14:00:00 | C17: 15680 | D17: 13595 | E17: 11231 | F17: 13450 | G17: =AVERAGE(C17:F17) -> 13489 | H17: =G17/$M$2/1000 -> 3.37225 | I17: =I16 -> 1 | J17: =H17+I17 -> 4.37225 | K17: =ROUNDUP(J17,0) -> 5 | O17: ='DHS25'!C16 -> 17104 | P17: ='DHS25'!D16 -> 23 | Q17: ='DHS25'!E16 -> 5257 | R17: 66.8 | S17: =(Q17/1000)*R17 -> 351.1676
A18: 45658 | B18: 15:00:00 | C18: 16079 | D18: 13736 | E18: 10983 | F18: 14406 | G18: =AVERAGE(C18:F18) -> 13801 | H18: =G18/$M$2/1000 -> 3.45025 | I18: =I17 -> 1 | J18: =H18+I18 -> 4.45025 | K18: =ROUNDUP(J18,0) -> 5 | O18: ='DHS25'!C17 -> 17064 | P18: ='DHS25'!D17 -> 22 | Q18: ='DHS25'!E17 -> 5299 | R18: 106.12 | S18: =(Q18/1000)*R18 -> 562.32988
A19: 45658 | B19: 16:00:00 | C19: 17070 | D19: 14998 | E19: 11198 | F19: 13504 | G19: =AVERAGE(C19:F19) -> 14192.5 | H19: =G19/$M$2/1000 -> 3.548125 | I19: =I18 -> 1 | J19: =H19+I19 -> 4.548125 | K19: =ROUNDUP(J19,0) -> 5 | O19: ='DHS25'!C18 -> 18609 | P19: ='DHS25'!D18 -> 279 | Q19: ='DHS25'!E18 -> 5706 | R19: 92.4 | S19: =(Q19/1000)*R19 -> 527.2344
A20: 45658 | B20: 17:00:00 | C20: 18961 | D20: 15179 | E20: 11327 | F20: 12671 | G20: =AVERAGE(C20:F20) -> 14534.5 | H20: =G20/$M$2/1000 -> 3.633625 | I20: =I19 -> 1 | J20: =H20+I20 -> 4.633625 | K20: =ROUNDUP(J20,0) -> 5 | O20: ='DHS25'!C19 -> 18475 | P20: ='DHS25'!D19 -> 22 | Q20: ='DHS25'!E19 -> 5691 | R20: 81.3 | S20: =(Q20/1000)*R20 -> 462.6783
A21: 45658 | B21: 18:00:00 | C21: 18411 | D21: 14363 | E21: 11249 | F21: 14250 | G21: =AVERAGE(C21:F21) -> 14568.25 | H21: =G21/$M$2/1000 -> 3.6420625 | I21: =I20 -> 1 | J21: =H21+I21 -> 4.6420625 | K21: =ROUNDUP(J21,0) -> 5 | O21: ='DHS25'!C20 -> 18488 | P21: ='DHS25'!D20 -> 168 | Q21: ='DHS25'!E20 -> 5704 | R21: 154.26 | S21: =(Q21/1000)*R21 -> 879.89904
A22: 45658 | B22: 19:00:00 | C22: 18783 | D22: 15492 | E22: 11556 | F22: 13394 | G22: =AVERAGE(C22:F22) -> 14806.25 | H22: =G22/$M$2/1000 -> 3.7015625 | I22: =I21 -> 1 | J22: =H22+I22 -> 4.7015625 | K22: =ROUNDUP(J22,0) -> 5 | O22: ='DHS25'!C21 -> 18299 | P22: ='DHS25'!D21 -> 24 | Q22: ='DHS25'!E21 -> 5714 | R22: 162.05 | S22: =(Q22/1000)*R22 -> 925.9537
... A746: 45688 | B746: 23:00:00 | C746: 7323 | D746: 12484 | E746: 7973 | F746: 8266 | G746: =AVERAGE(C746:F746) -> 9011.5 | H746: =G746/$M$2/1000 -> 2.252875 | I746: =I745 -> 1 | J746: =H746+I746 -> 3.252875 | K746: =ROUNDUP(J746,0) -> 4 | O746: ='DHS25'!C745 -> 7665 | P746: ='DHS25'!D745 -> 4758 | Q746: ='DHS25'!E745 -> 3932 | R746: 134.18 | S746: =(Q746/1000)*R746 -> 527.59576
G747: =SUM(G3:G746)/1000 -> 11321.178 | H747: =SUM(H3:H746) -> 2830.2944 | I747: =SUM(I3:I746) -> 744 | J747: =SUM(J3:J746) -> 3574.2944 | K747: =SUM(K3:K746) -> 3968 | S747: =SUM(S3:S746) -> 701120.04

Sheet DHS20
A1: $Date | B1: $Time | C1: IIN_LEISTUNG-NETZ | D1: IIN_TE_VORLAUF-NETZ | E1: IID_DAMPFDRUCK1-HEIZKONDENSATOR | F1: IIN_LEISTUNG-REGELKUEHLKREIS | G1: IIAN_DTU_GEN_WIRKLEISTUNG
A2: 01/01/20 | B2: 00:00:00 | C2: 6127 | D2: 78 | E2: -0.42 | F2: 17146 | G2: 8188
A3: 01/01/20 | B3: 01:00:00 | C3: 7742 | D3: 78.2 | E3: -0.428 | F3: 16107 | G3: 8210
A4: 01/01/20 | B4: 02:00:00 | C4: 9368 | D4: 77.7 | E4: -0.435 | F4: 14446 | G4: 8180
A5: 01/01/20 | B5: 03:00:00 | C5: 11370 | D5: 77.8 | E5: -0.436 | F5: 12534 | G5: 8195
A6: 01/01/20 | B6: 04:00:00 | C6: 20378 | D6: 78.2 | E6: -0.422 | F6: 3282 | G6: 8212
A7: 01/01/20 | B7: 05:00:00 | C7: 20060 | D7: 78.1 | E7: -0.416 | F7: 3889 | G7: 8202
A8: 01/01/20 | B8: 06:00:00 | C8: 19128 | D8: 78.5 | E8: -0.409 | F8: 4434 | G8: 8178
A9: 01/01/20 | B9: 07:00:00 | C9: 15697 | D9: 78.6 | E9: -0.411 | F9: 8280 | G9: 8204
A10: 01/01/20 | B10: 08:00:00 | C10: 16072 | D10: 78.7 | E10: -0.413 | F10: 7760 | G10: 8204
A11: 01/01/20 | B11: 09:00:00 | C11: 16398 | D11: 78.3 | E11: -0.42 | F11: 7779 | G11: 8206
A12: 01/01/20 | B12: 10:00:00 | C12: 15771 | D12: 77.9 | E12: -0.418 | F12: 7728 | G12: 8201
A13: 01/01/20 | B13: 11:00:00 | C13: 15834 | D13: 77.7 | E13: -0.417 | F13: 7458 | G13: 8171
... A49: 01/02/20 | B49: 23:00:00 | C49: 8038 | D49: 81.1 | E49: -0.379 | F49: 16317 | G49: 8204
A50: 01/03/20 | B50: 00:00:00
A51: 01/03/20 | B51: 01:00:00
A52: 01/03/20 | B52: 02:00:00
A53: 01/03/20 | B53: 03:00:00
A54: 01/03/20 | B54: 04:00:00
A55: 01/03/20 | B55: 05:00:00
A56: 01/03/20 | B56: 06:00:00
A57: 01/03/20 | B57: 07:00:00
A58: 01/03/20 | B58: 08:00:00 | C58: 18692 | D58: 81.3 | E58: -0.344 | F58: 4711 | G58: 8177
A59: 01/03/20 | B59: 09:00:00 | C59: 19893 | D59: 81.3 | E59: -0.353 | F59: 3701 | G59: 8082
A60: 01/03/20 | B60: 10:00:00 | C60: 19605 | D60: 81.2 | E60: -0.353 | F60: 3932 | G60: 8178
A61: 01/03/20 | B61: 11:00:00 | C61: 20343 | D61: 81.4 | E61: -0.35 | F61: 3639 | G61: 8146
A62: 01/03/20 | B62: 12:00:00 | C62: 19411 | D62: 81.2 | E62: -0.353 | F62: 4410 | G62: 8152
A63: 01/03/20 | B63: 13:00:00 | C63: 19432 | D63: 81.2 | E63: -0.354 | F63: 4813 | G63: 8181
A64: 01/03/20 | B64: 14:00:00 | C64: 19107 | D64: 81 | E64: -0.353 | F64: 4469 | G64: 8205
A65: 01/03/20 | B65: 15:00:00 | C65: 19440 | D65: 81.1 | E65: -0.353 | F65: 4616 | G65: 8190
A66: 01/03/20 | B66: 16:00:00 | C66: 18906 | D66: 80.9 | E66: -0.36 | F66: 4764 | G66: 8160
A67: 01/03/20 | B67: 17:00:00 | C67: 18865 | D67: 80.3 | E67: -0.374 | F67: 5129 | G67: 8200
A68: 01/03/20 | B68: 18:00:00 | C68: 19659 | D68: 81 | E68: -0.35 | F68: 3989 | G68: 8206
A69: 01/03/20 | B69: 19:00:00 | C69: 19864 | D69: 81.3 | E69: -0.347 | F69: 4340 | G69: 8195
... A183: 01/08/20 | B183: 13:00:00 | C183: 18702 | D183: 80.1 | E183: -0.379 | F183: 4541 | G183: 8187
A184: 01/08/20 | B184: 14:00:00
A185: 01/08/20 | B185: 15:00:00 | C185: 18738 | D185: 79.9 | E185: -0.38 | F185: 4881 | G185: 8185
A186: 01/08/20 | B186: 16:00:00 | C186: 19651 | D186: 80.8 | E186: -0.367 | F186: 3918 | G186: 8200
A187: 01/08/20 | B187: 17:00:00 | C187: 21800 | D187: 81.2 | E187: -0.359 | F187: 1458 | G187: 7946
A188: 01/08/20 | B188: 18:00:00 | C188: 22238 | D188: 82 | E188: -0.34 | F188: 1618 | G188: 8124
...

Sheet DHS21
A1: $Date | B1: $Time | C1: IIN_LEISTUNG-NETZ | D1: IIN_TE_VORLAUF-NETZ | E1: IID_DAMPFDRUCK1-HEIZKONDENSATOR | F1: IIN_LEISTUNG-REGELKUEHLKREIS | G1: IIAN_DTU_GEN_WIRKLEISTUNG
A2: 01/01/21 | B2: 00:00:00 | C2: 7558 | D2: 79.6 | E2: -0.491 | F2: 15854 | G2: 8208
A3: 01/01/21 | B3: 01:00:00 | C3: 7830 | D3: 79.3 | E3: -0.496 | F3: 15254 | G3: 8203
A4: 01/01/21 | B4: 02:00:00 | C4: 9217 | D4: 79.3 | E4: -0.494 | F4: 14421 | G4: 8199
A5: 01/01/21 | B5: 03:00:00 | C5: 9580 | D5: 79.3 | E5: -0.49 | F5: 13439 | G5: 8147
A6: 01/01/21 | B6: 04:00:00 | C6: 16424 | D6: 79.4 | E6: -0.499 | F6: 7623 | G6: 8203
A7: 01/01/21 | B7: 05:00:00 | C7: 18327 | D7: 79.6 | E7: -0.49 | F7: 5560 | G7: 8208
A8: 01/01/21 | B8: 06:00:00 | C8: 17300 | D8: 79.6 | E8: -0.483 | F8: 6023 | G8: 8200
A9: 01/01/21 | B9: 07:00:00 | C9: 14123 | D9: 79.6 | E9: -0.49 | F9: 10014 | G9: 8183
A10: 01/01/21 | B10: 08:00:00 | C10: 15030 | D10: 79.8 | E10: -0.484 | F10: 8781 | G10: 8189
A11: 01/01/21 | B11: 09:00:00 | C11: 14735 | D11: 79.6 | E11: -0.487 | F11: 8646 | G11: 8201
A12: 01/01/21 | B12: 10:00:00 | C12: 15635 | D12: 79.6 | E12: -0.487 | F12: 7361 | G12: 8186
A13: 01/01/21 | B13: 11:00:00 | C13: 14780 | D13: 79.3 | E13: -0.491 | F13: 8197 | G13: 8195
... A746: 02/01/21 | B746: 00:00:00 | C746: 13500 | D746: 84.6 | E746: -0.387 | F746: 10119 | G746: 8160

Sheet DHS23
A1: $Date | B1: $Time | C1: IIN_LEISTUNG-NETZ | D1: IIN_TE_VORLAUF-NETZ | E1: IID_DAMPFDRUCK1-HEIZKONDENSATOR | F1: IIN_LEISTUNG-REGELKUEHLKREIS | G1: IIAN_DTU_GEN_WIRKLEISTUNG
A2: 01/01/23 | B2: 00:00:00 | C2: 2689 | D2: 78.6 | E2: -0.499 | F2: 96 | G2: 5699
A3: 01/01/23 | B3: 01:00:00 | C3: 2551 | D3: 78.5 | E3: -0.516 | F3: 64 | G3: 4989
A4: 01/01/23 | B4: 02:00:00 | C4: 4289 | D4: 79.3 | E4: -0.507 | F4: 33 | G4: 5019
A5: 01/01/23 | B5: 03:00:00 | C5: 3060 | D5: 78.8 | E5: -0.507 | F5: 85 | G5: 4991
A6: 01/01/23 | B6: 04:00:00 | C6: 11925 | D6: 78.2 | E6: -0.497 | F6: 94 | G6: 4998
A7: 01/01/23 | B7: 05:00:00 | C7: 11649 | D7: 78.6 | E7: -0.492 | F7: 68 | G7: 5005
A8: 01/01/23 | B8: 06:00:00 | C8: 15412 | D8: 77.7 | E8: -0.509 | F8: 93 | G8: 4997
A9: 01/01/23 | B9: 07:00:00 | C9: 11700 | D9: 78.3 | E9: -0.506 | F9: 74 | G9: 5036
A10: 01/01/23 | B10: 08:00:00 | C10: 9900 | D10: 77.3 | E10: -0.528 | F10: 102 | G10: 4994
A11: 01/01/23 | B11: 09:00:00 | C11: 11947 | D11: 77.8 | E11: -0.508 | F11: 31 | G11: 5000
A12: 01/01/23 | B12: 10:00:00 | C12: 11512 | D12: 77.6 | E12: -0.517 | F12: 31 | G12: 5023
A13: 01/01/23 | B13: 11:00:00 | C13: 10799 | D13: 77 | E13: -0.523 | F13: 74 | G13: 4996
... A746: 02/01/23 | B746: 00:00:00 | C746: 6187 | D746: 79.7 | E746: -0.48 | F746: 6109 | G746: 3989

Sheet DHS24
A1: $Date | B1: $Time | C1: IIN_LEISTUNG-NETZ | D1: IIN_TE_VORLAUF-NETZ | E1: IID_DAMPFDRUCK1-HEIZKONDENSATOR | F1: IIN_LEISTUNG-REGELKUEHLKREIS | G1: IIAN_DTU_GEN_WIRKLEISTUNG
A2: 01/01/24 | B2: 00:00:00 | C2: 3668 | D2: 79.5 | E2: 0.025 | F2: 87 | G2: 0
A3: 01/01/24 | B3: 01:00:00 | C3: 4046 | D3: 81.3 | E3: 0.018 | F3: 23 | G3: 0
A4: 01/01/24 | B4: 02:00:00 | C4: 4026 | D4: 79.9 | E4: 0.016 | F4: 31 | G4: 0
A5: 01/01/24 | B5: 03:00:00 | C5: 6507 | D5: 80.4 | E5: 0.038 | F5: 80 | G5: 0
A6: 01/01/24 | B6: 04:00:00 | C6: 9266 | D6: 79.2 | E6: 0.04 | F6: 57 | G6: 0
A7: 01/01/24 | B7: 05:00:00 | C7: 16002 | D7: 80.7 | E7: 0.069 | F7: 46 | G7: 0
A8: 01/01/24 | B8: 06:00:00 | C8: 14947 | D8: 79.7 | E8: 0.043 | F8: 145 | G8: 0
A9: 01/01/24 | B9: 07:00:00 | C9: 11794 | D9: 81.3 | E9: 0.011 | F9: 111 | G9: 0
A10: 01/01/24 | B10: 08:00:00 | C10: 9948 | D10: 79.6 | E10: -0.005 | F10: 151 | G10: 0
A11: 01/01/24 | B11: 09:00:00 | C11: 12527 | D11: 80.1 | E11: 0.047 | F11: 132 | G11: 0
A12: 01/01/24 | B12: 10:00:00 | C12: 12019 | D12: 77 | E12: 0.007 | F12: 170 | G12: 0
A13: 01/01/24 | B13: 11:00:00 | C13: 14144 | D13: 80 | E13: 0.073 | F13: 214 | G13: 0
... A746: 02/01/24 | B746: 00:00:00 | C746: 8299 | D746: 90.4 | E746: 0.056 | F746: 20 | G746: 0

Sheet DHS25
A1: $Date | B1: $Time | C1: IIN_LEISTUNG-NETZ | D1: IIN_LEISTUNG-REGELKUEHLKREIS | E1: IIAN_DTU_GEN_WIRKLEISTUNG
A2: 01/01/25 | B2: 00:00:00 | C2: 9904 | D2: 4296 | E2: 4043
A3: 01/01/25 | B3: 01:00:00 | C3: 9949 | D3: 1848 | E3: 3007
A4: 01/01/25 | B4: 02:00:00 | C4: 11129 | D4: 309 | E4: 2996
A5: 01/01/25 | B5: 03:00:00 | C5: 11442 | D5: 49 | E5: 3000
A6: 01/01/25 | B6: 04:00:00 | C6: 16527 | D6: 89 | E6: 4991
A7: 01/01/25 | B7: 05:00:00 | C7: 19516 | D7: 60 | E7: 5988
A8: 01/01/25 | B8: 06:00:00 | C8: 19152 | D8: 25 | E8: 6004
A9: 01/01/25 | B9: 07:00:00 | C9: 19102 | D9: 111 | E9: 5888
A10: 01/01/25 | B10: 08:00:00 | C10: 16175 | D10: 80 | E10: 5000
A11: 01/01/25 | B11: 09:00:00 | C11: 15994 | D11: 28 | E11: 5001
A12: 01/01/25 | B12: 10:00:00 | C12: 17102 | D12: 69 | E12: 5503
A13: 01/01/25 | B13: 11:00:00 | C13: 18129 | D13: 115 | E13: 5695
... A217: 01/09/25 | B217: 23:00:00 | C217: 5128 | D217: 12292 | E217: 5516
A218: 45931 | B218: 00:00:00 | C218: 3335 | D218: 9840 | E218: 3993
A219: 45931 | B219: 0.041666667 | C219: 3653 | D219: 9511 | E219: 4004
A220: 45931 | B220: 0.083333333 | C220: 3621 | D220: 10093 | E220: 4004
A221: 45931 | B221: 0.125 | C221: 3694 | D221: 9626 | E221: 3990
A222: 45931 | B222: 0.16666667 | C222: 7022 | D222: 10175 | E222: 5910
A223: 45931 | B223: 0.20833333 | C223: 15181 | D223: 3496 | E223: 5993
A224: 45931 | B224: 0.25 | C224: 18852 | D224: 4842 | E224: 7883
A225: 45931 | B225: 0.29166667 | C225: 17672 | D225: 6609 | E225: 7936
A226: 45931 | B226: 0.33333333 | C226: 16996 | D226: 7337 | E226: 8006
A227: 45931 | B227: 0.375 | C227: 16894 | D227: 7170 | E227: 8003
A228: 45931 | B228: 0.41666667 | C228: 17110 | D228: 4835 | E228: 7487
A229: 45931 | B229: 0.45833333 | C229: 16662 | D229: 1787 | E229: 6001
A230: 45931 | B230: 0.5 | C230: 16629 | D230: 2273 | E230: 6030
... A241: 45931 | B241: 0.95833333 | C241: 9401 | D241: 4992 | E241: 5429
A242: 45962 | B242: 00:00:00 | C242: 10213 | D242: 3880 | E242: 3992
A243: 01/11/25 | B243: 01:00:00 | C243: 10769 | D243: 3030 | E243: 4004
A244: 01/11/25 | B244: 02:00:00 | C244: 13047 | D244: 1246 | E244: 4003
A245: 01/11/25 | B245: 03:00:00 | C245: 12728 | D245: 4187 | E245: 4988
A246: 01/11/25 | B246: 04:00:00 | C246: 19534 | D246: 222 | E246: 6008
A247: 01/11/25 | B247: 05:00:00 | C247: 19223 | D247: 143 | E247: 5999
A248: 01/11/25 | B248: 06:00:00 | C248: 19816 | D248: 22 | E248: 6189
A249: 01/11/25 | B249: 07:00:00 | C249: 19796 | D249: 65 | E249: 6210
A250: 01/11/25 | B250: 08:00:00 | C250: 18657 | D250: 21 | E250: 5986
A251: 01/11/25 | B251: 09:00:00 | C251: 18208 | D251: 1088 | E251: 6011
A252: 01/11/25 | B252: 10:00:00 | C252: 16389 | D252: 2894 | E252: 6013
A253: 01/11/25 | B253: 11:00:00 | C253: 14839 | D253: 1226 | E253: 5206
...

Sheet kalkulácia leto
A1: cena štiepky €/ATT | B1: 110
A2: spotreba štiepky ATT | B2: =B5*1.1 -> 818.4
A3: náklad štiepka € | B3: =B1*B2 -> 90024
A4: teplo dodávka MWh | B4: 1800
A5: EE dodávka MWh | B5: =31*24*C5 -> 744 | C5: 1
A6: tržba VZ teplo | B6: =B1/5/0.787*B4 -> 50317.662
A7: EE náklad na štiepku €/MWh | B7: =(B3-B6)/B5 -> 53.368734

Sheet Hárok1
A1: Mesačná Predikcia výroby (Január 2025)
A3: Obchodný deň | B3: Obchodná hodina | Z3: SPOLU
A4: v mesiaci | B4: 1 | C4: 2 | D4: 3 | E4: 4 | F4: 5 | G4: 6 | H4: 7 | I4: 8 | J4: 9 | K4: 10 | L4: 11 | M4: 12 | N4: 13 | O4: 14 | P4: 15 | Q4: 16 | R4: 17 | S4: 18 | T4: 19 | U4: 20 | V4: 21 | W4: 22 | X4: 23 | Y4: 24
A5: 1. | B5: =predikcia!$K3 -> 3 | C5: =predikcia!$K4 -> 3 | D5: =predikcia!$K5 -> 3 | E5: =predikcia!$K6 -> 3 | F5: =predikcia!$K7 -> 5 | G5: =predikcia!$K8 -> 6 | H5: =predikcia!$K9 -> 6 | I5: =predikcia!$K10 -> 5 | J5: =predikcia!$K11 -> 5 | K5: =predikcia!$K12 -> 5 | L5: =predikcia!$K13 -> 5 | M5: =predikcia!$K14 -> 5 | N5: =predikcia!$K15 -> 5 | O5: =predikcia!$K16 -> 5 | P5: =predikcia!$K17 -> 5 | Q5: =predikcia!$K18 -> 5 | R5: =predikcia!$K19 -> 5 | S5: =predikcia!$K20 -> 5 | T5: =predikcia!$K21 -> 5 | U5: =predikcia!$K22 -> 5 | V5: =predikcia!$K23 -> 5 | W5: =predikcia!$K24 -> 5 | X5: =predikcia!$K25 -> 5 | Y5: =predikcia!$K26 -> 3 | Z5: =SUM(B5:Y5) -> 112
A6: 2. | B6: =predikcia!$K27 -> 3 | C6: =predikcia!$K28 -> 4 | D6: =predikcia!$K29 -> 4 | E6: =predikcia!$K30 -> 4 | F6: =predikcia!$K31 -> 5 | G6: =predikcia!$K32 -> 6 | H6: =predikcia!$K33 -> 6 | I6: =predikcia!$K34 -> 5 | J6: =predikcia!$K35 -> 5 | K6: =predikcia!$K36 -> 5 | L6: =predikcia!$K37 -> 5 | M6: =predikcia!$K38 -> 5 | N6: =predikcia!$K39 -> 5 | O6: =predikcia!$K40 -> 5 | P6: =predikcia!$K41 -> 5 | Q6: =predikcia!$K42 -> 5 | R6: =predikcia!$K43 -> 5 | S6: =predikcia!$K44 -> 5 | T6: =predikcia!$K45 -> 5 | U6: =predikcia!$K46 -> 5 | V6: =predikcia!$K47 -> 5 | W6: =predikcia!$K48 -> 5 | X6: =predikcia!$K49 -> 5 | Y6: =predikcia!$K50 -> 3 | Z6: =SUM(B6:Y6) -> 115
A7: 3. | B7: =predikcia!$K51 -> 3 | C7: =predikcia!$K52 -> 3 | D7: =predikcia!$K53 -> 4 | E7: =predikcia!$K54 -> 4 | F7: =predikcia!$K55 -> 6 | G7: =predikcia!$K56 -> 6 | H7: =predikcia!$K57 -> 6 | I7: =predikcia!$K58 -> 5 | J7: =predikcia!$K59 -> 5 | K7: =predikcia!$K60 -> 5 | L7: =predikcia!$K61 -> 5 | M7: =predikcia!$K62 -> 5 | N7: =predikcia!$K63 -> 5 | O7: =predikcia!$K64 -> 5 | P7: =predikcia!$K65 -> 5 | Q7: =predikcia!$K66 -> 5 | R7: =predikcia!$K67 -> 5 | S7: =predikcia!$K68 -> 5 | T7: =predikcia!$K69 -> 5 | U7: =predikcia!$K70 -> 5 | V7: =predikcia!$K71 -> 5 | W7: =predikcia!$K72 -> 5 | X7: =predikcia!$K73 -> 5 | Y7: =predikcia!$K74 -> 3 | Z7: =SUM(B7:Y7) -> 115
A8: 4. | B8: =predikcia!$K75 -> 3 | C8: =predikcia!$K76 -> 3 | D8: =predikcia!$K77 -> 4 | E8: =predikcia!$K78 -> 4 | F8: =predikcia!$K79 -> 6 | G8: =predikcia!$K80 -> 6 | H8: =predikcia!$K81 -> 6 | I8: =predikcia!$K82 -> 5 | J8: =predikcia!$K83 -> 5 | K8: =predikcia!$K84 -> 5 | L8: =predikcia!$K85 -> 5 | M8: =predikcia!$K86 -> 5 | N8: =predikcia!$K87 -> 5 | O8: =predikcia!$K88 -> 5 | P8: =predikcia!$K89 -> 5 | Q8: =predikcia!$K90 -> 5 | R8: =predikcia!$K91 -> 5 | S8: =predikcia!$K92 -> 5 | T8: =predikcia!$K93 -> 5 | U8: =predikcia!$K94 -> 5 | V8: =predikcia!$K95 -> 5 | W8: =predikcia!$K96 -> 5 | X8: =predikcia!$K97 -> 5 | Y8: =predikcia!$K98 -> 3 | Z8: =SUM(B8:Y8) -> 115
A9: 5. | B9: =predikcia!$K99 -> 3 | C9: =predikcia!$K100 -> 3 | D9: =predikcia!$K101 -> 3 | E9: =predikcia!$K102 -> 4 | F9: =predikcia!$K103 -> 6 | G9: =predikcia!$K104 -> 5 | H9: =predikcia!$K105 -> 5 | I9: =predikcia!$K106 -> 5 | J9: =predikcia!$K107 -> 5 | K9: =predikcia!$K108 -> 5 | L9: =predikcia!$K109 -> 5 | M9: =predikcia!$K110 -> 5 | N9: =predikcia!$K111 -> 5 | O9: =predikcia!$K112 -> 5 | P9: =predikcia!$K113 -> 5 | Q9: =predikcia!$K114 -> 5 | R9: =predikcia!$K115 -> 5 | S9: =predikcia!$K116 -> 5 | T9: =predikcia!$K117 -> 5 | U9: =predikcia!$K118 -> 5 | V9: =predikcia!$K119 -> 5 | W9: =predikcia!$K120 -> 5 | X9: =predikcia!$K121 -> 5 | Y9: =predikcia!$K122 -> 3 | Z9: =SUM(B9:Y9) -> 112
A10: 6. | B10: =predikcia!$K123 -> 3 | C10: =predikcia!$K124 -> 3 | D10: =predikcia!$K125 -> 3 | E10: =predikcia!$K126 -> 4 | F10: =predikcia!$K127 -> 6 | G10: =predikcia!$K128 -> 6 | H10: =predikcia!$K129 -> 6 | I10: =predikcia!$K130 -> 5 | J10: =predikcia!$K131 -> 5 | K10: =predikcia!$K132 -> 5 | L10: =predikcia!$K133 -> 5 | M10: =predikcia!$K134 -> 5 | N10: =predikcia!$K135 -> 5 | O10: =predikcia!$K136 -> 5 | P10: =predikcia!$K137 -> 5 | Q10: =predikcia!$K138 -> 5 | R10: =predikcia!$K139 -> 5 | S10: =predikcia!$K140 -> 5 | T10: =predikcia!$K141 -> 5 | U10: =predikcia!$K142 -> 5 | V10: =predikcia!$K143 -> 5 | W10: =predikcia!$K144 -> 5 | X10: =predikcia!$K145 -> 5 | Y10: =predikcia!$K146 -> 3 | Z10: =SUM(B10:Y10) -> 114
A11: 7. | B11: =predikcia!$K147 -> 3 | C11: =predikcia!$K148 -> 4 | D11: =predikcia!$K149 -> 4 | E11: =predikcia!$K150 -> 4 | F11: =predikcia!$K151 -> 6 | G11: =predikcia!$K152 -> 6 | H11: =predikcia!$K153 -> 6 | I11: =predikcia!$K154 -> 5 | J11: =predikcia!$K155 -> 5 | K11: =predikcia!$K156 -> 6 | L11: =predikcia!$K157 -> 6 | M11: =predikcia!$K158 -> 5 | N11: =predikcia!$K159 -> 6 | O11: =predikcia!$K160 -> 6 | P11: =predikcia!$K161 -> 6 | Q11: =predikcia!$K162 -> 6 | R11: =predikcia!$K163 -> 6 | S11: =predikcia!$K164 -> 6 | T11: =predikcia!$K165 -> 6 | U11: =predikcia!$K166 -> 6 | V11: =predikcia!$K167 -> 6 | W11: =predikcia!$K168 -> 6 | X11: =predikcia!$K169 -> 5 | Y11: =predikcia!$K170 -> 4 | Z11: =SUM(B11:Y11) -> 129
A12: 8. | B12: =predikcia!$K171 -> 4 | C12: =predikcia!$K172 -> 4 | D12: =predikcia!$K173 -> 4 | E12: =predikcia!$K174 -> 4 | F12: =predikcia!$K175 -> 6 | G12: =predikcia!$K176 -> 6 | H12: =predikcia!$K177 -> 6 | I12: =predikcia!$K178 -> 6 | J12: =predikcia!$K179 -> 6 | K12: =predikcia!$K180 -> 6 | L12: =predikcia!$K181 -> 6 | M12: =predikcia!$K182 -> 6 | N12: =predikcia!$K183 -> 6 | O12: =predikcia!$K184 -> 6 | P12: =predikcia!$K185 -> 6 | Q12: =predikcia!$K186 -> 6 | R12: =predikcia!$K187 -> 6 | S12: =predikcia!$K188 -> 6 | T12: =predikcia!$K189 -> 6 | U12: =predikcia!$K190 -> 6 | V12: =predikcia!$K191 -> 6 | W12: =predikcia!$K192 -> 6 | X12: =predikcia!$K193 -> 6 | Y12: =predikcia!$K171 -> 4 | Z12: =SUM(B12:Y12) -> 134
A13: 9. | B13: =predikcia!$K195 -> 3 | C13: =predikcia!$K196 -> 4 | D13: =predikcia!$K197 -> 4 | E13: =predikcia!$K198 -> 4 | F13: =predikcia!$K199 -> 6 | G13: =predikcia!$K200 -> 7 | H13: =predikcia!$K201 -> 7 | I13: =predikcia!$K202 -> 6 | J13: =predikcia!$K203 -> 6 | K13: =predikcia!$K204 -> 6 | L13: =predikcia!$K205 -> 6 | M13: =predikcia!$K206 -> 6 | N13: =predikcia!$K207 -> 6 | O13: =predikcia!$K208 -> 5 | P13: =predikcia!$K209 -> 5 | Q13: =predikcia!$K210 -> 6 | R13: =predikcia!$K211 -> 6 | S13: =predikcia!$K212 -> 6 | T13: =predikcia!$K213 -> 6 | U13: =predikcia!$K214 -> 6 | V13: =predikcia!$K215 -> 6 | W13: =predikcia!$K216 -> 6 | X13: =predikcia!$K217 -> 6 | Y13: =predikcia!$K218 -> 4 | Z13: =SUM(B13:Y13) -> 133
A14: 10. | B14: =predikcia!$K219 -> 4 | C14: =predikcia!$K220 -> 4 | D14: =predikcia!$K221 -> 4 | E14: =predikcia!$K222 -> 4 | F14: =predikcia!$K223 -> 6 | G14: =predikcia!$K224 -> 6 | H14: =predikcia!$K225 -> 6 | I14: =predikcia!$K226 -> 6 | J14: =predikcia!$K227 -> 6 | K14: =predikcia!$K228 -> 6 | L14: =predikcia!$K229 -> 6 | M14: =predikcia!$K230 -> 6 | N14: =predikcia!$K231 -> 6 | O14: =predikcia!$K232 -> 6 | P14: =predikcia!$K233 -> 6 | Q14: =predikcia!$K234 -> 6 | R14: =predikcia!$K235 -> 6 | S14: =predikcia!$K236 -> 6 | T14: =predikcia!$K237 -> 6 | U14: =predikcia!$K238 -> 6 | V14: =predikcia!$K239 -> 6 | W14: =predikcia!$K240 -> 6 | X14: =predikcia!$K241 -> 6 | Y14: =predikcia!$K242 -> 4 | Z14: =SUM(B14:Y14) -> 134
A15: 11. | B15: =predikcia!$K243 -> 4 | C15: =predikcia!$K244 -> 4 | D15: =predikcia!$K245 -> 4 | E15: =predikcia!$K246 -> 5 | F15: =predikcia!$K247 -> 6 | G15: =predikcia!$K248 -> 6 | H15: =predikcia!$K249 -> 6 | I15: =predikcia!$K250 -> 6 | J15: =predikcia!$K251 -> 6 | K15: =predikcia!$K252 -> 6 | L15: =predikcia!$K253 -> 6 | M15: =predikcia!$K254 -> 5 | N15: =predikcia!$K255 -> 5 | O15: =predikcia!$K256 -> 6 | P15: =predikcia!$K257 -> 6 | Q15: =predikcia!$K258 -> 6 | R15: =predikcia!$K259 -> 6 | S15: =predikcia!$K260 -> 6 | T15: =predikcia!$K261 -> 6 | U15: =predikcia!$K262 -> 6 | V15: =predikcia!$K263 -> 6 | W15: =predikcia!$K264 -> 6 | X15: =predikcia!$K265 -> 5 | Y15: =predikcia!$K266 -> 4 | Z15: =SUM(B15:Y15) -> 132
A16: 12. | B16: =predikcia!$K267 -> 4 | C16: =predikcia!$K268 -> 4 | D16: =predikcia!$K269 -> 4 | E16: =predikcia!$K270 -> 5 | F16: =predikcia!$K271 -> 6 | G16: =predikcia!$K272 -> 6 | H16: =predikcia!$K273 -> 6 | I16: =predikcia!$K274 -> 6 | J16: =predikcia!$K275 -> 6 | K16: =predikcia!$K276 -> 6 | L16: =predikcia!$K277 -> 6 | M16: =predikcia!$K278 -> 6 | N16: =predikcia!$K279 -> 6 | O16: =predikcia!$K280 -> 5 | P16: =predikcia!$K281 -> 6 | Q16: =predikcia!$K282 -> 6 | R16: =predikcia!$K283 -> 6 | S16: =predikcia!$K284 -> 6 | T16: =predikcia!$K285 -> 6 | U16: =predikcia!$K286 -> 6 | V16: =predikcia!$K287 -> 6 | W16: =predikcia!$K288 -> 6 | X16: =predikcia!$K289 -> 5 | Y16: =predikcia!$K290 -> 4 | Z16: =SUM(B16:Y16) -> 133
A17: 13. | B17: =predikcia!$K291 -> 4 | C17: =predikcia!$K292 -> 4 | D17: =predikcia!$K293 -> 4 | E17: =predikcia!$K294 -> 4 | F17: =predikcia!$K295 -> 6 | G17: =predikcia!$K296 -> 6 | H17: =predikcia!$K297 -> 6 | I17: =predikcia!$K298 -> 6 | J17: =predikcia!$K299 -> 6 | K17: =predikcia!$K300 -> 6 | L17: =predikcia!$K301 -> 6 | M17: =predikcia!$K302 -> 6 | N17: =predikcia!$K303 -> 5 | O17: =predikcia!$K304 -> 6 | P17: =predikcia!$K305 -> 5 | Q17: =predikcia!$K306 -> 5 | R17: =predikcia!$K307 -> 6 | S17: =predikcia!$K308 -> 6 | T17: =predikcia!$K309 -> 6 | U17: =predikcia!$K310 -> 6 | V17: =predikcia!$K311 -> 6 | W17: =predikcia!$K312 -> 6 | X17: =predikcia!$K313 -> 5 | Y17: =predikcia!$K314 -> 4 | Z17: =SUM(B17:Y17) -> 130
A18: 14. | B18: =predikcia!$K315 -> 4 | C18: =predikcia!$K316 -> 4 | D18: =predikcia!$K317 -> 4 | E18: =predikcia!$K316 -> 4 | F18: =predikcia!$K319 -> 6 | G18: =predikcia!$K320 -> 6 | H18: =predikcia!$K321 -> 6 | I18: =predikcia!$K322 -> 6 | J18: =predikcia!$K323 -> 6 | K18: =predikcia!$K324 -> 6 | L18: =predikcia!$K325 -> 6 | M18: =predikcia!$K326 -> 6 | N18: =predikcia!$K327 -> 5 | O18: =predikcia!$K328 -> 5 | P18: =predikcia!$K329 -> 5 | Q18: =predikcia!$K330 -> 6 | R18: =predikcia!$K331 -> 6 | S18: =predikcia!$K332 -> 5 | T18: =predikcia!$K333 -> 6 | U18: =predikcia!$K334 -> 6 | V18: =predikcia!$K335 -> 6 | W18: =predikcia!$K336 -> 6 | X18: =predikcia!$K337 -> 5 | Y18: =predikcia!$K338 -> 4 | Z18: =SUM(B18:Y18) -> 129
A19: 15. | B19: =predikcia!$K339 -> 4 | C19: =predikcia!$K340 -> 4 | D19: =predikcia!$K341 -> 4 | E19: =predikcia!$K342 -> 4 | F19: =predikcia!$K343 -> 6 | G19: =predikcia!$K344 -> 6 | H19: =predikcia!$K345 -> 6 | I19: =predikcia!$K346 -> 6 | J19: =predikcia!$K347 -> 6 | K19: =predikcia!$K348 -> 6 | L19: =predikcia!$K349 -> 6 | M19: =predikcia!$K350 -> 5 | N19: =predikcia!$K351 -> 6 | O19: =predikcia!$K352 -> 6 | P19: =predikcia!$K353 -> 6 | Q19: =predikcia!$K354 -> 6 | R19: =predikcia!$K355 -> 6 | S19: =predikcia!$K356 -> 6 | T19: =predikcia!$K357 -> 6 | U19: =predikcia!$K358 -> 6 | V19: =predikcia!$K359 -> 6 | W19: =predikcia!$K360 -> 6 | X19: =predikcia!$K361 -> 5 | Y19: =predikcia!$K362 -> 4 | Z19: =SUM(B19:Y19) -> 132
A20: 16. | B20: =predikcia!$K363 -> 4 | C20: =predikcia!$K364 -> 4 | D20: =predikcia!$K365 -> 5 | E20: =predikcia!$K366 -> 5 | F20: =predikcia!$K367 -> 6 | G20: =predikcia!$K368 -> 7 | H20: =predikcia!$K369 -> 7 | I20: =predikcia!$K370 -> 6 | J20: =predikcia!$K371 -> 6 | K20: =predikcia!$K372 -> 6 | L20: =predikcia!$K373 -> 6 | M20: =predikcia!$K374 -> 6 | N20: =predikcia!$K375 -> 5 | O20: =predikcia!$K376 -> 6 | P20: =predikcia!$K377 -> 6 | Q20: =predikcia!$K378 -> 6 | R20: =predikcia!$K379 -> 6 | S20: =predikcia!$K380 -> 6 | T20: =predikcia!$K381 -> 6 | U20: =predikcia!$K382 -> 6 | V20: =predikcia!$K383 -> 6 | W20: =predikcia!$K384 -> 6 | X20: =predikcia!$K385 -> 6 | Y20: =predikcia!$K386 -> 4 | Z20: =SUM(B20:Y20) -> 137
A21: 17. | B21: =predikcia!$K387 -> 4 | C21: =predikcia!$K388 -> 4 | D21: =predikcia!$K389 -> 4 | E21: =predikcia!$K390 -> 5 | F21: =predikcia!$K391 -> 6 | G21: =predikcia!$K392 -> 6 | H21: =predikcia!$K393 -> 7 | I21: =predikcia!$K394 -> 6 | J21: =predikcia!$K395 -> 6 | K21: =predikcia!$K396 -> 6 | L21: =predikcia!$K397 -> 6 | M21: =predikcia!$K398 -> 6 | N21: =predikcia!$K399 -> 6 | O21: =predikcia!$K400 -> 6 | P21: =predikcia!$K401 -> 6 | Q21: =predikcia!$K402 -> 6 | R21: =predikcia!$K403 -> 6 | S21: =predikcia!$K404 -> 6 | T21: =predikcia!$K405 -> 6 | U21: =predikcia!$K406 -> 6 | V21: =predikcia!$K407 -> 6 | W21: =predikcia!$K408 -> 6 | X21: =predikcia!$K409 -> 6 | Y21: =predikcia!$K387 -> 4 | Z21: =SUM(B21:Y21) -> 136
A22: 18. | B22: =predikcia!$K411 -> 4 | C22: =predikcia!$K412 -> 4 | D22: =predikcia!$K413 -> 5 | E22: =predikcia!$K414 -> 5 | F22: =predikcia!$K415 -> 6 | G22: =predikcia!$K416 -> 6 | H22: =predikcia!$K417 -> 6 | I22: =predikcia!$K418 -> 6 | J22: =predikcia!$K419 -> 6 | K22: =predikcia!$K420 -> 6 | L22: =predikcia!$K421 -> 6 | M22: =predikcia!$K422 -> 6 | N22: =predikcia!$K423 -> 6 | O22: =predikcia!$K424 -> 5 | P22: =predikcia!$K425 -> 5 | Q22: =predikcia!$K426 -> 6 | R22: =predikcia!$K427 -> 6 | S22: =predikcia!$K428 -> 6 | T22: =predikcia!$K429 -> 6 | U22: =predikcia!$K430 -> 6 | V22: =predikcia!$K431 -> 6 | W22: =predikcia!$K432 -> 6 | X22: =predikcia!$K433 -> 6 | Y22: =predikcia!$K434 -> 4 | Z22: =SUM(B22:Y22) -> 134
A23: 19. | B23: =predikcia!$K435 -> 4 | C23: =predikcia!$K436 -> 4 | D23: =predikcia!$K437 -> 5 | E23: =predikcia!$K438 -> 5 | F23: =predikcia!$K439 -> 6 | G23: =predikcia!$K440 -> 6 | H23: =predikcia!$K441 -> 6 | I23: =predikcia!$K442 -> 6 | J23: =predikcia!$K443 -> 6 | K23: =predikcia!$K444 -> 5 | L23: =predikcia!$K445 -> 6 | M23: =predikcia!$K446 -> 6 | N23: =predikcia!$K447 -> 6 | O23: =predikcia!$K448 -> 6 | P23: =predikcia!$K449 -> 6 | Q23: =predikcia!$K450 -> 6 | R23: =predikcia!$K451 -> 6 | S23: =predikcia!$K452 -> 6 | T23: =predikcia!$K453 -> 6 | U23: =predikcia!$K454 -> 6 | V23: =predikcia!$K455 -> 6 | W23: =predikcia!$K456 -> 6 | X23: =predikcia!$K457 -> 5 | Y23: =predikcia!$K458 -> 4 | Z23: =SUM(B23:Y23) -> 134
A24: 20. | B24: =predikcia!$K459 -> 4 | C24: =predikcia!$K460 -> 4 | D24: =predikcia!$K461 -> 4 | E24: =predikcia!$K462 -> 4 | F24: =predikcia!$K463 -> 6 | G24: =predikcia!$K464 -> 6 | H24: =predikcia!$K465 -> 6 | I24: =predikcia!$K466 -> 6 | J24: =predikcia!$K467 -> 6 | K24: =predikcia!$K468 -> 6 | L24: =predikcia!$K469 -> 6 | M24: =predikcia!$K470 -> 6 | N24: =predikcia!$K471 -> 6 | O24: =predikcia!$K472 -> 6 | P24: =predikcia!$K473 -> 6 | Q24: =predikcia!$K474 -> 6 | R24: =predikcia!$K475 -> 6 | S24: =predikcia!$K476 -> 6 | T24: =predikcia!$K477 -> 6 | U24: =predikcia!$K478 -> 6 | V24: =predikcia!$K479 -> 6 | W24: =predikcia!$K480 -> 6 | X24: =predikcia!$K481 -> 5 | Y24: =predikcia!$K482 -> 4 | Z24: =SUM(B24:Y24) -> 133
A25: 21. | B25: =predikcia!$K483 -> 4 | C25: =predikcia!$K484 -> 4 | D25: =predikcia!$K485 -> 4 | E25: =predikcia!$K486 -> 4 | F25: =predikcia!$K487 -> 6 | G25: =predikcia!$K488 -> 6 | H25: =predikcia!$K489 -> 6 | I25: =predikcia!$K490 -> 6 | J25: =predikcia!$K491 -> 6 | K25: =predikcia!$K492 -> 6 | L25: =predikcia!$K493 -> 6 | M25: =predikcia!$K494 -> 6 | N25: =predikcia!$K495 -> 5 | O25: =predikcia!$K496 -> 5 | P25: =predikcia!$K497 -> 5 | Q25: =predikcia!$K498 -> 5 | R25: =predikcia!$K499 -> 6 | S25: =predikcia!$K500 -> 6 | T25: =predikcia!$K501 -> 6 | U25: =predikcia!$K502 -> 6 | V25: =predikcia!$K503 -> 6 | W25: =predikcia!$K504 -> 6 | X25: =predikcia!$K505 -> 5 | Y25: =predikcia!$K506 -> 4 | Z25: =SUM(B25:Y25) -> 129
A26: 22. | B26: =predikcia!$K507 -> 4 | C26: =predikcia!$K508 -> 4 | D26: =predikcia!$K509 -> 4 | E26: =predikcia!$K510 -> 4 | F26: =predikcia!$K511 -> 6 | G26: =predikcia!$K512 -> 6 | H26: =predikcia!$K513 -> 6 | I26: =predikcia!$K514 -> 6 | J26: =predikcia!$K515 -> 6 | K26: =predikcia!$K516 -> 6 | L26: =predikcia!$K517 -> 6 | M26: =predikcia!$K518 -> 6 | N26: =predikcia!$K519 -> 6 | O26: =predikcia!$K520 -> 5 | P26: =predikcia!$K521 -> 5 | Q26: =predikcia!$K522 -> 5 | R26: =predikcia!$K523 -> 6 | S26: =predikcia!$K524 -> 6 | T26: =predikcia!$K525 -> 6 | U26: =predikcia!$K526 -> 6 | V26: =predikcia!$K527 -> 6 | W26: =predikcia!$K528 -> 6 | X26: =predikcia!$K529 -> 5 | Y26: =predikcia!$K530 -> 4 | Z26: =SUM(B26:Y26) -> 130
A27: 23. | B27: =predikcia!$K531 -> 3 | C27: =predikcia!$K532 -> 3 | D27: =predikcia!$K533 -> 4 | E27: =predikcia!$K534 -> 4 | F27: =predikcia!$K535 -> 6 | G27: =predikcia!$K536 -> 6 | H27: =predikcia!$K537 -> 6 | I27: =predikcia!$K538 -> 6 | J27: =predikcia!$K539 -> 6 | K27: =predikcia!$K540 -> 6 | L27: =predikcia!$K541 -> 6 | M27: =predikcia!$K542 -> 5 | N27: =predikcia!$K543 -> 5 | O27: =predikcia!$K544 -> 5 | P27: =predikcia!$K545 -> 5 | Q27: =predikcia!$K546 -> 5 | R27: =predikcia!$K547 -> 6 | S27: =predikcia!$K548 -> 6 | T27: =predikcia!$K549 -> 6 | U27: =predikcia!$K550 -> 6 | V27: =predikcia!$K551 -> 6 | W27: =predikcia!$K552 -> 6 | X27: =predikcia!$K553 -> 5 | Y27: =predikcia!$K554 -> 4 | Z27: =SUM(B27:Y27) -> 126
A28: 24. | B28: =predikcia!$K555 -> 3 | C28: =predikcia!$K556 -> 4 | D28: =predikcia!$K557 -> 4 | E28: =predikcia!$K558 -> 4 | F28: =predikcia!$K559 -> 5 | G28: =predikcia!$K560 -> 6 | H28: =predikcia!$K561 -> 6 | I28: =predikcia!$K562 -> 6 | J28: =predikcia!$K563 -> 6 | K28: =predikcia!$K564 -> 6 | L28: =predikcia!$K565 -> 6 | M28: =predikcia!$K566 -> 5 | N28: =predikcia!$K567 -> 5 | O28: =predikcia!$K568 -> 5 | P28: =predikcia!$K569 -> 5 | Q28: =predikcia!$K570 -> 5 | R28: =predikcia!$K571 -> 6 | S28: =predikcia!$K572 -> 6 | T28: =predikcia!$K573 -> 6 | U28: =predikcia!$K574 -> 6 | V28: =predikcia!$K575 -> 6 | W28: =predikcia!$K576 -> 6 | X28: =predikcia!$K577 -> 5 | Y28: =predikcia!$K578 -> 3 | Z28: =SUM(B28:Y28) -> 125
A29: 25. | B29: =predikcia!$K579 -> 4 | C29: =predikcia!$K580 -> 4 | D29: =predikcia!$K581 -> 4 | E29: =predikcia!$K582 -> 4 | F29: =predikcia!$K583 -> 6 | G29: =predikcia!$K584 -> 6 | H29: =predikcia!$K585 -> 6 | I29: =predikcia!$K586 -> 6 | J29: =predikcia!$K587 -> 6 | K29: =predikcia!$K588 -> 6 | L29: =predikcia!$K589 -> 6 | M29: =predikcia!$K590 -> 6 | N29: =predikcia!$K591 -> 6 | O29: =predikcia!$K592 -> 6 | P29: =predikcia!$K593 -> 6 | Q29: =predikcia!$K594 -> 6 | R29: =predikcia!$K595 -> 6 | S29: =predikcia!$K596 -> 6 | T29: =predikcia!$K597 -> 6 | U29: =predikcia!$K598 -> 6 | V29: =predikcia!$K599 -> 6 | W29: =predikcia!$K600 -> 6 | X29: =predikcia!$K601 -> 5 | Y29: =predikcia!$K602 -> 4 | Z29: =SUM(B29:Y29) -> 133
A30: 26. | B30: =predikcia!$K603 -> 4 | C30: =predikcia!$K604 -> 4 | D30: =predikcia!$K605 -> 4 | E30: =predikcia!$K606 -> 4 | F30: =predikcia!$K607 -> 6 | G30: =predikcia!$K608 -> 6 | H30: =predikcia!$K609 -> 6 | I30: =predikcia!$K610 -> 6 | J30: =predikcia!$K611 -> 6 | K30: =predikcia!$K612 -> 6 | L30: =predikcia!$K613 -> 6 | M30: =predikcia!$K614 -> 5 | N30: =predikcia!$K615 -> 6 | O30: =predikcia!$K616 -> 6 | P30: =predikcia!$K617 -> 5 | Q30: =predikcia!$K618 -> 6 | R30: =predikcia!$K619 -> 6 | S30: =predikcia!$K620 -> 6 | T30: =predikcia!$K621 -> 6 | U30: =predikcia!$K622 -> 6 | V30: =predikcia!$K623 -> 6 | W30: =predikcia!$K624 -> 6 | X30: =predikcia!$K625 -> 5 | Y30: =predikcia!$K626 -> 4 | Z30: =SUM(B30:Y30) -> 131
A31: 27. | B31: =predikcia!$K627 -> 4 | C31: =predikcia!$K628 -> 4 | D31: =predikcia!$K629 -> 4 | E31: =predikcia!$K630 -> 5 | F31: =predikcia!$K631 -> 6 | G31: =predikcia!$K632 -> 6 | H31: =predikcia!$K633 -> 6 | I31: =predikcia!$K634 -> 6 | J31: =predikcia!$K635 -> 6 | K31: =predikcia!$K636 -> 6 | L31: =predikcia!$K637 -> 6 | M31: =predikcia!$K638 -> 6 | N31: =predikcia!$K639 -> 6 | O31: =predikcia!$K640 -> 5 | P31: =predikcia!$K641 -> 6 | Q31: =predikcia!$K642 -> 6 | R31: =predikcia!$K643 -> 6 | S31: =predikcia!$K644 -> 6 | T31: =predikcia!$K645 -> 6 | U31: =predikcia!$K646 -> 6 | V31: =predikcia!$K647 -> 6 | W31: =predikcia!$K648 -> 6 | X31: =predikcia!$K649 -> 5 | Y31: =predikcia!$K650 -> 3 | Z31: =SUM(B31:Y31) -> 132
A32: 28. | B32: =predikcia!$K651 -> 4 | C32: =predikcia!$K652 -> 4 | D32: =predikcia!$K653 -> 4 | E32: =predikcia!$K654 -> 4 | F32: =predikcia!$K655 -> 6 | G32: =predikcia!$K656 -> 6 | H32: =predikcia!$K657 -> 6 | I32: =predikcia!$K658 -> 6 | J32: =predikcia!$K659 -> 6 | K32: =predikcia!$K660 -> 6 | L32: =predikcia!$K661 -> 6 | M32: =predikcia!$K662 -> 6 | N32: =predikcia!$K663 -> 5 | O32: =predikcia!$K664 -> 5 | P32: =predikcia!$K665 -> 5 | Q32: =predikcia!$K666 -> 5 | R32: =predikcia!$K667 -> 6 | S32: =predikcia!$K668 -> 6 | T32: =predikcia!$K669 -> 6 | U32: =predikcia!$K670 -> 6 | V32: =predikcia!$K671 -> 6 | W32: =predikcia!$K672 -> 6 | X32: =predikcia!$K673 -> 5 | Y32: =predikcia!$K674 -> 3 | Z32: =SUM(B32:Y32) -> 128
A33: 29. | B33: =predikcia!$K675 -> 3 | C33: =predikcia!$K676 -> 4 | D33: =predikcia!$K677 -> 4 | E33: =predikcia!$K678 -> 5 | F33: =predikcia!$K679 -> 6 | G33: =predikcia!$K680 -> 6 | H33: =predikcia!$K681 -> 6 | I33: =predikcia!$K682 -> 6 | J33: =predikcia!$K683 -> 6 | K33: =predikcia!$K684 -> 6 | L33: =predikcia!$K685 -> 6 | M33: =predikcia!$K686 -> 5 | N33: =predikcia!$K687 -> 6 | O33: =predikcia!$K688 -> 6 | P33: =predikcia!$K689 -> 5 | Q33: =predikcia!$K690 -> 5 | R33: =predikcia!$K691 -> 6 | S33: =predikcia!$K692 -> 6 | T33: =predikcia!$K693 -> 6 | U33: =predikcia!$K694 -> 6 | V33: =predikcia!$K695 -> 6 | W33: =predikcia!$K696 -> 6 | X33: =predikcia!$K697 -> 5 | Y33: =predikcia!$K698 -> 4 | Z33: =SUM(B33:Y33) -> 130
A34: 30. | B34: =predikcia!$K699 -> 4 | C34: =predikcia!$K700 -> 4 | D34: =predikcia!$K701 -> 4 | E34: =predikcia!$K702 -> 4 | F34: =predikcia!$K703 -> 6 | G34: =predikcia!$K704 -> 6 | H34: =predikcia!$K705 -> 6 | I34: =predikcia!$K706 -> 6 | J34: =predikcia!$K707 -> 6 | K34: =predikcia!$K708 -> 6 | L34: =predikcia!$K709 -> 6 | M34: =predikcia!$K710 -> 5 | N34: =predikcia!$K711 -> 5 | O34: =predikcia!$K712 -> 5 | P34: =predikcia!$K713 -> 5 | Q34: =predikcia!$K714 -> 6 | R34: =predikcia!$K715 -> 6 | S34: =predikcia!$K716 -> 6 | T34: =predikcia!$K717 -> 6 | U34: =predikcia!$K718 -> 6 | V34: =predikcia!$K719 -> 6 | W34: =predikcia!$K720 -> 6 | X34: =predikcia!$K721 -> 5 | Y34: =predikcia!$K722 -> 4 | Z34: =SUM(B34:Y34) -> 129
A35: 31. | B35: =predikcia!$K723 -> 4 | C35: =predikcia!$K724 -> 4 | D35: =predikcia!$K725 -> 5 | E35: =predikcia!$K726 -> 5 | F35: =predikcia!$K727 -> 6 | G35: =predikcia!$K728 -> 6 | H35: =predikcia!$K729 -> 6 | I35: =predikcia!$K730 -> 6 | J35: =predikcia!$K731 -> 6 | K35: =predikcia!$K732 -> 6 | L35: =predikcia!$K733 -> 6 | M35: =predikcia!$K734 -> 5 | N35: =predikcia!$K735 -> 6 | O35: =predikcia!$K736 -> 5 | P35: =predikcia!$K737 -> 5 | Q35: =predikcia!$K738 -> 5 | R35: =predikcia!$K739 -> 6 | S35: =predikcia!$K740 -> 6 | T35: =predikcia!$K741 -> 6 | U35: =predikcia!$K742 -> 6 | V35: =predikcia!$K743 -> 6 | W35: =predikcia!$K744 -> 6 | X35: =predikcia!$K745 -> 6 | Y35: =predikcia!$K746 -> 4 | Z35: =SUM(B35:Y35) -> 132
