Workbook
Name Volume: 'Porovnanie 15min.'!$G$966:$G$990
Name Volume01: 'Porovnanie 15min.'!$G$966
Name Volume02: 'Porovnanie 15min.'!$G$967
Name Volume03: 'Porovnanie 15min.'!$G$968
Name Volume04: 'Porovnanie 15min.'!$G$969
Name Volume05: 'Porovnanie 15min.'!$G$970
Name Volume06: 'Porovnanie 15min.'!$G$971
Name Volume07: 'Porovnanie 15min.'!$G$972
Name Volume08: 'Porovnanie 15min.'!$G$973
Name Volume09: 'Porovnanie 15min.'!$G$974
Name Volume10: 'Porovnanie 15min.'!$G$975
Name Volume11: 'Porovnanie 15min.'!$G$976
Name Volume12: 'Porovnanie 15min.'!$G$977
Name Volume13: 'Porovnanie 15min.'!$G$978
Name Volume14: 'Porovnanie 15min.'!$G$979
Name Volume15: 'Porovnanie 15min.'!$G$980
Name Volume16: 'Porovnanie 15min.'!$G$981
Name Volume17: 'Porovnanie 15min.'!$G$982
Name Volume18: 'Porovnanie 15min.'!$G$983
Name Volume19: 'Porovnanie 15min.'!$G$984
Name Volume20: 'Porovnanie 15min.'!$G$985
Name Volume21: 'Porovnanie 15min.'!$G$986
Name Volume22: 'Porovnanie 15min.'!$G$987
Name Volume23: 'Porovnanie 15min.'!$G$988
Name Volume24: 'Porovnanie 15min.'!$G$989
Name Volume25: 'Porovnanie 15min.'!$G$990

Sheet Porovnanie 15min.
C1: Dátum | D1: Čas | E1: Skutočnosť sieť [MWh] | F1: Marič [MWh] | G1: Plán EE [MW] | H1: Skutočnosť EE [MW] | I1: Cena SK (EUR/MWh) | J1: Tržby výroba EE | K1: Táto farba znamená plán
K2: Táto farba znamená skutočnosť | L2: Táto farba znamená skutočnosť
K3: Zobchodované na intraday
K4: Zmena plánu oproti pôvodnému
K5: Použitie redučky/bypasu | L5: Plán EE pôvodný | M5: Zobchodnovanie na intraday
C6: ='Predikcia 15min.'!A3 -> 45962 | D6: ='Predikcia 15min.'!B3 -> 00:00:00 | E6: =IF(OR('DHS2025'!K3="",'DHS2025'!K2=""),"",'DHS2025'!K3-'DHS2025'!K2) -> 1.1 | F6: =IF(OR('DHS2025'!J3="",'DHS2025'!J2=""),"",'DHS2025'!J3-'DHS2025'!J2) -> 4.8 | G6: 8 | H6: =IF('DHS2025'!L2="","",'DHS2025'!L2) -> 8.00142 | I6: =IF('DHS2025'!M2="","",'DHS2025'!M2) -> 110.43 | J6: =IF(OR(I6="",H6=""),"",(I6*0.99-1.9)*H6) -> 859.55814 | L6: ='Predikcia 15min.'!K3 -> 2.5 | M6: 8
C7: ='Predikcia 15min.'!A4 -> 45962 | D7: ='Predikcia 15min.'!B4 -> 0.010416667 | E7: =IF(OR('DHS2025'!K4="",'DHS2025'!K3=""),"",'DHS2025'!K4-'DHS2025'!K3) -> 1.4 | F7: =IF(OR('DHS2025'!J4="",'DHS2025'!J3=""),"",'DHS2025'!J4-'DHS2025'!J3) -> 4.5 | G7: 8 | H7: =IF('DHS2025'!L3="","",'DHS2025'!L3) -> 8.01396 | I7: =IF('DHS2025'!M3="","",'DHS2025'!M3) -> 110 | J7: =IF(OR(I7="",H7=""),"",(I7*0.99-1.9)*H7) -> 857.49372 | L7: ='Predikcia 15min.'!K4 -> 2.5 | M7: 8
C8: ='Predikcia 15min.'!A5 -> 45962 | D8: ='Predikcia 15min.'!B5 -> 0.020833333 | E8: =IF(OR('DHS2025'!K5="",'DHS2025'!K4=""),"",'DHS2025'!K5-'DHS2025'!K4) -> 1.5 | F8: =IF(OR('DHS2025'!J5="",'DHS2025'!J4=""),"",'DHS2025'!J5-'DHS2025'!J4) -> 4.3 | G8: 8 | H8: =IF('DHS2025'!L4="","",'DHS2025'!L4) -> 8.01147 | I8: =IF('DHS2025'!M4="","",'DHS2025'!M4) -> 96.95 | J8: =IF(OR(I8="",H8=""),"",(I8*0.99-1.9)*H8) -> 753.7231 | L8: ='Predikcia 15min.'!K5 -> 2.5 | M8: 8
C9: ='Predikcia 15min.'!A6 -> 45962 | D9: ='Predikcia 15min.'!B6 -> 0.03125 | E9: =IF(OR('DHS2025'!K6="",'DHS2025'!K5=""),"",'DHS2025'!K6-'DHS2025'!K5) -> 1.7 | F9: =IF(OR('DHS2025'!J6="",'DHS2025'!J5=""),"",'DHS2025'!J6-'DHS2025'!J5) -> 4.1 | G9: 8 | H9: =IF('DHS2025'!L5="","",'DHS2025'!L5) -> 7.87629 | I9: =IF('DHS2025'!M5="","",'DHS2025'!M5) -> 63.66 | J9: =IF(OR(I9="",H9=""),"",(I9*0.99-1.9)*H9) -> 481.42562 | L9: ='Predikcia 15min.'!K6 -> 2.5 | M9: 8
C10: ='Predikcia 15min.'!A7 -> 45962 | D10: ='Predikcia 15min.'!B7 -> 0.041666667 | E10: =IF(OR('DHS2025'!K7="",'DHS2025'!K6=""),"",'DHS2025'!K7-'DHS2025'!K6) -> 2 | F10: =IF(OR('DHS2025'!J7="",'DHS2025'!J6=""),"",'DHS2025'!J7-'DHS2025'!J6) -> 1.9 | G10: 4.5 | H10: =IF('DHS2025'!L6="","",'DHS2025'!L6) -> 4.72164 | I10: =IF('DHS2025'!M6="","",'DHS2025'!M6) -> 94.75 | J10: =IF(OR(I10="",H10=""),"",(I10*0.99-1.9)*H10) -> 433.93052 | L10: ='Predikcia 15min.'!K7 -> 2.5 | M10: 4.5
C11: ='Predikcia 15min.'!A8 -> 45962 | D11: ='Predikcia 15min.'!B8 -> 0.052083333 | E11: =IF(OR('DHS2025'!K8="",'DHS2025'!K7=""),"",'DHS2025'!K8-'DHS2025'!K7) -> 1.7 | F11: =IF(OR('DHS2025'!J8="",'DHS2025'!J7=""),"",'DHS2025'!J8-'DHS2025'!J7) -> 2 | G11: 4.5 | H11: =IF('DHS2025'!L7="","",'DHS2025'!L7) -> 4.5363 | I11: =IF('DHS2025'!M7="","",'DHS2025'!M7) -> 86.87 | J11: =IF(OR(I11="",H11=""),"",(I11*0.99-1.9)*H11) -> 381.50873 | L11: ='Predikcia 15min.'!K8 -> 2.5 | M11: 4.5
C12: ='Predikcia 15min.'!A9 -> 45962 | D12: ='Predikcia 15min.'!B9 -> 0.0625 | E12: =IF(OR('DHS2025'!K9="",'DHS2025'!K8=""),"",'DHS2025'!K9-'DHS2025'!K8) -> 1.5 | F12: =IF(OR('DHS2025'!J9="",'DHS2025'!J8=""),"",'DHS2025'!J9-'DHS2025'!J8) -> 2.1 | G12: 4.5 | H12: =IF('DHS2025'!L8="","",'DHS2025'!L8) -> 4.5429 | I12: =IF('DHS2025'!M8="","",'DHS2025'!M8) -> 84.38 | J12: =IF(OR(I12="",H12=""),"",(I12*0.99-1.9)*H12) -> 370.86509 | L12: ='Predikcia 15min.'!K9 -> 3 | M12: 4.5
C13: ='Predikcia 15min.'!A10 -> 45962 | D13: ='Predikcia 15min.'!B10 -> 0.072916667 | E13: =IF(OR('DHS2025'!K10="",'DHS2025'!K9=""),"",'DHS2025'!K10-'DHS2025'!K9) -> 1.5 | F13: =IF(OR('DHS2025'!J10="",'DHS2025'!J9=""),"",'DHS2025'!J10-'DHS2025'!J9) -> 2.1 | G13: 4.5 | H13: =IF('DHS2025'!L9="","",'DHS2025'!L9) -> 4.48245 | I13: =IF('DHS2025'!M9="","",'DHS2025'!M9) -> 69.92 | J13: =IF(OR(I13="",H13=""),"",(I13*0.99-1.9)*H13) -> 301.76212 | L13: ='Predikcia 15min.'!K10 -> 2.5 | M13: 4.5
C14: ='Predikcia 15min.'!A11 -> 45962 | D14: ='Predikcia 15min.'!B11 -> 0.083333333 | E14: =IF(OR('DHS2025'!K11="",'DHS2025'!K10=""),"",'DHS2025'!K11-'DHS2025'!K10) -> 1.7 | F14: =IF(OR('DHS2025'!J11="",'DHS2025'!J10=""),"",'DHS2025'!J11-'DHS2025'!J10) -> 0.8 | G14: 2.5 | H14: =IF('DHS2025'!L10="","",'DHS2025'!L10) -> 2.5806 | I14: =IF('DHS2025'!M10="","",'DHS2025'!M10) -> 73.55 | J14: =IF(OR(I14="",H14=""),"",(I14*0.99-1.9)*H14) -> 183.00196 | L14: ='Predikcia 15min.'!K11 -> 2.5 | M14: 2.5
C15: ='Predikcia 15min.'!A12 -> 45962 | D15: ='Predikcia 15min.'!B12 -> 0.09375 | E15: =IF(OR('DHS2025'!K12="",'DHS2025'!K11=""),"",'DHS2025'!K12-'DHS2025'!K11) -> 2.2 | F15: =IF(OR('DHS2025'!J12="",'DHS2025'!J11=""),"",'DHS2025'!J12-'DHS2025'!J11) -> 0.4 | G15: 2.5 | H15: =IF('DHS2025'!L11="","",'DHS2025'!L11) -> 2.55075 | I15: =IF('DHS2025'!M11="","",'DHS2025'!M11) -> 60.58 | J15: =IF(OR(I15="",H15=""),"",(I15*0.99-1.9)*H15) -> 148.13277 | L15: ='Predikcia 15min.'!K12 -> 2.5 | M15: 2.5
C16: ='Predikcia 15min.'!A13 -> 45962 | D16: ='Predikcia 15min.'!B13 -> 0.10416667 | E16: =IF(OR('DHS2025'!K13="",'DHS2025'!K12=""),"",'DHS2025'!K13-'DHS2025'!K12) -> 2.4 | F16: =IF(OR('DHS2025'!J13="",'DHS2025'!J12=""),"",'DHS2025'!J13-'DHS2025'!J12) -> 0 | G16: 2.5 | H16: =IF('DHS2025'!L12="","",'DHS2025'!L12) -> 2.54772 | I16: =IF('DHS2025'!M12="","",'DHS2025'!M12) -> 61.58 | J16: =IF(OR(I16="",H16=""),"",(I16*0.99-1.9)*H16) -> 150.47904 | L16: ='Predikcia 15min.'!K13 -> 2.5 | M16: 2.5
C17: ='Predikcia 15min.'!A14 -> 45962 | D17: ='Predikcia 15min.'!B14 -> 0.11458333 | E17: =IF(OR('DHS2025'!K14="",'DHS2025'!K13=""),"",'DHS2025'!K14-'DHS2025'!K13) -> 2.6 | F17: =IF(OR('DHS2025'!J14="",'DHS2025'!J13=""),"",'DHS2025'!J14-'DHS2025'!J13) -> 0 | G17: 2.5 | H17: =IF('DHS2025'!L13="","",'DHS2025'!L13) -> 2.54916 | I17: =IF('DHS2025'!M13="","",'DHS2025'!M13) -> 71.52 | J17: =IF(OR(I17="",H17=""),"",(I17*0.99-1.9)*H17) -> 175.64936 | L17: ='Predikcia 15min.'!K14 -> 3 | M17: 2.5
... C2885: ='Predikcia 15min.'!A2882 -> 45991 | D2885: ='Predikcia 15min.'!B2882 -> 29.989583 | E2885: =IF(OR('DHS2025'!K2882="",'DHS2025'!K2881=""),"",'DHS2025'!K2882-'DHS2025'!K2881) -> 1.4 | F2885: =IF(OR('DHS2025'!J2882="",'DHS2025'!J2881=""),"",'DHS2025'!J2882-'DHS2025'!J2881) -> 4.3 | G2885: 8 | H2885: =IF('DHS2025'!L2881="","",'DHS2025'!L2881) -> 7.93029 | I2885: =IF('DHS2025'!M2881="","",'DHS2025'!M2881) -> 86.29 | J2885: =IF(OR(I2885="",H2885=""),"",(I2885*0.99-1.9)*H2885) -> 662.39413 | L2885: ='Predikcia 15min.'!K2882 -> 4 | M2885: 4.4

Sheet Predikcia 15min.
N1: Marič | O1: 2025 Skutočnosť
A2: $Date | B2: $Time | C2: 2021 | D2: 2022 | E2: 2023 | F2: 2024 | G2: Ø | H2: MW EE | I2: Marič | J2: ∑ | K2: PLÁN | L2: koef | M2: 2 | N2: 1 | O2: Sieť [kWh] | P2: Marič [kWh] | Q2: EE [kW] | R2: Cena SK (EUR/MWh) | S2: Tržby výroba EE
A3: 45962 | B3: 00:00:00 | C3: ='DHS2021'!J2 -> 7207 | D3: ='DHS2022'!J2 -> 1615 | E3: ='DHS2023'!J2 -> 1714 | F3: ='DHS2024'!J2 -> 2328 | G3: =AVERAGE(C3:F3) -> 3216 | H3: =G3/$M$2/1000 -> 1.608 | I3: =$N$2 -> 1 | J3: =H3+I3 -> 2.608 | K3: =MIN(MROUND(J3, 0.5), 8) -> 2.5 | O3: =('DHS2025'!K3-'DHS2025'!K2)*1000 -> 1100 | P3: =('DHS2025'!J3-'DHS2025'!J2)*1000 -> 4800 | Q3: ='DHS2025'!L2*1000 -> 8001.42 | R3: 99.26 | S3: =(R3*0.99-1.9)*(Q3/1000) -> 771.07604
A4: =$A$3+INT((ROW()-3)/96) -> 45962 | B4: =B3+TIME(0,15,0) -> 0.010416667 | C4: ='DHS2021'!J3 -> 7399 | D4: ='DHS2022'!J3 -> 1702 | E4: ='DHS2023'!J3 -> 1864 | F4: ='DHS2024'!J3 -> 2200 | G4: =AVERAGE(C4:F4) -> 3291.25 | H4: =G4/$M$2/1000 -> 1.645625 | I4: =$N$2 -> 1 | J4: =H4+I4 -> 2.645625 | K4: =MIN(MROUND(J4, 0.5), 8) -> 2.5 | O4: =('DHS2025'!K4-'DHS2025'!K3)*1000 -> 1400 | P4: =('DHS2025'!J4-'DHS2025'!J3)*1000 -> 4500 | Q4: ='DHS2025'!L3*1000 -> 8013.96 | R4: 89.7 | S4: =(R4*0.99-1.9)*(Q4/1000) -> 696.43717
A5: =$A$3+INT((ROW()-3)/96) -> 45962 | B5: =B4+TIME(0,15,0) -> 0.020833333 | C5: ='DHS2021'!J4 -> 6967 | D5: ='DHS2022'!J4 -> 1625 | E5: ='DHS2023'!J4 -> 2079 | F5: ='DHS2024'!J4 -> 2348 | G5: =AVERAGE(C5:F5) -> 3254.75 | H5: =G5/$M$2/1000 -> 1.627375 | I5: =$N$2 -> 1 | J5: =H5+I5 -> 2.627375 | K5: =MIN(MROUND(J5, 0.5), 8) -> 2.5 | O5: =('DHS2025'!K5-'DHS2025'!K4)*1000 -> 1500 | P5: =('DHS2025'!J5-'DHS2025'!J4)*1000 -> 4300 | Q5: ='DHS2025'!L4*1000 -> 8011.47 | R5: 84.43 | S5: =(R5*0.99-1.9)*(Q5/1000) -> 654.42253
A6: =$A$3+INT((ROW()-3)/96) -> 45962 | B6: =B5+TIME(0,15,0) -> 0.03125 | C6: ='DHS2021'!J5 -> 6930 | D6: ='DHS2022'!J5 -> 1523 | E6: ='DHS2023'!J5 -> 2281 | F6: ='DHS2024'!J5 -> 2238 | G6: =AVERAGE(C6:F6) -> 3243 | H6: =G6/$M$2/1000 -> 1.6215 | I6: =$N$2 -> 1 | J6: =H6+I6 -> 2.6215 | K6: =MIN(MROUND(J6, 0.5), 8) -> 2.5 | O6: =('DHS2025'!K6-'DHS2025'!K5)*1000 -> 1700 | P6: =('DHS2025'!J6-'DHS2025'!J5)*1000 -> 4100 | Q6: ='DHS2025'!L5*1000 -> 7876.29 | R6: 83.7 | S6: =(R6*0.99-1.9)*(Q6/1000) -> 637.68807
A7: =$A$3+INT((ROW()-3)/96) -> 45962 | B7: =B6+TIME(0,15,0) -> 0.041666667 | C7: ='DHS2021'!J6 -> 6757 | D7: ='DHS2022'!J6 -> 1545 | E7: ='DHS2023'!J6 -> 2244 | F7: ='DHS2024'!J6 -> 2234 | G7: =AVERAGE(C7:F7) -> 3195 | H7: =G7/$M$2/1000 -> 1.5975 | I7: =$N$2 -> 1 | J7: =H7+I7 -> 2.5975 | K7: =MIN(MROUND(J7, 0.5), 8) -> 2.5 | O7: =('DHS2025'!K7-'DHS2025'!K6)*1000 -> 2000 | P7: =('DHS2025'!J7-'DHS2025'!J6)*1000 -> 1900 | Q7: ='DHS2025'!L6*1000 -> 4721.64 | R7: 89.37 | S7: =(R7*0.99-1.9)*(Q7/1000) -> 408.78212
A8: =$A$3+INT((ROW()-3)/96) -> 45962 | B8: =B7+TIME(0,15,0) -> 0.052083333 | C8: ='DHS2021'!J7 -> 5327 | D8: ='DHS2022'!J7 -> 1699 | E8: ='DHS2023'!J7 -> 2097 | F8: ='DHS2024'!J7 -> 2151 | G8: =AVERAGE(C8:F8) -> 2818.5 | H8: =G8/$M$2/1000 -> 1.40925 | I8: =$N$2 -> 1 | J8: =H8+I8 -> 2.40925 | K8: =MIN(MROUND(J8, 0.5), 8) -> 2.5 | O8: =('DHS2025'!K8-'DHS2025'!K7)*1000 -> 1700 | P8: =('DHS2025'!J8-'DHS2025'!J7)*1000 -> 2000 | Q8: ='DHS2025'!L7*1000 -> 4536.3 | R8: 84.51 | S8: =(R8*0.99-1.9)*(Q8/1000) -> 370.91012
A9: =$A$3+INT((ROW()-3)/96) -> 45962 | B9: =B8+TIME(0,15,0) -> 0.0625 | C9: ='DHS2021'!J8 -> 7229 | D9: ='DHS2022'!J8 -> 2010 | E9: ='DHS2023'!J8 -> 2104 | F9: ='DHS2024'!J8 -> 3334 | G9: =AVERAGE(C9:F9) -> 3669.25 | H9: =G9/$M$2/1000 -> 1.834625 | I9: =$N$2 -> 1 | J9: =H9+I9 -> 2.834625 | K9: =MIN(MROUND(J9, 0.5), 8) -> 3 | O9: =('DHS2025'!K9-'DHS2025'!K8)*1000 -> 1500 | P9: =('DHS2025'!J9-'DHS2025'!J8)*1000 -> 2100 | Q9: ='DHS2025'!L8*1000 -> 4542.9 | R9: 83.78 | S9: =(R9*0.99-1.9)*(Q9/1000) -> 368.16661
A10: =$A$3+INT((ROW()-3)/96) -> 45962 | B10: =B9+TIME(0,15,0) -> 0.072916667 | C10: ='DHS2021'!J9 -> 6347 | D10: ='DHS2022'!J9 -> 1808 | E10: ='DHS2023'!J9 -> 2053 | F10: ='DHS2024'!J9 -> 3031 | G10: =AVERAGE(C10:F10) -> 3309.75 | H10: =G10/$M$2/1000 -> 1.654875 | I10: =$N$2 -> 1 | J10: =H10+I10 -> 2.654875 | K10: =MIN(MROUND(J10, 0.5), 8) -> 2.5 | O10: =('DHS2025'!K10-'DHS2025'!K9)*1000 -> 1500 | P10: =('DHS2025'!J10-'DHS2025'!J9)*1000 -> 2100 | Q10: ='DHS2025'!L9*1000 -> 4482.45 | R10: 83.3 | S10: =(R10*0.99-1.9)*(Q10/1000) -> 361.13755
A11: =$A$3+INT((ROW()-3)/96) -> 45962 | B11: =B10+TIME(0,15,0) -> 0.083333333 | C11: ='DHS2021'!J10 -> 7102 | D11: ='DHS2022'!J10 -> 1597 | E11: ='DHS2023'!J10 -> 1949 | F11: ='DHS2024'!J10 -> 2656 | G11: =AVERAGE(C11:F11) -> 3326 | H11: =G11/$M$2/1000 -> 1.663 | I11: =$N$2 -> 1 | J11: =H11+I11 -> 2.663 | K11: =MIN(MROUND(J11, 0.5), 8) -> 2.5 | O11: =('DHS2025'!K11-'DHS2025'!K10)*1000 -> 1700 | P11: =('DHS2025'!J11-'DHS2025'!J10)*1000 -> 800 | Q11: ='DHS2025'!L10*1000 -> 2580.6 | R11: 83.72 | S11: =(R11*0.99-1.9)*(Q11/1000) -> 208.98421
A12: =$A$3+INT((ROW()-3)/96) -> 45962 | B12: =B11+TIME(0,15,0) -> 0.09375 | C12: ='DHS2021'!J11 -> 5896 | D12: ='DHS2022'!J11 -> 1835 | E12: ='DHS2023'!J11 -> 2239 | F12: ='DHS2024'!J11 -> 2515 | G12: =AVERAGE(C12:F12) -> 3121.25 | H12: =G12/$M$2/1000 -> 1.560625 | I12: =$N$2 -> 1 | J12: =H12+I12 -> 2.560625 | K12: =MIN(MROUND(J12, 0.5), 8) -> 2.5 | O12: =('DHS2025'!K12-'DHS2025'!K11)*1000 -> 2200 | P12: =('DHS2025'!J12-'DHS2025'!J11)*1000 -> 400 | Q12: ='DHS2025'!L11*1000 -> 2550.75 | R12: 83.15 | S12: =(R12*0.99-1.9)*(Q12/1000) -> 205.12749
A13: =$A$3+INT((ROW()-3)/96) -> 45962 | B13: =B12+TIME(0,15,0) -> 0.10416667 | C13: ='DHS2021'!J12 -> 6822 | D13: ='DHS2022'!J12 -> 1971 | E13: ='DHS2023'!J12 -> 2166 | F13: ='DHS2024'!J12 -> 2532 | G13: =AVERAGE(C13:F13) -> 3372.75 | H13: =G13/$M$2/1000 -> 1.686375 | I13: =$N$2 -> 1 | J13: =H13+I13 -> 2.686375 | K13: =MIN(MROUND(J13, 0.5), 8) -> 2.5 | O13: =('DHS2025'!K13-'DHS2025'!K12)*1000 -> 2400 | P13: =('DHS2025'!J13-'DHS2025'!J12)*1000 -> 0 | Q13: ='DHS2025'!L12*1000 -> 2547.72 | R13: 84.54 | S13: =(R13*0.99-1.9)*(Q13/1000) -> 208.38974
A14: =$A$3+INT((ROW()-3)/96) -> 45962 | B14: =B13+TIME(0,15,0) -> 0.11458333 | C14: ='DHS2021'!J13 -> 8558 | D14: ='DHS2022'!J13 -> 1843 | E14: ='DHS2023'!J13 -> 2209 | F14: ='DHS2024'!J13 -> 3423 | G14: =AVERAGE(C14:F14) -> 4008.25 | H14: =G14/$M$2/1000 -> 2.004125 | I14: =$N$2 -> 1 | J14: =H14+I14 -> 3.004125 | K14: =MIN(MROUND(J14, 0.5), 8) -> 3 | O14: =('DHS2025'!K14-'DHS2025'!K13)*1000 -> 2600 | P14: =('DHS2025'!J14-'DHS2025'!J13)*1000 -> 0 | Q14: ='DHS2025'!L13*1000 -> 2549.16 | R14: 85.08 | S14: =(R14*0.99-1.9)*(Q14/1000) -> 209.8703
A15: =$A$3+INT((ROW()-3)/96) -> 45962 | B15: =B14+TIME(0,15,0) -> 0.125 | C15: ='DHS2021'!J14 -> 8465 | D15: ='DHS2022'!J14 -> 1840 | E15: ='DHS2023'!J14 -> 2360 | F15: ='DHS2024'!J14 -> 4332 | G15: =AVERAGE(C15:F15) -> 4249.25 | H15: =G15/$M$2/1000 -> 2.124625 | I15: =$N$2 -> 1 | J15: =H15+I15 -> 3.124625 | K15: =MIN(MROUND(J15, 0.5), 8) -> 3 | O15: =('DHS2025'!K15-'DHS2025'!K14)*1000 -> 2500 | P15: =('DHS2025'!J15-'DHS2025'!J14)*1000 -> 0 | Q15: ='DHS2025'!L14*1000 -> 2547.99 | R15: 90.22 | S15: =(R15*0.99-1.9)*(Q15/1000) -> 222.73968
... A674: =$A$3+INT((ROW()-3)/96) -> 45968 | B674: =B673+TIME(0,15,0) -> 6.9895833 | C674: ='DHS2021'!J673 -> 3302 | D674: ='DHS2022'!J673 -> 1853 | E674: ='DHS2023'!J673 -> 1880 | F674: ='DHS2024'!J673 -> 6967 | G674: =AVERAGE(C674:F674) -> 3500.5 | H674: =G674/$M$2/1000 -> 1.75025 | I674: =$N$2 -> 1 | J674: =H674+I674 -> 2.75025 | K674: =MIN(MROUND(J674, 0.5), 8) -> 3 | O674: =('DHS2025'!K674-'DHS2025'!K673)*1000 -> 1400 | P674: =('DHS2025'!J674-'DHS2025'!J673)*1000 -> 4500 | Q674: ='DHS2025'!L673*1000 -> 8011.32 | R674: 90.11 | S674: =(R674*0.99-1.9)*(Q674/1000) -> 699.45954
A675: =$A$3+INT((ROW()-3)/96) -> 45969 | B675: =B674+TIME(0,15,0) -> 7 | C675: ='DHS2021'!J674 -> 2999 | D675: ='DHS2022'!J674 -> 1775 | E675: ='DHS2023'!J674 -> 2081 | F675: ='DHS2024'!J674 -> 7950 | G675: =AVERAGE(C675:F675) -> 3701.25 | H675: =G675/$M$2/1000 -> 1.850625 | I675: =$N$2 -> 1 | J675: =H675+I675 -> 2.850625 | K675: =MIN(MROUND(J675, 0.5), 8) -> 3 | O675: =('DHS2025'!K675-'DHS2025'!K674)*1000 -> 1400 | P675: =('DHS2025'!J675-'DHS2025'!J674)*1000 -> 4400 | Q675: ='DHS2025'!L674*1000 -> 8010.27 | S675: =(R675*0.99-1.9)*(Q675/1000) -> -15.219513
A676: =$A$3+INT((ROW()-3)/96) -> 45969 | B676: =B675+TIME(0,15,0) -> 7.0104167 | C676: ='DHS2021'!J675 -> 4085 | D676: ='DHS2022'!J675 -> 1617 | E676: ='DHS2023'!J675 -> 2074 | F676: ='DHS2024'!J675 -> 7499 | G676: =AVERAGE(C676:F676) -> 3818.75 | H676: =G676/$M$2/1000 -> 1.909375 | I676: =$N$2 -> 1 | J676: =H676+I676 -> 2.909375 | K676: =MIN(MROUND(J676, 0.5), 8) -> 3 | O676: =('DHS2025'!K676-'DHS2025'!K675)*1000 -> 1600 | P676: =('DHS2025'!J676-'DHS2025'!J675)*1000 -> 4200 | Q676: ='DHS2025'!L675*1000 -> 8009.34 | S676: =(R676*0.99-1.9)*(Q676/1000) -> -15.217746
A677: =$A$3+INT((ROW()-3)/96) -> 45969 | B677: =B676+TIME(0,15,0) -> 7.0208333 | C677: ='DHS2021'!J676 -> 3673 | D677: ='DHS2022'!J676 -> 1552 | E677: ='DHS2023'!J676 -> 2579 | F677: ='DHS2024'!J676 -> 8111 | G677: =AVERAGE(C677:F677) -> 3978.75 | H677: =G677/$M$2/1000 -> 1.989375 | I677: =$N$2 -> 1 | J677: =H677+I677 -> 2.989375 | K677: =MIN(MROUND(J677, 0.5), 8) -> 3 | O677: =('DHS2025'!K677-'DHS2025'!K676)*1000 -> 1500 | P677: =('DHS2025'!J677-'DHS2025'!J676)*1000 -> 4300 | Q677: ='DHS2025'!L676*1000 -> 8005.26 | S677: =(R677*0.99-1.9)*(Q677/1000) -> -15.209994
A678: =$A$3+INT((ROW()-3)/96) -> 45969 | B678: =B677+TIME(0,15,0) -> 7.03125 | C678: ='DHS2021'!J677 -> 4186 | D678: ='DHS2022'!J677 -> 1653 | E678: ='DHS2023'!J677 -> 3246 | F678: ='DHS2024'!J677 -> 7980 | G678: =AVERAGE(C678:F678) -> 4266.25 | H678: =G678/$M$2/1000 -> 2.133125 | I678: =$N$2 -> 1 | J678: =H678+I678 -> 3.133125 | K678: =MIN(MROUND(J678, 0.5), 8) -> 3 | O678: =('DHS2025'!K678-'DHS2025'!K677)*1000 -> 1700 | P678: =('DHS2025'!J678-'DHS2025'!J677)*1000 -> 4200 | Q678: ='DHS2025'!L677*1000 -> 8009.76 | S678: =(R678*0.99-1.9)*(Q678/1000) -> -15.218544
A679: =$A$3+INT((ROW()-3)/96) -> 45969 | B679: =B678+TIME(0,15,0) -> 7.0416667 | C679: ='DHS2021'!J678 -> 3193 | D679: ='DHS2022'!J678 -> 1684 | E679: ='DHS2023'!J678 -> 3245 | F679: ='DHS2024'!J678 -> 7656 | G679: =AVERAGE(C679:F679) -> 3944.5 | H679: =G679/$M$2/1000 -> 1.97225 | I679: =$N$2 -> 1 | J679: =H679+I679 -> 2.97225 | K679: =MIN(MROUND(J679, 0.5), 8) -> 3 | O679: =('DHS2025'!K679-'DHS2025'!K678)*1000 -> 1700 | P679: =('DHS2025'!J679-'DHS2025'!J678)*1000 -> 4100 | Q679: ='DHS2025'!L678*1000 -> 8012.79 | S679: =(R679*0.99-1.9)*(Q679/1000) -> -15.224301
A680: =$A$3+INT((ROW()-3)/96) -> 45969 | B680: =B679+TIME(0,15,0) -> 7.0520833 | C680: ='DHS2021'!J679 -> 3422 | D680: ='DHS2022'!J679 -> 1807 | E680: ='DHS2023'!J679 -> 3505 | F680: ='DHS2024'!J679 -> 8706 | G680: =AVERAGE(C680:F680) -> 4360 | H680: =G680/$M$2/1000 -> 2.18 | I680: =$N$2 -> 1 | J680: =H680+I680 -> 3.18 | K680: =MIN(MROUND(J680, 0.5), 8) -> 3 | O680: =('DHS2025'!K680-'DHS2025'!K679)*1000 -> 1700 | P680: =('DHS2025'!J680-'DHS2025'!J679)*1000 -> 4200 | Q680: ='DHS2025'!L679*1000 -> 7998.12 | S680: =(R680*0.99-1.9)*(Q680/1000) -> -15.196428
A681: =$A$3+INT((ROW()-3)/96) -> 45969 | B681: =B680+TIME(0,15,0) -> 7.0625 | C681: ='DHS2021'!J680 -> 3697 | D681: ='DHS2022'!J680 -> 1695 | E681: ='DHS2023'!J680 -> 3188 | F681: ='DHS2024'!J680 -> 9258 | G681: =AVERAGE(C681:F681) -> 4459.5 | H681: =G681/$M$2/1000 -> 2.22975 | I681: =$N$2 -> 1 | J681: =H681+I681 -> 3.22975 | K681: =MIN(MROUND(J681, 0.5), 8) -> 3 | O681: =('DHS2025'!K681-'DHS2025'!K680)*1000 -> 1600 | P681: =('DHS2025'!J681-'DHS2025'!J680)*1000 -> 4200 | Q681: ='DHS2025'!L680*1000 -> 7985.07 | S681: =(R681*0.99-1.9)*(Q681/1000) -> -15.171633
A682: =$A$3+INT((ROW()-3)/96) -> 45969 | B682: =B681+TIME(0,15,0) -> 7.0729167 | C682: ='DHS2021'!J681 -> 4451 | D682: ='DHS2022'!J681 -> 1638 | E682: ='DHS2023'!J681 -> 2997 | F682: ='DHS2024'!J681 -> 9460 | G682: =AVERAGE(C682:F682) -> 4636.5 | H682: =G682/$M$2/1000 -> 2.31825 | I682: =$N$2 -> 1 | J682: =H682+I682 -> 3.31825 | K682: =MIN(MROUND(J682, 0.5), 8) -> 3.5 | O682: =('DHS2025'!K682-'DHS2025'!K681)*1000 -> 1600 | P682: =('DHS2025'!J682-'DHS2025'!J681)*1000 -> 4100 | Q682: ='DHS2025'!L681*1000 -> 7788 | S682: =(R682*0.99-1.9)*(Q682/1000) -> -14.7972
A683: =$A$3+INT((ROW()-3)/96) -> 45969 | B683: =B682+TIME(0,15,0) -> 7.0833333 | C683: ='DHS2021'!J682 -> 3337 | D683: ='DHS2022'!J682 -> 1679 | E683: ='DHS2023'!J682 -> 3085 | F683: ='DHS2024'!J682 -> 9390 | G683: =AVERAGE(C683:F683) -> 4372.75 | H683: =G683/$M$2/1000 -> 2.186375 | I683: =$N$2 -> 1 | J683: =H683+I683 -> 3.186375 | K683: =MIN(MROUND(J683, 0.5), 8) -> 3 | O683: =('DHS2025'!K683-'DHS2025'!K682)*1000 -> 1800 | P683: =('DHS2025'!J683-'DHS2025'!J682)*1000 -> 1900 | Q683: ='DHS2025'!L682*1000 -> 4657.86 | S683: =(R683*0.99-1.9)*(Q683/1000) -> -8.849934
A684: =$A$3+INT((ROW()-3)/96) -> 45969 | B684: =B683+TIME(0,15,0) -> 7.09375 | C684: ='DHS2021'!J683 -> 2983 | D684: ='DHS2022'!J683 -> 1684 | E684: ='DHS2023'!J683 -> 3222 | F684: ='DHS2024'!J683 -> 9574 | G684: =AVERAGE(C684:F684) -> 4365.75 | H684: =G684/$M$2/1000 -> 2.182875 | I684: =$N$2 -> 1 | J684: =H684+I684 -> 3.182875 | K684: =MIN(MROUND(J684, 0.5), 8) -> 3 | O684: =('DHS2025'!K684-'DHS2025'!K683)*1000 -> 1800 | P684: =('DHS2025'!J684-'DHS2025'!J683)*1000 -> 1900 | Q684: ='DHS2025'!L683*1000 -> 4526.01 | S684: =(R684*0.99-1.9)*(Q684/1000) -> -8.599419
A685: =$A$3+INT((ROW()-3)/96) -> 45969 | B685: =B684+TIME(0,15,0) -> 7.1041667 | C685: ='DHS2021'!J684 -> 2908 | D685: ='DHS2022'!J684 -> 2021 | E685: ='DHS2023'!J684 -> 3476 | F685: ='DHS2024'!J684 -> 9245 | G685: =AVERAGE(C685:F685) -> 4412.5 | H685: =G685/$M$2/1000 -> 2.20625 | I685: =$N$2 -> 1 | J685: =H685+I685 -> 3.20625 | K685: =MIN(MROUND(J685, 0.5), 8) -> 3 | O685: =('DHS2025'!K685-'DHS2025'!K684)*1000 -> 1900 | P685: =('DHS2025'!J685-'DHS2025'!J684)*1000 -> 1700 | Q685: ='DHS2025'!L684*1000 -> 4532.46 | S685: =(R685*0.99-1.9)*(Q685/1000) -> -8.611674
A686: =$A$3+INT((ROW()-3)/96) -> 45969 | B686: =B685+TIME(0,15,0) -> 7.1145833 | C686: ='DHS2021'!J685 -> 3794 | D686: ='DHS2022'!J685 -> 1622 | E686: ='DHS2023'!J685 -> 3784 | F686: ='DHS2024'!J685 -> 10238 | G686: =AVERAGE(C686:F686) -> 4859.5 | H686: =G686/$M$2/1000 -> 2.42975 | I686: =$N$2 -> 1 | J686: =H686+I686 -> 3.42975 | K686: =MIN(MROUND(J686, 0.5), 8) -> 3.5 | O686: =('DHS2025'!K686-'DHS2025'!K685)*1000 -> 2000 | P686: =('DHS2025'!J686-'DHS2025'!J685)*1000 -> 1700 | Q686: ='DHS2025'!L685*1000 -> 4524.03 | S686: =(R686*0.99-1.9)*(Q686/1000) -> -8.595657
... A1934: =$A$3+INT((ROW()-3)/96) -> 45982 | B1934: =B1933+TIME(0,15,0) -> 20.114583 | C1934: ='DHS2021'!J1933 -> 6219 | D1934: ='DHS2022'!J1933 -> 11206 | E1934: ='DHS2023'!J1933 -> 7925 | F1934: ='DHS2024'!J1933 -> 11435 | G1934: =AVERAGE(C1934:F1934) -> 9196.25 | H1934: =G1934/$M$2/1000 -> 4.598125 | I1934: =$N$2 -> 1 | J1934: =H1934+I1934 -> 5.598125 | K1934: =MIN(MROUND(J1934, 0.5), 8) -> 5.5 | O1934: =('DHS2025'!K1934-'DHS2025'!K1933)*1000 -> 1700 | P1934: =('DHS2025'!J1934-'DHS2025'!J1933)*1000 -> 2000 | Q1934: ='DHS2025'!L1933*1000 -> 4514.52 | S1934: =(R1934*0.99-1.9)*(Q1934/1000) -> -8.577588
A1935: =$A$3+INT((ROW()-3)/96) -> 45982 | B1935: =B1934+TIME(0,15,0) -> 20.125 | C1935: ='DHS2021'!J1934 -> 5731 | D1935: ='DHS2022'!J1934 -> 11641 | E1935: ='DHS2023'!J1934 -> 8106 | F1935: ='DHS2024'!J1934 -> 12670 | G1935: =AVERAGE(C1935:F1935) -> 9537 | H1935: =G1935/$M$2/1000 -> 4.7685 | I1935: =$N$2 -> 1 | J1935: =H1935+I1935 -> 5.7685 | K1935: =MIN(MROUND(J1935, 0.5), 8) -> 6 | O1935: =('DHS2025'!K1935-'DHS2025'!K1934)*1000 -> 1700 | P1935: =('DHS2025'!J1935-'DHS2025'!J1934)*1000 -> 1500 | Q1935: ='DHS2025'!L1934*1000 -> 4040.37 | R1935: =INDEX(U$3:U$1048576,INT((ROW()-3)/4)+1) -> 0 | S1935: =(R1935*0.99-1.9)*(Q1935/1000) -> -7.676703
A1936: =$A$3+INT((ROW()-3)/96) -> 45982 | B1936: =B1935+TIME(0,15,0) -> 20.135417 | C1936: ='DHS2021'!J1935 -> 7659 | D1936: ='DHS2022'!J1935 -> 14632 | E1936: ='DHS2023'!J1935 -> 8674 | F1936: ='DHS2024'!J1935 -> 13304 | G1936: =AVERAGE(C1936:F1936) -> 11067.25 | H1936: =G1936/$M$2/1000 -> 5.533625 | I1936: =$N$2 -> 1 | J1936: =H1936+I1936 -> 6.533625 | K1936: =MIN(MROUND(J1936, 0.5), 8) -> 6.5 | O1936: =('DHS2025'!K1936-'DHS2025'!K1935)*1000 -> 2100 | P1936: =('DHS2025'!J1936-'DHS2025'!J1935)*1000 -> 1200 | Q1936: ='DHS2025'!L1935*1000 -> 4037.34 | R1936: =INDEX(U$3:U$1048576,INT((ROW()-3)/4)+1) -> 0 | S1936: =(R1936*0.99-1.9)*(Q1936/1000) -> -7.670946
A1937: =$A$3+INT((ROW()-3)/96) -> 45982 | B1937: =B1936+TIME(0,15,0) -> 20.145833 | C1937: ='DHS2021'!J1936 -> 7054 | D1937: ='DHS2022'!J1936 -> 15952 | E1937: ='DHS2023'!J1936 -> 10800 | F1937: ='DHS2024'!J1936 -> 14536 | G1937: =AVERAGE(C1937:F1937) -> 12085.5 | H1937: =G1937/$M$2/1000 -> 6.04275 | I1937: =$N$2 -> 1 | J1937: =H1937+I1937 -> 7.04275 | K1937: =MIN(MROUND(J1937, 0.5), 8) -> 7 | O1937: =('DHS2025'!K1937-'DHS2025'!K1936)*1000 -> 2800 | P1937: =('DHS2025'!J1937-'DHS2025'!J1936)*1000 -> 500 | Q1937: ='DHS2025'!L1936*1000 -> 4038.93 | R1937: =INDEX(U$3:U$1048576,INT((ROW()-3)/4)+1) -> 0 | S1937: =(R1937*0.99-1.9)*(Q1937/1000) -> -7.673967
A1938: =$A$3+INT((ROW()-3)/96) -> 45982 | B1938: =B1937+TIME(0,15,0) -> 20.15625 | C1938: ='DHS2021'!J1937 -> 4740 | D1938: ='DHS2022'!J1937 -> 17938 | E1938: ='DHS2023'!J1937 -> 12005 | F1938: ='DHS2024'!J1937 -> 16502 | G1938: =AVERAGE(C1938:F1938) -> 12796.25 | H1938: =G1938/$M$2/1000 -> 6.398125 | I1938: =$N$2 -> 1 | J1938: =H1938+I1938 -> 7.398125 | K1938: =MIN(MROUND(J1938, 0.5), 8) -> 7.5 | O1938: =('DHS2025'!K1938-'DHS2025'!K1937)*1000 -> 3400 | P1938: =('DHS2025'!J1938-'DHS2025'!J1937)*1000 -> 0 | Q1938: ='DHS2025'!L1937*1000 -> 4050.54 | R1938: =INDEX(U$3:U$1048576,INT((ROW()-3)/4)+1) -> 0 | S1938: =(R1938*0.99-1.9)*(Q1938/1000) -> -7.696026
A1939: =$A$3+INT((ROW()-3)/96) -> 45982 | B1939: =B1938+TIME(0,15,0) -> 20.166667 | C1939: ='DHS2021'!J1938 -> 6461 | D1939: ='DHS2022'!J1938 -> 17807 | E1939: ='DHS2023'!J1938 -> 13359 | F1939: ='DHS2024'!J1938 -> 18112 | G1939: =AVERAGE(C1939:F1939) -> 13934.75 | H1939: =G1939/$M$2/1000 -> 6.967375 | I1939: =$N$2 -> 1 | J1939: =H1939+I1939 -> 7.967375 | K1939: =MIN(MROUND(J1939, 0.5), 8) -> 8 | O1939: =('DHS2025'!K1939-'DHS2025'!K1938)*1000 -> 3300 | P1939: =('DHS2025'!J1939-'DHS2025'!J1938)*1000 -> 0 | Q1939: ='DHS2025'!L1938*1000 -> 4041.84 | R1939: =INDEX(U$3:U$1048576,INT((ROW()-3)/4)+1) -> 0 | S1939: =(R1939*0.99-1.9)*(Q1939/1000) -> -7.679496
A1940: =$A$3+INT((ROW()-3)/96) -> 45982 | B1940: =B1939+TIME(0,15,0) -> 20.177083 | C1940: ='DHS2021'!J1939 -> 6886 | D1940: ='DHS2022'!J1939 -> 17598 | E1940: ='DHS2023'!J1939 -> 14986 | F1940: ='DHS2024'!J1939 -> 18549 | G1940: =AVERAGE(C1940:F1940) -> 14504.75 | H1940: =G1940/$M$2/1000 -> 7.252375 | I1940: =$N$2 -> 1 | J1940: =H1940+I1940 -> 8.252375 | K1940: =MIN(MROUND(J1940, 0.5), 8) -> 8 | O1940: =('DHS2025'!K1940-'DHS2025'!K1939)*1000 -> 3200 | P1940: =('DHS2025'!J1940-'DHS2025'!J1939)*1000 -> 0 | Q1940: ='DHS2025'!L1939*1000 -> 4041.57 | R1940: =INDEX(U$3:U$1048576,INT((ROW()-3)/4)+1) -> 0 | S1940: =(R1940*0.99-1.9)*(Q1940/1000) -> -7.678983
A1941: =$A$3+INT((ROW()-3)/96) -> 45982 | B1941: =B1940+TIME(0,15,0) -> 20.1875 | C1941: ='DHS2021'!J1940 -> 8968 | D1941: ='DHS2022'!J1940 -> 17526 | E1941: ='DHS2023'!J1940 -> 15179 | F1941: ='DHS2024'!J1940 -> 18265 | G1941: =AVERAGE(C1941:F1941) -> 14984.5 | H1941: =G1941/$M$2/1000 -> 7.49225 | I1941: =$N$2 -> 1 | J1941: =H1941+I1941 -> 8.49225 | K1941: =MIN(MROUND(J1941, 0.5), 8) -> 8 | O1941: =('DHS2025'!K1941-'DHS2025'!K1940)*1000 -> 3300 | P1941: =('DHS2025'!J1941-'DHS2025'!J1940)*1000 -> 0 | Q1941: ='DHS2025'!L1940*1000 -> 4042.62 | R1941: =INDEX(U$3:U$1048576,INT((ROW()-3)/4)+1) -> 0 | S1941: =(R1941*0.99-1.9)*(Q1941/1000) -> -7.680978
A1942: =$A$3+INT((ROW()-3)/96) -> 45982 | B1942: =B1941+TIME(0,15,0) -> 20.197917 | C1942: ='DHS2021'!J1941 -> 11113 | D1942: ='DHS2022'!J1941 -> 17380 | E1942: ='DHS2023'!J1941 -> 13586 | F1942: ='DHS2024'!J1941 -> 19358 | G1942: =AVERAGE(C1942:F1942) -> 15359.25 | H1942: =G1942/$M$2/1000 -> 7.679625 | I1942: =$N$2 -> 1 | J1942: =H1942+I1942 -> 8.679625 | K1942: =MIN(MROUND(J1942, 0.5), 8) -> 8 | O1942: =('DHS2025'!K1942-'DHS2025'!K1941)*1000 -> 3600 | P1942: =('DHS2025'!J1942-'DHS2025'!J1941)*1000 -> 100 | Q1942: ='DHS2025'!L1941*1000 -> 4601.1 | R1942: =INDEX(U$3:U$1048576,INT((ROW()-3)/4)+1) -> 0 | S1942: =(R1942*0.99-1.9)*(Q1942/1000) -> -8.74209
A1943: =$A$3+INT((ROW()-3)/96) -> 45982 | B1943: =B1942+TIME(0,15,0) -> 20.208333 | C1943: ='DHS2021'!J1942 -> 12440 | D1943: ='DHS2022'!J1942 -> 16938 | E1943: ='DHS2023'!J1942 -> 14918 | F1943: ='DHS2024'!J1942 -> 17604 | G1943: =AVERAGE(C1943:F1943) -> 15475 | H1943: =G1943/$M$2/1000 -> 7.7375 | I1943: =$N$2 -> 1 | J1943: =H1943+I1943 -> 8.7375 | K1943: =MIN(MROUND(J1943, 0.5), 8) -> 8 | O1943: =('DHS2025'!K1943-'DHS2025'!K1942)*1000 -> 4400 | P1943: =('DHS2025'!J1943-'DHS2025'!J1942)*1000 -> 1500 | Q1943: ='DHS2025'!L1942*1000 -> 8011.47 | R1943: =INDEX(U$3:U$1048576,INT((ROW()-3)/4)+1) -> 0 | S1943: =(R1943*0.99-1.9)*(Q1943/1000) -> -15.221793
A1944: =$A$3+INT((ROW()-3)/96) -> 45982 | B1944: =B1943+TIME(0,15,0) -> 20.21875 | C1944: ='DHS2021'!J1943 -> 13808 | D1944: ='DHS2022'!J1943 -> 17455 | E1944: ='DHS2023'!J1943 -> 16067 | F1944: ='DHS2024'!J1943 -> 18445 | G1944: =AVERAGE(C1944:F1944) -> 16443.75 | H1944: =G1944/$M$2/1000 -> 8.221875 | I1944: =$N$2 -> 1 | J1944: =H1944+I1944 -> 9.221875 | K1944: =MIN(MROUND(J1944, 0.5), 8) -> 8 | O1944: =('DHS2025'!K1944-'DHS2025'!K1943)*1000 -> 3900 | P1944: =('DHS2025'!J1944-'DHS2025'!J1943)*1000 -> 1800 | Q1944: ='DHS2025'!L1943*1000 -> 8010.15 | R1944: =INDEX(U$3:U$1048576,INT((ROW()-3)/4)+1) -> 0 | S1944: =(R1944*0.99-1.9)*(Q1944/1000) -> -15.219285
A1945: =$A$3+INT((ROW()-3)/96) -> 45982 | B1945: =B1944+TIME(0,15,0) -> 20.229167 | C1945: ='DHS2021'!J1944 -> 14095 | D1945: ='DHS2022'!J1944 -> 17517 | E1945: ='DHS2023'!J1944 -> 16924 | F1945: ='DHS2024'!J1944 -> 18805 | G1945: =AVERAGE(C1945:F1945) -> 16835.25 | H1945: =G1945/$M$2/1000 -> 8.417625 | I1945: =$N$2 -> 1 | J1945: =H1945+I1945 -> 9.417625 | K1945: =MIN(MROUND(J1945, 0.5), 8) -> 8 | O1945: =('DHS2025'!K1945-'DHS2025'!K1944)*1000 -> 4500 | P1945: =('DHS2025'!J1945-'DHS2025'!J1944)*1000 -> 1300 | Q1945: ='DHS2025'!L1944*1000 -> 8010.15 | R1945: =INDEX(U$3:U$1048576,INT((ROW()-3)/4)+1) -> 0 | S1945: =(R1945*0.99-1.9)*(Q1945/1000) -> -15.219285
...

Sheet DHS2021
A1: $Date | B1: $Time | C1: IIN_LEISTUNG-NETZ | D1: IIN_LEISTUNG-REGELKUEHLKREIS | E1: IIAN_DTU_GEN_WIRKLEISTUNG | G1: 15min. | H1: $Date | I1: $Time | J1: IIN_LEISTUNG-NETZ | K1: IIN_LEISTUNG-REGELKUEHLKREIS | L1: IIAN_DTU_GEN_WIRKLEISTUNG
A2: 01//21 | B2: 00:00:00 | H2: 11/01/21 | I2: 00:00:00 | J2: 7207 | K2: 23 | L2: 0
A3: 01//21 | B3: 01:00:00 | H3: 11/01/21 | I3: 00:15:00 | J3: 7399 | K3: 171 | L3: 0
A4: 01//21 | B4: 02:00:00 | H4: 11/01/21 | I4: 00:30:00 | J4: 6967 | K4: 39 | L4: 0
A5: 01//21 | B5: 03:00:00 | H5: 11/01/21 | I5: 00:45:00 | J5: 6930 | K5: 71 | L5: 0
A6: 01//21 | B6: 04:00:00 | H6: 11/01/21 | I6: 01:00:00 | J6: 6757 | K6: 86 | L6: 0
A7: 01//21 | B7: 05:00:00 | H7: 11/01/21 | I7: 01:15:00 | J7: 5327 | K7: 51 | L7: 0
A8: 01//21 | B8: 06:00:00 | H8: 11/01/21 | I8: 01:30:00 | J8: 7229 | K8: 82 | L8: 0
A9: 01//21 | B9: 07:00:00 | H9: 11/01/21 | I9: 01:45:00 | J9: 6347 | K9: 55 | L9: 0
A10: 01//21 | B10: 08:00:00 | H10: 11/01/21 | I10: 02:00:00 | J10: 7102 | K10: 88 | L10: 0
A11: 01//21 | B11: 09:00:00 | H11: 11/01/21 | I11: 02:15:00 | J11: 5896 | K11: 26 | L11: 0
A12: 01//21 | B12: 10:00:00 | H12: 11/01/21 | I12: 02:30:00 | J12: 6822 | K12: 56 | L12: 0
A13: 01//21 | B13: 11:00:00 | H13: 11/01/21 | I13: 02:45:00 | J13: 8558 | K13: 69 | L13: 0
... A745: 31//21 | B745: 23:00:00 | H745: 11/08/21 | I745: 17:45:00 | J745: 13035 | K745: 68 | L745: 0
H746: 11/08/21 | I746: 18:00:00 | J746: 13441 | K746: 75 | L746: 0
H747: 11/08/21 | I747: 18:15:00 | J747: 13691 | K747: 107 | L747: 0
H748: 11/08/21 | I748: 18:30:00 | J748: 12721 | K748: 24 | L748: 0
H749: 11/08/21 | I749: 18:45:00 | J749: 12573 | K749: 89 | L749: 0
H750: 11/08/21 | I750: 19:00:00 | J750: 11922 | K750: 27 | L750: 0
H751: 11/08/21 | I751: 19:15:00 | J751: 12609 | K751: 121 | L751: 0
H752: 11/08/21 | I752: 19:30:00 | J752: 12329 | K752: 42 | L752: 0
H753: 11/08/21 | I753: 19:45:00 | J753: 12874 | K753: 182 | L753: 0
H754: 11/08/21 | I754: 20:00:00 | J754: 11883 | K754: 188 | L754: 0
H755: 11/08/21 | I755: 20:15:00 | J755: 12364 | K755: 27 | L755: 0
H756: 11/08/21 | I756: 20:30:00 | J756: 11506 | K756: 25 | L756: 0
H757: 11/08/21 | I757: 20:45:00 | J757: 11399 | K757: 25 | L757: 0
... H2764: 11/29/21 | I2764: 18:30:00 | J2764: 15974 | K2764: 450 | L2764: 4003
H2765: 11/29/21 | I2765: 18:45:00
H2766: 11/29/21 | I2766: 19:00:00 | J2766: 16079 | K2766: 280 | L2766: 3984
H2767: 11/29/21 | I2767: 19:15:00 | J2767: 16350 | K2767: 274 | L2767: 4020
H2768: 11/29/21 | I2768: 19:30:00 | J2768: 15991 | K2768: 449 | L2768: 3991
H2769: 11/29/21 | I2769: 19:45:00 | J2769: 16138 | K2769: 227 | L2769: 4003
H2770: 11/29/21 | I2770: 20:00:00 | J2770: 15946 | K2770: 279 | L2770: 4009
H2771: 11/29/21 | I2771: 20:15:00 | J2771: 15531 | K2771: 365 | L2771: 3992
H2772: 11/29/21 | I2772: 20:30:00 | J2772: 15608 | K2772: 180 | L2772: 4004
H2773: 11/29/21 | I2773: 20:45:00 | J2773: 15427 | K2773: 227 | L2773: 3998
H2774: 11/29/21 | I2774: 21:00:00 | J2774: 15804 | K2774: 561 | L2774: 4006
H2775: 11/29/21 | I2775: 21:15:00 | J2775: 15207 | K2775: 1038 | L2775: 4007
H2776: 11/29/21 | I2776: 21:30:00 | J2776: 12762 | K2776: 73 | L2776: 4006
H2777: 11/29/21 | I2777: 21:45:00 | J2777: 12734 | K2777: 150 | L2777: 4000
...

Sheet DHS2022
A1: $Date | B1: $Time | C1: IIN_LEISTUNG-NETZ | D1: IIN_LEISTUNG-REGELKUEHLKREIS | E1: IIAN_DTU_GEN_WIRKLEISTUNG | G1: 15min. | H1: $Date | I1: $Time | J1: IIN_LEISTUNG-NETZ | K1: IIN_LEISTUNG-REGELKUEHLKREIS | L1: IIAN_DTU_GEN_WIRKLEISTUNG
A2: 01//22 | B2: 00:00:00 | H2: 11/01/22 | I2: 00:00:00 | J2: 1615 | K2: 104 | L2: 7808
A3: 01//22 | B3: 01:00:00 | H3: 11/01/22 | I3: 00:15:00 | J3: 1702 | K3: 214 | L3: 7794
A4: 01//22 | B4: 02:00:00 | H4: 11/01/22 | I4: 00:30:00 | J4: 1625 | K4: 108 | L4: 7799
A5: 01//22 | B5: 03:00:00 | H5: 11/01/22 | I5: 00:45:00 | J5: 1523 | K5: 29 | L5: 7807
A6: 01//22 | B6: 04:00:00 | H6: 11/01/22 | I6: 01:00:00 | J6: 1545 | K6: 143 | L6: 7800
A7: 01//22 | B7: 05:00:00 | H7: 11/01/22 | I7: 01:15:00 | J7: 1699 | K7: 69 | L7: 7814
A8: 01//22 | B8: 06:00:00 | H8: 11/01/22 | I8: 01:30:00 | J8: 2010 | K8: 30 | L8: 7796
A9: 01//22 | B9: 07:00:00 | H9: 11/01/22 | I9: 01:45:00 | J9: 1808 | K9: 93 | L9: 7802
A10: 01//22 | B10: 08:00:00 | H10: 11/01/22 | I10: 02:00:00 | J10: 1597 | K10: 69 | L10: 7789
A11: 01//22 | B11: 09:00:00 | H11: 11/01/22 | I11: 02:15:00 | J11: 1835 | K11: 27 | L11: 7805
A12: 01//22 | B12: 10:00:00 | H12: 11/01/22 | I12: 02:30:00 | J12: 1971 | K12: 131 | L12: 7790
A13: 01//22 | B13: 11:00:00 | H13: 11/01/22 | I13: 02:45:00 | J13: 1843 | K13: 29 | L13: 7805
... A745: 31//22 | B745: 23:00:00 | H745: 11/08/22 | I745: 17:45:00 | J745: 10383 | K745: 110 | L745: 7811
H746: 11/08/22 | I746: 18:00:00 | J746: 10451 | K746: 82 | L746: 7802
H747: 11/08/22 | I747: 18:15:00 | J747: 10593 | K747: 127 | L747: 7799
H748: 11/08/22 | I748: 18:30:00 | J748: 10313 | K748: 66 | L748: 7781
H749: 11/08/22 | I749: 18:45:00 | J749: 10601 | K749: 184 | L749: 7799
H750: 11/08/22 | I750: 19:00:00 | J750: 10322 | K750: 116 | L750: 7798
H751: 11/08/22 | I751: 19:15:00 | J751: 9662 | K751: 79 | L751: 7730
H752: 11/08/22 | I752: 19:30:00 | J752: 10058 | K752: 82 | L752: 7522
H753: 11/08/22 | I753: 19:45:00 | J753: 10025 | K753: 31 | L753: 7685
H754: 11/08/22 | I754: 20:00:00 | J754: 10261 | K754: 73 | L754: 7829
H755: 11/08/22 | I755: 20:15:00 | J755: 10073 | K755: 61 | L755: 7806
H756: 11/08/22 | I756: 20:30:00 | J756: 10529 | K756: 87 | L756: 7803
H757: 11/08/22 | I757: 20:45:00 | J757: 10548 | K757: 83 | L757: 7798
... H2981: 10/31/22 | I2981: 23:45:00 | J2981: 1800 | K2981: 79 | L2981: 7733

Sheet DHS2023
A1: $Date | B1: $Time | C1: IIN_LEISTUNG-NETZ | D1: IIN_LEISTUNG-REGELKUEHLKREIS | E1: IIAN_DTU_GEN_WIRKLEISTUNG | G1: 15min. | H1: $Date | I1: $Time | J1: IIN_LEISTUNG-NETZ | K1: IIN_LEISTUNG-REGELKUEHLKREIS | L1: IIAN_DTU_GEN_WIRKLEISTUNG
A2: 01//23 | B2: 00:00:00 | H2: 11/01/23 | I2: 00:00:00 | J2: 1714 | K2: 8672 | L2: 3014
A3: 01//23 | B3: 01:00:00 | H3: 11/01/23 | I3: 00:15:00 | J3: 1864 | K3: 8472 | L3: 2990
A4: 01//23 | B4: 02:00:00 | H4: 11/01/23 | I4: 00:30:00 | J4: 2079 | K4: 7969 | L4: 2998
A5: 01//23 | B5: 03:00:00 | H5: 11/01/23 | I5: 00:45:00 | J5: 2281 | K5: 8532 | L5: 3006
A6: 01//23 | B6: 04:00:00 | H6: 11/01/23 | I6: 01:00:00 | J6: 2244 | K6: 8042 | L6: 3005
A7: 01//23 | B7: 05:00:00 | H7: 11/01/23 | I7: 01:15:00 | J7: 2097 | K7: 8373 | L7: 2991
A8: 01//23 | B8: 06:00:00 | H8: 11/01/23 | I8: 01:30:00 | J8: 2104 | K8: 9028 | L8: 3018
A9: 01//23 | B9: 07:00:00 | H9: 11/01/23 | I9: 01:45:00 | J9: 2053 | K9: 8777 | L9: 2999
A10: 01//23 | B10: 08:00:00 | H10: 11/01/23 | I10: 02:00:00 | J10: 1949 | K10: 8899 | L10: 3012
A11: 01//23 | B11: 09:00:00 | H11: 11/01/23 | I11: 02:15:00 | J11: 2239 | K11: 8001 | L11: 3000
A12: 01//23 | B12: 10:00:00 | H12: 11/01/23 | I12: 02:30:00 | J12: 2166 | K12: 7975 | L12: 2990
A13: 01//23 | B13: 11:00:00 | H13: 11/01/23 | I13: 02:45:00 | J13: 2209 | K13: 8282 | L13: 2996
... A745: 31//23 | B745: 23:00:00 | H745: 11/08/23 | I745: 17:45:00 | J745: 12429 | K745: 210 | L745: 3001
H746: 11/08/23 | I746: 18:00:00 | J746: 12179 | K746: 84 | L746: 2994
H747: 11/08/23 | I747: 18:15:00 | J747: 12248 | K747: 32 | L747: 2999
H748: 11/08/23 | I748: 18:30:00 | J748: 12296 | K748: 148 | L748: 2999
H749: 11/08/23 | I749: 18:45:00 | J749: 12322 | K749: 82 | L749: 3002
H750: 11/08/23 | I750: 19:00:00 | J750: 12390 | K750: 74 | L750: 3012
H751: 11/08/23 | I751: 19:15:00 | J751: 12298 | K751: 23 | L751: 3004
H752: 11/08/23 | I752: 19:30:00 | J752: 12550 | K752: 45 | L752: 3022
H753: 11/08/23 | I753: 19:45:00 | J753: 12471 | K753: 107 | L753: 3008
H754: 11/08/23 | I754: 20:00:00 | J754: 12532 | K754: 119 | L754: 2993
H755: 11/08/23 | I755: 20:15:00 | J755: 12420 | K755: 78 | L755: 3000
H756: 11/08/23 | I756: 20:30:00 | J756: 12391 | K756: 23 | L756: 2997
H757: 11/08/23 | I757: 20:45:00 | J757: 12714 | K757: 248 | L757: 2993
... H2978: 10/31/23 | I2978: 23:00:00 | J2978: 3351 | K2978: 6821 | L2978: 2999

Sheet DHS2024
A1: $Date | B1: $Time | C1: IIN_LEISTUNG-NETZ | D1: IIN_LEISTUNG-REGELKUEHLKREIS | E1: IIAN_DTU_GEN_WIRKLEISTUNG | G1: 15min. | H1: $Date | I1: $Time | J1: IIN_LEISTUNG-NETZ | K1: IIN_LEISTUNG-REGELKUEHLKREIS | L1: IIAN_DTU_GEN_WIRKLEISTUNG
A2: 01//24 | B2: 00:00:00 | H2: 11/01/24 | I2: 00:00:00 | J2: 2328 | K2: 20497 | L2: 7994
A3: 01//24 | B3: 01:00:00 | H3: 11/01/24 | I3: 00:15:00 | J3: 2200 | K3: 20545 | L3: 8005
A4: 01//24 | B4: 02:00:00 | H4: 11/01/24 | I4: 00:30:00 | J4: 2348 | K4: 20592 | L4: 8007
A5: 01//24 | B5: 03:00:00 | H5: 11/01/24 | I5: 00:45:00 | J5: 2238 | K5: 20276 | L5: 8001
A6: 01//24 | B6: 04:00:00 | H6: 11/01/24 | I6: 01:00:00 | J6: 2234 | K6: 20532 | L6: 7986
A7: 01//24 | B7: 05:00:00 | H7: 11/01/24 | I7: 01:15:00 | J7: 2151 | K7: 19911 | L7: 7999
A8: 01//24 | B8: 06:00:00 | H8: 11/01/24 | I8: 01:30:00 | J8: 3334 | K8: 19142 | L8: 8001
A9: 01//24 | B9: 07:00:00 | H9: 11/01/24 | I9: 01:45:00 | J9: 3031 | K9: 20076 | L9: 7990
A10: 01//24 | B10: 08:00:00 | H10: 11/01/24 | I10: 02:00:00 | J10: 2656 | K10: 20153 | L10: 8002
A11: 01//24 | B11: 09:00:00 | H11: 11/01/24 | I11: 02:15:00 | J11: 2515 | K11: 20091 | L11: 8001
A12: 01//24 | B12: 10:00:00 | H12: 11/01/24 | I12: 02:30:00 | J12: 2532 | K12: 20325 | L12: 7996
A13: 01//24 | B13: 11:00:00 | H13: 11/01/24 | I13: 02:45:00 | J13: 3423 | K13: 19091 | L13: 7996
... A745: 31//24 | B745: 23:00:00 | H745: 11/08/24 | I745: 17:45:00 | J745: 14513 | K745: 9713 | L745: 8000
H746: 11/08/24 | I746: 18:00:00 | J746: 14460 | K746: 9640 | L746: 8008
H747: 11/08/24 | I747: 18:15:00 | J747: 14845 | K747: 9863 | L747: 8004
H748: 11/08/24 | I748: 18:30:00 | J748: 14645 | K748: 9391 | L748: 8013
H749: 11/08/24 | I749: 18:45:00 | J749: 14299 | K749: 8996 | L749: 7985
H750: 11/08/24 | I750: 19:00:00 | J750: 14616 | K750: 9873 | L750: 8011
H751: 11/08/24 | I751: 19:15:00 | J751: 14997 | K751: 9878 | L751: 8007
H752: 11/08/24 | I752: 19:30:00 | J752: 14870 | K752: 9034 | L752: 7998
H753: 11/08/24 | I753: 19:45:00 | J753: 15333 | K753: 8674 | L753: 7996
H754: 11/08/24 | I754: 20:00:00 | J754: 15495 | K754: 9112 | L754: 8004
H755: 11/08/24 | I755: 20:15:00 | J755: 15322 | K755: 8124 | L755: 7998
H756: 11/08/24 | I756: 20:30:00 | J756: 15604 | K756: 9092 | L756: 8003
H757: 11/08/24 | I757: 20:45:00 | J757: 15830 | K757: 8280 | L757: 8004
... H2981: 10/31/24 | I2981: 23:45:00 | J2981: 2267 | K2981: 21000 | L2981: 8009

Sheet DHS2025
G1: 15min. | H1: $Date | I1: $Time | J1: Marič [MWh] | K1: Skutočnosť sieť [MWh] | L1: Skutočnosť EE [MW] | M1: Cena SK (EUR/MWh)
H2: 11/01/25 | I2: 00:00:00 | J2: 498582.3 | K2: 262970.2 | L2: 8.00142 | M2: 110.43
H3: 11/01/25 | I3: 00:15:00 | J3: 498587.1 | K3: 262971.3 | L3: 8.01396 | M3: 110
H4: 11/01/25 | I4: 00:30:00 | J4: 498591.6 | K4: 262972.7 | L4: 8.01147 | M4: 96.95
H5: 11/01/25 | I5: 00:45:00 | J5: 498595.9 | K5: 262974.2 | L5: 7.87629 | M5: 63.66
H6: 11/01/25 | I6: 01:00:00 | J6: 498600 | K6: 262975.9 | L6: 4.72164 | M6: 94.75
H7: 11/01/25 | I7: 01:15:00 | J7: 498601.9 | K7: 262977.9 | L7: 4.5363 | M7: 86.87
H8: 11/01/25 | I8: 01:30:00 | J8: 498603.9 | K8: 262979.6 | L8: 4.5429 | M8: 84.38
H9: 11/01/25 | I9: 01:45:00 | J9: 498606 | K9: 262981.1 | L9: 4.48245 | M9: 69.92
H10: 11/01/25 | I10: 02:00:00 | J10: 498608.1 | K10: 262982.6 | L10: 2.5806 | M10: 73.55
H11: 11/01/25 | I11: 02:15:00 | J11: 498608.9 | K11: 262984.3 | L11: 2.55075 | M11: 60.58
H12: 11/01/25 | I12: 02:30:00 | J12: 498609.3 | K12: 262986.5 | L12: 2.54772 | M12: 61.58
H13: 11/01/25 | I13: 02:45:00 | J13: 498609.3 | K13: 262988.9 | L13: 2.54916 | M13: 71.52
... H961: 11/10/25 | I961: 23:45:00 | J961: 500965 | K961: 265345.2 | L961: 4.45236 | M961: 89.78
H962: 45972 | I962: 00:00:00 | J962: 500968 | K962: 265345.8 | L962: 2.56038 | M962: 95.43
H963: 45972 | I963: 00:15:00 | J963: 500969.9 | K963: 265346.5 | L963: 2.53677 | M963: 89.98
H964: 45972 | I964: 00:30:00 | J964: 500971.7 | K964: 265347.1 | L964: 2.53623 | M964: 85.79
H965: 45972 | I965: 00:45:00 | J965: 500973.5 | K965: 265347.7 | L965: 2.53941 | M965: 83.29
H966: 45972 | I966: 01:00:00 | J966: 500975.4 | K966: 265348.3 | L966: 2.53584 | M966: 94.64
H967: 45972 | I967: 01:15:00 | J967: 500977.1 | K967: 265349 | L967: 2.53914 | M967: 85.95
H968: 45972 | I968: 01:30:00 | J968: 500978.9 | K968: 265349.7 | L968: 2.53821 | M968: 84.13
H969: 45972 | I969: 01:45:00 | J969: 500980.6 | K969: 265350.4 | L969: 2.5386 | M969: 83.15
H970: 45972 | I970: 02:00:00 | J970: 500982.4 | K970: 265351 | L970: 2.53794 | M970: 84.44
H971: 45972 | I971: 02:15:00 | J971: 500984 | K971: 265351.9 | L971: 2.53848 | M971: 82.87
H972: 45972 | I972: 02:30:00 | J972: 500985.6 | K972: 265352.8 | L972: 2.53677 | M972: 82.25
H973: 45972 | I973: 02:45:00 | J973: 500987.1 | K973: 265353.7 | L973: 2.70822 | M973: 86.32
... H1058: 46002 | I1058: 00:00:00 | J1058: 501196.3 | K1058: 265581.4 | L1058: 4.72122 | M1058: 91.58
H1059: 11/12/25 | I1059: 00:15:00 | J1059: 501199.3 | K1059: 265581.9 | L1059: 4.52139 | M1059: 90.55
H1060: 11/12/25 | I1060: 00:30:00 | J1060: 501202.3 | K1060: 265582.4 | L1060: 4.53114 | M1060: 111
H1061: 11/12/25 | I1061: 00:45:00 | J1061: 501205.2 | K1061: 265582.9 | L1061: 4.53576 | M1061: 102.54
H1062: 11/12/25 | I1062: 01:00:00 | J1062: 501208 | K1062: 265584.4 | L1062: 4.52442 | M1062: 97.94
H1063: 11/12/25 | I1063: 01:15:00 | J1063: 501210.9 | K1063: 265585.9 | L1063: 4.52904 | M1063: 96.47
H1064: 11/12/25 | I1064: 01:30:00 | J1064: 501213.8 | K1064: 265585.9 | L1064: 4.5309 | M1064: 90.5
H1065: 11/12/25 | I1065: 01:45:00 | J1065: 501216.7 | K1065: 265586.6 | L1065: 4.53432 | M1065: 97.27
H1066: 11/12/25 | I1066: 02:00:00 | J1066: 501219.5 | K1066: 265587.3 | L1066: 4.52496 | M1066: 97.35
H1067: 11/12/25 | I1067: 02:15:00 | J1067: 501222.4 | K1067: 265588.1 | L1067: 4.52838 | M1067: 90.84
H1068: 11/12/25 | I1068: 02:30:00 | J1068: 501225.3 | K1068: 265588.8 | L1068: 4.53393 | M1068: 87.96
H1069: 11/12/25 | I1069: 02:45:00 | J1069: 501228.2 | K1069: 265589.5 | L1069: 4.4418 | M1069: 95.44
H1070: 11/12/25 | I1070: 03:00:00 | J1070: 501231 | K1070: 265590.2 | L1070: 4.03338 | M1070: 83.54
... H2881: 11/30/25 | I2881: 23:45:00 | J2881: 505134 | K2881: 271252.8 | L2881: 7.93029 | M2881: 86.29
...
