Workbook

Sheet Porovnanie 15min.
C1: Dátum | D1: Čas | E1: Skutočnosť sieť [kWh] | F1: Marič [kWh] | G1: Plán EE [MW] | H1: Skutočnosť EE [MW] | I1: Cena SK (EUR/MWh) | J1: Tržby výroba EE | K1: Táto farba znamená plán
K2: Táto farba znamená skutočnosť
K3: Zobchodované na intraday
K4: Zmena plánu oproti pôvodnému
K5: Použitie redučky/bypasu | L5: Plán EE pôvodný | M5: Zobchodnovanie na intraday
C6: ='Predikcia 15min.'!A3 -> 45870 | D6: ='Predikcia 15min.'!B3 -> 00:00:00 | E6: ='Predikcia 15min.'!O3 -> 200 | F6: ='Predikcia 15min.'!P3 -> 2800 | G6: 4 | H6: ='Predikcia 15min.'!Q3/1000 -> 3.00522 | I6: ='Predikcia 15min.'!R3 -> 105.21 | J6: =(I6*0.99-1.9)*H6 -> 307.30749 | L6: ='Predikcia 15min.'!K3 -> 1 | M6: 4
C7: ='Predikcia 15min.'!A4 -> 45870 | D7: ='Predikcia 15min.'!B4 -> 0.010416667 | E7: ='Predikcia 15min.'!O4 -> 100 | F7: ='Predikcia 15min.'!P4 -> 2800 | G7: 4 | H7: ='Predikcia 15min.'!Q4/1000 -> 0 | I7: ='Predikcia 15min.'!R4 -> 105.21 | J7: =(I7*0.99-1.9)*H7 -> 0 | L7: ='Predikcia 15min.'!K4 -> 1 | M7: 4
C8: ='Predikcia 15min.'!A5 -> 45870 | D8: ='Predikcia 15min.'!B5 -> 0.020833333 | E8: ='Predikcia 15min.'!O5 -> 200 | F8: ='Predikcia 15min.'!P5 -> 3100 | G8: 4 | H8: ='Predikcia 15min.'!Q5/1000 -> 0.56442 | I8: ='Predikcia 15min.'!R5 -> 105.21 | J8: =(I8*0.99-1.9)*H8 -> 57.716404 | L8: ='Predikcia 15min.'!K5 -> 1 | M8: 4
C9: ='Predikcia 15min.'!A6 -> 45870 | D9: ='Predikcia 15min.'!B6 -> 0.03125 | E9: ='Predikcia 15min.'!O6 -> 200 | F9: ='Predikcia 15min.'!P6 -> 3500 | G9: 4 | H9: ='Predikcia 15min.'!Q6/1000 -> 3.2844 | I9: ='Predikcia 15min.'!R6 -> 105.21 | J9: =(I9*0.99-1.9)*H9 -> 335.85585 | L9: ='Predikcia 15min.'!K6 -> 1 | M9: 4
C10: ='Predikcia 15min.'!A7 -> 45870 | D10: ='Predikcia 15min.'!B7 -> 0.041666667 | E10: ='Predikcia 15min.'!O7 -> 200 | F10: ='Predikcia 15min.'!P7 -> 3000 | G10: 4 | H10: ='Predikcia 15min.'!Q7/1000 -> 4.03524 | I10: ='Predikcia 15min.'!R7 -> 98.38 | J10: =(I10*0.99-1.9)*H10 -> 385.35009 | L10: ='Predikcia 15min.'!K7 -> 1 | M10: 4
C11: ='Predikcia 15min.'!A8 -> 45870 | D11: ='Predikcia 15min.'!B8 -> 0.052083333 | E11: ='Predikcia 15min.'!O8 -> 200 | F11: ='Predikcia 15min.'!P8 -> 2800 | G11: 4 | H11: ='Predikcia 15min.'!Q8/1000 -> 4.04076 | I11: ='Predikcia 15min.'!R8 -> 98.38 | J11: =(I11*0.99-1.9)*H11 -> 385.87723 | L11: ='Predikcia 15min.'!K8 -> 1 | M11: 4
C12: ='Predikcia 15min.'!A9 -> 45870 | D12: ='Predikcia 15min.'!B9 -> 0.0625 | E12: ='Predikcia 15min.'!O9 -> 300 | F12: ='Predikcia 15min.'!P9 -> 2800 | G12: 4 | H12: ='Predikcia 15min.'!Q9/1000 -> 4.038 | I12: ='Predikcia 15min.'!R9 -> 98.38 | J12: =(I12*0.99-1.9)*H12 -> 385.61366 | L12: ='Predikcia 15min.'!K9 -> 1 | M12: 4
C13: ='Predikcia 15min.'!A10 -> 45870 | D13: ='Predikcia 15min.'!B10 -> 0.072916667 | E13: ='Predikcia 15min.'!O10 -> 200 | F13: ='Predikcia 15min.'!P10 -> 2900 | G13: 4 | H13: ='Predikcia 15min.'!Q10/1000 -> 4.03062 | I13: ='Predikcia 15min.'!R10 -> 98.38 | J13: =(I13*0.99-1.9)*H13 -> 384.90889 | L13: ='Predikcia 15min.'!K10 -> 1 | M13: 4
C14: ='Predikcia 15min.'!A11 -> 45870 | D14: ='Predikcia 15min.'!B11 -> 0.083333333 | E14: ='Predikcia 15min.'!O11 -> 100 | F14: ='Predikcia 15min.'!P11 -> 2800 | G14: 4 | H14: ='Predikcia 15min.'!Q11/1000 -> 4.03812 | I14: ='Predikcia 15min.'!R11 -> 91.74 | J14: =(I14*0.99-1.9)*H14 -> 359.08013 | L14: ='Predikcia 15min.'!K11 -> 1 | M14: 4
C15: ='Predikcia 15min.'!A12 -> 45870 | D15: ='Predikcia 15min.'!B12 -> 0.09375 | E15: ='Predikcia 15min.'!O12 -> 200 | F15: ='Predikcia 15min.'!P12 -> 2900 | G15: 4 | H15: ='Predikcia 15min.'!Q12/1000 -> 4.03218 | I15: ='Predikcia 15min.'!R12 -> 91.74 | J15: =(I15*0.99-1.9)*H15 -> 358.55193 | L15: ='Predikcia 15min.'!K12 -> 1 | M15: 4
C16: ='Predikcia 15min.'!A13 -> 45870 | D16: ='Predikcia 15min.'!B13 -> 0.10416667 | E16: ='Predikcia 15min.'!O13 -> 300 | F16: ='Predikcia 15min.'!P13 -> 2800 | G16: 4 | H16: ='Predikcia 15min.'!Q13/1000 -> 4.03854 | I16: ='Predikcia 15min.'!R13 -> 91.74 | J16: =(I16*0.99-1.9)*H16 -> 359.11748 | L16: ='Predikcia 15min.'!K13 -> 1 | M16: 4
C17: ='Predikcia 15min.'!A14 -> 45870 | D17: ='Predikcia 15min.'!B14 -> 0.11458333 | E17: ='Predikcia 15min.'!O14 -> 200 | F17: ='Predikcia 15min.'!P14 -> 2800 | G17: 4 | H17: ='Predikcia 15min.'!Q14/1000 -> 4.03272 | I17: ='Predikcia 15min.'!R14 -> 91.74 | J17: =(I17*0.99-1.9)*H17 -> 358.59995 | L17: ='Predikcia 15min.'!K14 -> 1 | M17: 4
... C2981: ='Predikcia 15min.'!A2978 -> 45900 | D2981: ='Predikcia 15min.'!B2978 -> 30.989583 | E2981: ='Predikcia 15min.'!O2978 -> 300 | F2981: ='Predikcia 15min.'!P2978 -> 5500 | G2981: 8 | H2981: ='Predikcia 15min.'!Q2978/1000 -> 7.89954 | I2981: ='Predikcia 15min.'!R2978 -> 91.86 | J2981: =(I2981*0.99-1.9)*H2981 -> 703.3861 | L2981: ='Predikcia 15min.'!K2978 -> 1 | M2981: 8

Sheet Predikcia 15min.
N1: Marič | O1: 2025 Skutočnosť
A2: $Date | B2: $Time | C2: 2021 | D2: 2022 | E2: 2023 | F2: 2024 | G2: Ø | H2: MW EE | I2: Marič | J2: ∑ | K2: PLÁN | L2: koef | M2: 3 | N2: 0 | O2: Sieť [kWh] | P2: Marič [kWh] | Q2: EE [kW] | R2: Cena SK (EUR/MWh) | S2: Tržby výroba EE | U2: Cena EE v hodinovom intervale
A3: 45870 | B3: 00:00:00 | C3: ='DHS2021'!J2 -> 713 | D3: ='DHS2022'!J2 -> 910 | E3: ='DHS2023'!J2 -> 533 | F3: ='DHS2024'!J2 -> 899 | G3: =AVERAGE(C3:F3) -> 763.75 | H3: =G3/$M$2/1000 -> 0.25458333 | I3: =$N$2 -> 0 | J3: =H3+I3 -> 0.25458333 | K3: =ROUNDUP(J3,0) -> 1 | O3: =('DHS2025'!K3-'DHS2025'!K2)*1000 -> 200 | P3: =('DHS2025'!J3-'DHS2025'!J2)*1000 -> 2800 | Q3: ='DHS2025'!L2*1000 -> 3005.22 | R3: =INDEX(U$3:U$1048576,INT((ROW()-3)/4)+1) -> 105.21 | S3: =(R3*0.99-1.9)*(Q3/1000) -> 307.30749 | U3: 105.21
A4: =$A$3+INT((ROW()-3)/96) -> 45870 | B4: =B3+TIME(0,15,0) -> 0.010416667 | C4: ='DHS2021'!J3 -> 576 | D4: ='DHS2022'!J3 -> 917 | E4: ='DHS2023'!J3 -> 561 | F4: ='DHS2024'!J3 -> 661 | G4: =AVERAGE(C4:F4) -> 678.75 | H4: =G4/$M$2/1000 -> 0.22625 | I4: =$N$2 -> 0 | J4: =H4+I4 -> 0.22625 | K4: =ROUNDUP(J4,0) -> 1 | O4: =('DHS2025'!K4-'DHS2025'!K3)*1000 -> 100 | P4: =('DHS2025'!J4-'DHS2025'!J3)*1000 -> 2800 | Q4: ='DHS2025'!L3*1000 -> 0 | R4: =INDEX(U$3:U$1048576,INT((ROW()-3)/4)+1) -> 105.21 | S4: =(R4*0.99-1.9)*(Q4/1000) -> 0 | U4: 98.38
A5: =$A$3+INT((ROW()-3)/96) -> 45870 | B5: =B4+TIME(0,15,0) -> 0.020833333 | C5: ='DHS2021'!J4 -> 776 | D5: ='DHS2022'!J4 -> 986 | E5: ='DHS2023'!J4 -> 582 | F5: ='DHS2024'!J4 -> 747 | G5: =AVERAGE(C5:F5) -> 772.75 | H5: =G5/$M$2/1000 -> 0.25758333 | I5: =$N$2 -> 0 | J5: =H5+I5 -> 0.25758333 | K5: =ROUNDUP(J5,0) -> 1 | O5: =('DHS2025'!K5-'DHS2025'!K4)*1000 -> 200 | P5: =('DHS2025'!J5-'DHS2025'!J4)*1000 -> 3100 | Q5: ='DHS2025'!L4*1000 -> 564.42 | R5: =INDEX(U$3:U$1048576,INT((ROW()-3)/4)+1) -> 105.21 | S5: =(R5*0.99-1.9)*(Q5/1000) -> 57.716404 | U5: 91.74
A6: =$A$3+INT((ROW()-3)/96) -> 45870 | B6: =B5+TIME(0,15,0) -> 0.03125 | C6: ='DHS2021'!J5 -> 688 | D6: ='DHS2022'!J5 -> 907 | E6: ='DHS2023'!J5 -> 574 | F6: ='DHS2024'!J5 -> 523 | G6: =AVERAGE(C6:F6) -> 673 | H6: =G6/$M$2/1000 -> 0.22433333 | I6: =$N$2 -> 0 | J6: =H6+I6 -> 0.22433333 | K6: =ROUNDUP(J6,0) -> 1 | O6: =('DHS2025'!K6-'DHS2025'!K5)*1000 -> 200 | P6: =('DHS2025'!J6-'DHS2025'!J5)*1000 -> 3500 | Q6: ='DHS2025'!L5*1000 -> 3284.4 | R6: =INDEX(U$3:U$1048576,INT((ROW()-3)/4)+1) -> 105.21 | S6: =(R6*0.99-1.9)*(Q6/1000) -> 335.85585 | U6: 87.98
A7: =$A$3+INT((ROW()-3)/96) -> 45870 | B7: =B6+TIME(0,15,0) -> 0.041666667 | C7: ='DHS2021'!J6 -> 750 | D7: ='DHS2022'!J6 -> 866 | E7: ='DHS2023'!J6 -> 610 | F7: ='DHS2024'!J6 -> 473 | G7: =AVERAGE(C7:F7) -> 674.75 | H7: =G7/$M$2/1000 -> 0.22491667 | I7: =$N$2 -> 0 | J7: =H7+I7 -> 0.22491667 | K7: =ROUNDUP(J7,0) -> 1 | O7: =('DHS2025'!K7-'DHS2025'!K6)*1000 -> 200 | P7: =('DHS2025'!J7-'DHS2025'!J6)*1000 -> 3000 | Q7: ='DHS2025'!L6*1000 -> 4035.24 | R7: =INDEX(U$3:U$1048576,INT((ROW()-3)/4)+1) -> 98.38 | S7: =(R7*0.99-1.9)*(Q7/1000) -> 385.35009 | U7: 93.62
A8: =$A$3+INT((ROW()-3)/96) -> 45870 | B8: =B7+TIME(0,15,0) -> 0.052083333 | C8: ='DHS2021'!J7 -> 739 | D8: ='DHS2022'!J7 -> 843 | E8: ='DHS2023'!J7 -> 518 | F8: ='DHS2024'!J7 -> 431 | G8: =AVERAGE(C8:F8) -> 632.75 | H8: =G8/$M$2/1000 -> 0.21091667 | I8: =$N$2 -> 0 | J8: =H8+I8 -> 0.21091667 | K8: =ROUNDUP(J8,0) -> 1 | O8: =('DHS2025'!K8-'DHS2025'!K7)*1000 -> 200 | P8: =('DHS2025'!J8-'DHS2025'!J7)*1000 -> 2800 | Q8: ='DHS2025'!L7*1000 -> 4040.76 | R8: =INDEX(U$3:U$1048576,INT((ROW()-3)/4)+1) -> 98.38 | S8: =(R8*0.99-1.9)*(Q8/1000) -> 385.87723 | U8: 100.52
A9: =$A$3+INT((ROW()-3)/96) -> 45870 | B9: =B8+TIME(0,15,0) -> 0.0625 | C9: ='DHS2021'!J8 -> 805 | D9: ='DHS2022'!J8 -> 886 | E9: ='DHS2023'!J8 -> 623 | F9: ='DHS2024'!J8 -> 608 | G9: =AVERAGE(C9:F9) -> 730.5 | H9: =G9/$M$2/1000 -> 0.2435 | I9: =$N$2 -> 0 | J9: =H9+I9 -> 0.2435 | K9: =ROUNDUP(J9,0) -> 1 | O9: =('DHS2025'!K9-'DHS2025'!K8)*1000 -> 300 | P9: =('DHS2025'!J9-'DHS2025'!J8)*1000 -> 2800 | Q9: ='DHS2025'!L8*1000 -> 4038 | R9: =INDEX(U$3:U$1048576,INT((ROW()-3)/4)+1) -> 98.38 | S9: =(R9*0.99-1.9)*(Q9/1000) -> 385.61366 | U9: 106.2
A10: =$A$3+INT((ROW()-3)/96) -> 45870 | B10: =B9+TIME(0,15,0) -> 0.072916667 | C10: ='DHS2021'!J9 -> 847 | D10: ='DHS2022'!J9 -> 807 | E10: ='DHS2023'!J9 -> 575 | F10: ='DHS2024'!J9 -> 644 | G10: =AVERAGE(C10:F10) -> 718.25 | H10: =G10/$M$2/1000 -> 0.23941667 | I10: =$N$2 -> 0 | J10: =H10+I10 -> 0.23941667 | K10: =ROUNDUP(J10,0) -> 1 | O10: =('DHS2025'!K10-'DHS2025'!K9)*1000 -> 200 | P10: =('DHS2025'!J10-'DHS2025'!J9)*1000 -> 2900 | Q10: ='DHS2025'!L9*1000 -> 4030.62 | R10: =INDEX(U$3:U$1048576,INT((ROW()-3)/4)+1) -> 98.38 | S10: =(R10*0.99-1.9)*(Q10/1000) -> 384.90889 | U10: 109.68
A11: =$A$3+INT((ROW()-3)/96) -> 45870 | B11: =B10+TIME(0,15,0) -> 0.083333333 | C11: ='DHS2021'!J10 -> 590 | D11: ='DHS2022'!J10 -> 939 | E11: ='DHS2023'!J10 -> 771 | F11: ='DHS2024'!J10 -> 684 | G11: =AVERAGE(C11:F11) -> 746 | H11: =G11/$M$2/1000 -> 0.24866667 | I11: =$N$2 -> 0 | J11: =H11+I11 -> 0.24866667 | K11: =ROUNDUP(J11,0) -> 1 | O11: =('DHS2025'!K11-'DHS2025'!K10)*1000 -> 100 | P11: =('DHS2025'!J11-'DHS2025'!J10)*1000 -> 2800 | Q11: ='DHS2025'!L10*1000 -> 4038.12 | R11: =INDEX(U$3:U$1048576,INT((ROW()-3)/4)+1) -> 91.74 | S11: =(R11*0.99-1.9)*(Q11/1000) -> 359.08013 | U11: 105.62
A12: =$A$3+INT((ROW()-3)/96) -> 45870 | B12: =B11+TIME(0,15,0) -> 0.09375 | C12: ='DHS2021'!J11 -> 720 | D12: ='DHS2022'!J11 -> 906 | E12: ='DHS2023'!J11 -> 777 | F12: ='DHS2024'!J11 -> 644 | G12: =AVERAGE(C12:F12) -> 761.75 | H12: =G12/$M$2/1000 -> 0.25391667 | I12: =$N$2 -> 0 | J12: =H12+I12 -> 0.25391667 | K12: =ROUNDUP(J12,0) -> 1 | O12: =('DHS2025'!K12-'DHS2025'!K11)*1000 -> 200 | P12: =('DHS2025'!J12-'DHS2025'!J11)*1000 -> 2900 | Q12: ='DHS2025'!L11*1000 -> 4032.18 | R12: =INDEX(U$3:U$1048576,INT((ROW()-3)/4)+1) -> 91.74 | S12: =(R12*0.99-1.9)*(Q12/1000) -> 358.55193 | U12: 95.25
A13: =$A$3+INT((ROW()-3)/96) -> 45870 | B13: =B12+TIME(0,15,0) -> 0.10416667 | C13: ='DHS2021'!J12 -> 642 | D13: ='DHS2022'!J12 -> 839 | E13: ='DHS2023'!J12 -> 668 | F13: ='DHS2024'!J12 -> 623 | G13: =AVERAGE(C13:F13) -> 693 | H13: =G13/$M$2/1000 -> 0.231 | I13: =$N$2 -> 0 | J13: =H13+I13 -> 0.231 | K13: =ROUNDUP(J13,0) -> 1 | O13: =('DHS2025'!K13-'DHS2025'!K12)*1000 -> 300 | P13: =('DHS2025'!J13-'DHS2025'!J12)*1000 -> 2800 | Q13: ='DHS2025'!L12*1000 -> 4038.54 | R13: =INDEX(U$3:U$1048576,INT((ROW()-3)/4)+1) -> 91.74 | S13: =(R13*0.99-1.9)*(Q13/1000) -> 359.11748 | U13: 68.67
A14: =$A$3+INT((ROW()-3)/96) -> 45870 | B14: =B13+TIME(0,15,0) -> 0.11458333 | C14: ='DHS2021'!J13 -> 620 | D14: ='DHS2022'!J13 -> 901 | E14: ='DHS2023'!J13 -> 639 | F14: ='DHS2024'!J13 -> 611 | G14: =AVERAGE(C14:F14) -> 692.75 | H14: =G14/$M$2/1000 -> 0.23091667 | I14: =$N$2 -> 0 | J14: =H14+I14 -> 0.23091667 | K14: =ROUNDUP(J14,0) -> 1 | O14: =('DHS2025'!K14-'DHS2025'!K13)*1000 -> 200 | P14: =('DHS2025'!J14-'DHS2025'!J13)*1000 -> 2800 | Q14: ='DHS2025'!L13*1000 -> 4032.72 | R14: =INDEX(U$3:U$1048576,INT((ROW()-3)/4)+1) -> 91.74 | S14: =(R14*0.99-1.9)*(Q14/1000) -> 358.59995 | U14: 68.21
A15: =$A$3+INT((ROW()-3)/96) -> 45870 | B15: =B14+TIME(0,15,0) -> 0.125 | C15: ='DHS2021'!J14 -> 626 | D15: ='DHS2022'!J14 -> 821 | E15: ='DHS2023'!J14 -> 757 | F15: ='DHS2024'!J14 -> 537 | G15: =AVERAGE(C15:F15) -> 685.25 | H15: =G15/$M$2/1000 -> 0.22841667 | I15: =$N$2 -> 0 | J15: =H15+I15 -> 0.22841667 | K15: =ROUNDUP(J15,0) -> 1 | O15: =('DHS2025'!K15-'DHS2025'!K14)*1000 -> 300 | P15: =('DHS2025'!J15-'DHS2025'!J14)*1000 -> 2800 | Q15: ='DHS2025'!L14*1000 -> 4034.82 | R15: =INDEX(U$3:U$1048576,INT((ROW()-3)/4)+1) -> 87.98 | S15: =(R15*0.99-1.9)*(Q15/1000) -> 343.76747 | U15: 68.81
... A746: =$A$3+INT((ROW()-3)/96) -> 45877 | B746: =B745+TIME(0,15,0) -> 7.7395833 | C746: ='DHS2021'!J745 -> 3070 | D746: ='DHS2022'!J745 -> 3367 | E746: ='DHS2023'!J745 -> 2420 | F746: ='DHS2024'!J745 -> 2510 | G746: =AVERAGE(C746:F746) -> 2841.75 | H746: =G746/$M$2/1000 -> 0.94725 | I746: =$N$2 -> 0 | J746: =H746+I746 -> 0.94725 | K746: =ROUNDUP(J746,0) -> 1 | O746: =('DHS2025'!K746-'DHS2025'!K745)*1000 -> 700 | P746: =('DHS2025'!J746-'DHS2025'!J745)*1000 -> 2300 | Q746: ='DHS2025'!L745*1000 -> 4043.94 | R746: =INDEX(U$3:U$1048576,INT((ROW()-3)/4)+1) -> 78.88 | S746: =(R746*0.99-1.9)*(Q746/1000) -> 308.11264 | U746: 91.86
A747: =$A$3+INT((ROW()-3)/96) -> 45877 | B747: =B746+TIME(0,15,0) -> 7.75 | C747: ='DHS2021'!J746 -> 3236 | D747: ='DHS2022'!J746 -> 3286 | E747: ='DHS2023'!J746 -> 3417 | F747: ='DHS2024'!J746 -> 2308 | G747: =AVERAGE(C747:F747) -> 3061.75 | H747: =G747/$M$2/1000 -> 1.0205833 | I747: =$N$2 -> 0 | J747: =H747+I747 -> 1.0205833 | K747: =ROUNDUP(J747,0) -> 2 | O747: =('DHS2025'!K747-'DHS2025'!K746)*1000 -> 700 | P747: =('DHS2025'!J747-'DHS2025'!J746)*1000 -> 2300 | Q747: ='DHS2025'!L746*1000 -> 4037.34 | R747: =INDEX(U$3:U$1048576,INT((ROW()-3)/4)+1) -> 113.77 | S747: =(R747*0.99-1.9)*(Q747/1000) -> 447.06394
A748: =$A$3+INT((ROW()-3)/96) -> 45877 | B748: =B747+TIME(0,15,0) -> 7.7604167 | C748: ='DHS2021'!J747 -> 2244 | D748: ='DHS2022'!J747 -> 3371 | E748: ='DHS2023'!J747 -> 3194 | F748: ='DHS2024'!J747 -> 2446 | G748: =AVERAGE(C748:F748) -> 2813.75 | H748: =G748/$M$2/1000 -> 0.93791667 | I748: =$N$2 -> 0 | J748: =H748+I748 -> 0.93791667 | K748: =ROUNDUP(J748,0) -> 1 | O748: =('DHS2025'!K748-'DHS2025'!K747)*1000 -> 800 | P748: =('DHS2025'!J748-'DHS2025'!J747)*1000 -> 2200 | Q748: ='DHS2025'!L747*1000 -> 3864.69 | R748: =INDEX(U$3:U$1048576,INT((ROW()-3)/4)+1) -> 113.77 | S748: =(R748*0.99-1.9)*(Q748/1000) -> 427.94601
A749: =$A$3+INT((ROW()-3)/96) -> 45877 | B749: =B748+TIME(0,15,0) -> 7.7708333 | C749: ='DHS2021'!J748 -> 2630 | D749: ='DHS2022'!J748 -> 3541 | E749: ='DHS2023'!J748 -> 3644 | F749: ='DHS2024'!J748 -> 2304 | G749: =AVERAGE(C749:F749) -> 3029.75 | H749: =G749/$M$2/1000 -> 1.0099167 | I749: =$N$2 -> 0 | J749: =H749+I749 -> 1.0099167 | K749: =ROUNDUP(J749,0) -> 2 | O749: =('DHS2025'!K749-'DHS2025'!K748)*1000 -> 800 | P749: =('DHS2025'!J749-'DHS2025'!J748)*1000 -> 2300 | Q749: ='DHS2025'!L748*1000 -> 4032.72 | R749: =INDEX(U$3:U$1048576,INT((ROW()-3)/4)+1) -> 113.77 | S749: =(R749*0.99-1.9)*(Q749/1000) -> 446.55236
A750: =$A$3+INT((ROW()-3)/96) -> 45877 | B750: =B749+TIME(0,15,0) -> 7.78125 | C750: ='DHS2021'!J749 -> 2103 | D750: ='DHS2022'!J749 -> 3542 | E750: ='DHS2023'!J749 -> 3693 | F750: ='DHS2024'!J749 -> 1768 | G750: =AVERAGE(C750:F750) -> 2776.5 | H750: =G750/$M$2/1000 -> 0.9255 | I750: =$N$2 -> 0 | J750: =H750+I750 -> 0.9255 | K750: =ROUNDUP(J750,0) -> 1 | O750: =('DHS2025'!K750-'DHS2025'!K749)*1000 -> 700 | P750: =('DHS2025'!J750-'DHS2025'!J749)*1000 -> 2300 | Q750: ='DHS2025'!L749*1000 -> 4049.76 | R750: =INDEX(U$3:U$1048576,INT((ROW()-3)/4)+1) -> 113.77 | S750: =(R750*0.99-1.9)*(Q750/1000) -> 448.43924
A751: =$A$3+INT((ROW()-3)/96) -> 45877 | B751: =B750+TIME(0,15,0) -> 7.7916667 | C751: ='DHS2021'!J750 -> 2154 | D751: ='DHS2022'!J750 -> 3744 | E751: ='DHS2023'!J750 -> 3091 | F751: ='DHS2024'!J750 -> 2462 | G751: =AVERAGE(C751:F751) -> 2862.75 | H751: =G751/$M$2/1000 -> 0.95425 | I751: =$N$2 -> 0 | J751: =H751+I751 -> 0.95425 | K751: =ROUNDUP(J751,0) -> 1 | O751: =('DHS2025'!K751-'DHS2025'!K750)*1000 -> 700 | P751: =('DHS2025'!J751-'DHS2025'!J750)*1000 -> 2300 | Q751: ='DHS2025'!L750*1000 -> 4046.97 | R751: =INDEX(U$3:U$1048576,INT((ROW()-3)/4)+1) -> 151.05 | S751: =(R751*0.99-1.9)*(Q751/1000) -> 597.49263
A752: =$A$3+INT((ROW()-3)/96) -> 45877 | B752: =B751+TIME(0,15,0) -> 7.8020833 | C752: ='DHS2021'!J751 -> 3017 | D752: ='DHS2022'!J751 -> 3528 | E752: ='DHS2023'!J751 -> 3133 | F752: ='DHS2024'!J751 -> 2536 | G752: =AVERAGE(C752:F752) -> 3053.5 | H752: =G752/$M$2/1000 -> 1.0178333 | I752: =$N$2 -> 0 | J752: =H752+I752 -> 1.0178333 | K752: =ROUNDUP(J752,0) -> 2 | O752: =('DHS2025'!K752-'DHS2025'!K751)*1000 -> 700 | P752: =('DHS2025'!J752-'DHS2025'!J751)*1000 -> 2400 | Q752: ='DHS2025'!L751*1000 -> 4050.54 | R752: =INDEX(U$3:U$1048576,INT((ROW()-3)/4)+1) -> 151.05 | S752: =(R752*0.99-1.9)*(Q752/1000) -> 598.0197
A753: =$A$3+INT((ROW()-3)/96) -> 45877 | B753: =B752+TIME(0,15,0) -> 7.8125 | C753: ='DHS2021'!J752 -> 3359 | D753: ='DHS2022'!J752 -> 3618 | E753: ='DHS2023'!J752 -> 2958 | F753: ='DHS2024'!J752 -> 3045 | G753: =AVERAGE(C753:F753) -> 3245 | H753: =G753/$M$2/1000 -> 1.0816667 | I753: =$N$2 -> 0 | J753: =H753+I753 -> 1.0816667 | K753: =ROUNDUP(J753,0) -> 2 | O753: =('DHS2025'!K753-'DHS2025'!K752)*1000 -> 700 | P753: =('DHS2025'!J753-'DHS2025'!J752)*1000 -> 2300 | Q753: ='DHS2025'!L752*1000 -> 4050 | R753: =INDEX(U$3:U$1048576,INT((ROW()-3)/4)+1) -> 151.05 | S753: =(R753*0.99-1.9)*(Q753/1000) -> 597.93998
A754: =$A$3+INT((ROW()-3)/96) -> 45877 | B754: =B753+TIME(0,15,0) -> 7.8229167 | C754: ='DHS2021'!J753 -> 3724 | D754: ='DHS2022'!J753 -> 3504 | E754: ='DHS2023'!J753 -> 2775 | F754: ='DHS2024'!J753 -> 3117 | G754: =AVERAGE(C754:F754) -> 3280 | H754: =G754/$M$2/1000 -> 1.0933333 | I754: =$N$2 -> 0 | J754: =H754+I754 -> 1.0933333 | K754: =ROUNDUP(J754,0) -> 2 | O754: =('DHS2025'!K754-'DHS2025'!K753)*1000 -> 700 | P754: =('DHS2025'!J754-'DHS2025'!J753)*1000 -> 2300 | Q754: ='DHS2025'!L753*1000 -> 4043.55 | R754: =INDEX(U$3:U$1048576,INT((ROW()-3)/4)+1) -> 151.05 | S754: =(R754*0.99-1.9)*(Q754/1000) -> 596.9877
A755: =$A$3+INT((ROW()-3)/96) -> 45877 | B755: =B754+TIME(0,15,0) -> 7.8333333 | C755: ='DHS2021'!J754 -> 4108 | D755: ='DHS2022'!J754 -> 3409 | E755: ='DHS2023'!J754 -> 3229 | F755: ='DHS2024'!J754 -> 3240 | G755: =AVERAGE(C755:F755) -> 3496.5 | H755: =G755/$M$2/1000 -> 1.1655 | I755: =$N$2 -> 0 | J755: =H755+I755 -> 1.1655 | K755: =ROUNDUP(J755,0) -> 2 | O755: =('DHS2025'!K755-'DHS2025'!K754)*1000 -> 700 | P755: =('DHS2025'!J755-'DHS2025'!J754)*1000 -> 2500 | Q755: ='DHS2025'!L754*1000 -> 4044.99 | R755: =INDEX(U$3:U$1048576,INT((ROW()-3)/4)+1) -> 192.13 | S755: =(R755*0.99-1.9)*(Q755/1000) -> 761.70681
A756: =$A$3+INT((ROW()-3)/96) -> 45877 | B756: =B755+TIME(0,15,0) -> 7.84375 | C756: ='DHS2021'!J755 -> 3538 | D756: ='DHS2022'!J755 -> 3290 | E756: ='DHS2023'!J755 -> 3115 | F756: ='DHS2024'!J755 -> 2974 | G756: =AVERAGE(C756:F756) -> 3229.25 | H756: =G756/$M$2/1000 -> 1.0764167 | I756: =$N$2 -> 0 | J756: =H756+I756 -> 1.0764167 | K756: =ROUNDUP(J756,0) -> 2 | O756: =('DHS2025'!K756-'DHS2025'!K755)*1000 -> 600 | P756: =('DHS2025'!J756-'DHS2025'!J755)*1000 -> 2400 | Q756: ='DHS2025'!L755*1000 -> 4048.95 | R756: =INDEX(U$3:U$1048576,INT((ROW()-3)/4)+1) -> 192.13 | S756: =(R756*0.99-1.9)*(Q756/1000) -> 762.45251
A757: =$A$3+INT((ROW()-3)/96) -> 45877 | B757: =B756+TIME(0,15,0) -> 7.8541667 | C757: ='DHS2021'!J756 -> 3200 | D757: ='DHS2022'!J756 -> 3719 | E757: ='DHS2023'!J756 -> 3335 | F757: ='DHS2024'!J756 -> 3300 | G757: =AVERAGE(C757:F757) -> 3388.5 | H757: =G757/$M$2/1000 -> 1.1295 | I757: =$N$2 -> 0 | J757: =H757+I757 -> 1.1295 | K757: =ROUNDUP(J757,0) -> 2 | O757: =('DHS2025'!K757-'DHS2025'!K756)*1000 -> 700 | P757: =('DHS2025'!J757-'DHS2025'!J756)*1000 -> 2400 | Q757: ='DHS2025'!L756*1000 -> 4049.76 | R757: =INDEX(U$3:U$1048576,INT((ROW()-3)/4)+1) -> 192.13 | S757: =(R757*0.99-1.9)*(Q757/1000) -> 762.60504
A758: =$A$3+INT((ROW()-3)/96) -> 45877 | B758: =B757+TIME(0,15,0) -> 7.8645833 | C758: ='DHS2021'!J757 -> 3511 | D758: ='DHS2022'!J757 -> 3396 | E758: ='DHS2023'!J757 -> 3344 | F758: ='DHS2024'!J757 -> 2891 | G758: =AVERAGE(C758:F758) -> 3285.5 | H758: =G758/$M$2/1000 -> 1.0951667 | I758: =$N$2 -> 0 | J758: =H758+I758 -> 1.0951667 | K758: =ROUNDUP(J758,0) -> 2 | O758: =('DHS2025'!K758-'DHS2025'!K757)*1000 -> 700 | P758: =('DHS2025'!J758-'DHS2025'!J757)*1000 -> 2300 | Q758: ='DHS2025'!L757*1000 -> 4044.33 | R758: =INDEX(U$3:U$1048576,INT((ROW()-3)/4)+1) -> 192.13 | S758: =(R758*0.99-1.9)*(Q758/1000) -> 761.58252
... A2978: =$A$3+INT((ROW()-3)/96) -> 45900 | B2978: =B2977+TIME(0,15,0) -> 30.989583 | C2978: ='DHS2021'!J2977 -> 1654 | D2978: ='DHS2022'!J2977 -> 1071 | E2978: ='DHS2023'!J2977 -> 969 | F2978: ='DHS2024'!J2977 -> 709 | G2978: =AVERAGE(C2978:F2978) -> 1100.75 | H2978: =G2978/$M$2/1000 -> 0.36691667 | I2978: =$N$2 -> 0 | J2978: =H2978+I2978 -> 0.36691667 | K2978: =ROUNDUP(J2978,0) -> 1 | O2978: =('DHS2025'!K2978-'DHS2025'!K2977)*1000 -> 300 | P2978: =('DHS2025'!J2978-'DHS2025'!J2977)*1000 -> 5500 | Q2978: ='DHS2025'!L2977*1000 -> 7899.54 | R2978: =INDEX(U$3:U$1048576,INT((ROW()-3)/4)+1) -> 91.86 | S2978: =(R2978*0.99-1.9)*(Q2978/1000) -> 703.3861

Sheet DHS2021
A1: $Date | B1: $Time | C1: IIN_LEISTUNG-NETZ | D1: IIN_LEISTUNG-REGELKUEHLKREIS | E1: IIAN_DTU_GEN_WIRKLEISTUNG | G1: 15min. | H1: $Date | I1: $Time | J1: IIN_LEISTUNG-NETZ | K1: IIN_LEISTUNG-REGELKUEHLKREIS | L1: IIAN_DTU_GEN_WIRKLEISTUNG
A2: 01//21 | B2: 00:00:00 | H2: 08/01/21 | I2: 00:00:00 | J2: 713 | K2: 11199 | L2: 3983
A3: 01//21 | B3: 01:00:00 | H3: 08/01/21 | I3: 00:15:00 | J3: 576 | K3: 11161 | L3: 4000
A4: 01//21 | B4: 02:00:00 | H4: 08/01/21 | I4: 00:30:00 | J4: 776 | K4: 11527 | L4: 4003
A5: 01//21 | B5: 03:00:00 | H5: 08/01/21 | I5: 00:45:00 | J5: 688 | K5: 11283 | L5: 4005
A6: 01//21 | B6: 04:00:00 | H6: 08/01/21 | I6: 01:00:00 | J6: 750 | K6: 11234 | L6: 3998
A7: 01//21 | B7: 05:00:00 | H7: 08/01/21 | I7: 01:15:00 | J7: 739 | K7: 11244 | L7: 4003
A8: 01//21 | B8: 06:00:00 | H8: 08/01/21 | I8: 01:30:00 | J8: 805 | K8: 10955 | L8: 4001
A9: 01//21 | B9: 07:00:00 | H9: 08/01/21 | I9: 01:45:00 | J9: 847 | K9: 11662 | L9: 4010
A10: 01//21 | B10: 08:00:00 | H10: 08/01/21 | I10: 02:00:00 | J10: 590 | K10: 11120 | L10: 3992
A11: 01//21 | B11: 09:00:00 | H11: 08/01/21 | I11: 02:15:00 | J11: 720 | K11: 10858 | L11: 3998
A12: 01//21 | B12: 10:00:00 | H12: 08/01/21 | I12: 02:30:00 | J12: 642 | K12: 11177 | L12: 3995
A13: 01//21 | B13: 11:00:00 | H13: 08/01/21 | I13: 02:45:00 | J13: 620 | K13: 11440 | L13: 3991
... A745: 31//21 | B745: 23:00:00 | H745: 08/08/21 | I745: 17:45:00 | J745: 3070 | K745: 57 | L745: 0
H746: 08/08/21 | I746: 18:00:00 | J746: 3236 | K746: 26 | L746: 0
H747: 08/08/21 | I747: 18:15:00 | J747: 2244 | K747: 66 | L747: 0
H748: 08/08/21 | I748: 18:30:00 | J748: 2630 | K748: 78 | L748: 0
H749: 08/08/21 | I749: 18:45:00 | J749: 2103 | K749: 73 | L749: 0
H750: 08/08/21 | I750: 19:00:00 | J750: 2154 | K750: 108 | L750: 0
H751: 08/08/21 | I751: 19:15:00 | J751: 3017 | K751: 71 | L751: 0
H752: 08/08/21 | I752: 19:30:00 | J752: 3359 | K752: 70 | L752: 0
H753: 08/08/21 | I753: 19:45:00 | J753: 3724 | K753: 86 | L753: 0
H754: 08/08/21 | I754: 20:00:00 | J754: 4108 | K754: 114 | L754: 0
H755: 08/08/21 | I755: 20:15:00 | J755: 3538 | K755: 55 | L755: 0
H756: 08/08/21 | I756: 20:30:00 | J756: 3200 | K756: 58 | L756: 0
H757: 08/08/21 | I757: 20:45:00 | J757: 3511 | K757: 59 | L757: 0
... H2977: 08/31/21 | I2977: 23:45:00 | J2977: 1654 | K2977: 62 | L2977: 0

Sheet DHS2022
A1: $Date | B1: $Time | C1: IIN_LEISTUNG-NETZ | D1: IIN_LEISTUNG-REGELKUEHLKREIS | E1: IIAN_DTU_GEN_WIRKLEISTUNG | G1: 15min. | H1: $Date | I1: $Time | J1: IIN_LEISTUNG-NETZ | K1: IIN_LEISTUNG-REGELKUEHLKREIS | L1: IIAN_DTU_GEN_WIRKLEISTUNG
A2: 01//22 | B2: 00:00:00 | H2: 08/01/22 | I2: 00:00:00 | J2: 910 | K2: 9926 | L2: 3511
A3: 01//22 | B3: 01:00:00 | H3: 08/01/22 | I3: 00:15:00 | J3: 917 | K3: 10315 | L3: 3509
A4: 01//22 | B4: 02:00:00 | H4: 08/01/22 | I4: 00:30:00 | J4: 986 | K4: 10624 | L4: 3513
A5: 01//22 | B5: 03:00:00 | H5: 08/01/22 | I5: 00:45:00 | J5: 907 | K5: 10044 | L5: 3504
A6: 01//22 | B6: 04:00:00 | H6: 08/01/22 | I6: 01:00:00 | J6: 866 | K6: 9522 | L6: 3488
A7: 01//22 | B7: 05:00:00 | H7: 08/01/22 | I7: 01:15:00 | J7: 843 | K7: 10066 | L7: 3525
A8: 01//22 | B8: 06:00:00 | H8: 08/01/22 | I8: 01:30:00 | J8: 886 | K8: 9843 | L8: 3498
A9: 01//22 | B9: 07:00:00 | H9: 08/01/22 | I9: 01:45:00 | J9: 807 | K9: 10145 | L9: 3499
A10: 01//22 | B10: 08:00:00 | H10: 08/01/22 | I10: 02:00:00 | J10: 939 | K10: 10523 | L10: 3505
A11: 01//22 | B11: 09:00:00 | H11: 08/01/22 | I11: 02:15:00 | J11: 906 | K11: 10564 | L11: 3504
A12: 01//22 | B12: 10:00:00 | H12: 08/01/22 | I12: 02:30:00 | J12: 839 | K12: 9748 | L12: 3496
A13: 01//22 | B13: 11:00:00 | H13: 08/01/22 | I13: 02:45:00 | J13: 901 | K13: 10134 | L13: 3497
... A745: 31//22 | B745: 23:00:00 | H745: 08/08/22 | I745: 17:45:00 | J745: 3367 | K745: 7389 | L745: 3491
H746: 08/08/22 | I746: 18:00:00 | J746: 3286 | K746: 7569 | L746: 3509
H747: 08/08/22 | I747: 18:15:00 | J747: 3371 | K747: 7784 | L747: 3508
H748: 08/08/22 | I748: 18:30:00 | J748: 3541 | K748: 6763 | L748: 3494
H749: 08/08/22 | I749: 18:45:00 | J749: 3542 | K749: 7107 | L749: 3486
H750: 08/08/22 | I750: 19:00:00 | J750: 3744 | K750: 7530 | L750: 3509
H751: 08/08/22 | I751: 19:15:00 | J751: 3528 | K751: 7787 | L751: 3511
H752: 08/08/22 | I752: 19:30:00 | J752: 3618 | K752: 6921 | L752: 3502
H753: 08/08/22 | I753: 19:45:00 | J753: 3504 | K753: 7565 | L753: 3508
H754: 08/08/22 | I754: 20:00:00 | J754: 3409 | K754: 7307 | L754: 3489
H755: 08/08/22 | I755: 20:15:00 | J755: 3290 | K755: 7507 | L755: 3510
H756: 08/08/22 | I756: 20:30:00 | J756: 3719 | K756: 7778 | L756: 3503
H757: 08/08/22 | I757: 20:45:00 | J757: 3396 | K757: 7165 | L757: 3508
... H2977: 08/31/22 | I2977: 23:45:00 | J2977: 1071 | K2977: 12 | L2977: 0

Sheet DHS2023
A1: $Date | B1: $Time | C1: IIN_LEISTUNG-NETZ | D1: IIN_LEISTUNG-REGELKUEHLKREIS | E1: IIAN_DTU_GEN_WIRKLEISTUNG | G1: 15min. | H1: $Date | I1: $Time | J1: IIN_LEISTUNG-NETZ | K1: IIN_LEISTUNG-REGELKUEHLKREIS | L1: IIAN_DTU_GEN_WIRKLEISTUNG
A2: 01//23 | B2: 00:00:00 | H2: 08/01/23 | I2: 00:00:00 | J2: 533 | K2: 9120 | L2: 2983
A3: 01//23 | B3: 01:00:00 | H3: 08/01/23 | I3: 00:15:00 | J3: 561 | K3: 9315 | L3: 2996
A4: 01//23 | B4: 02:00:00 | H4: 08/01/23 | I4: 00:30:00 | J4: 582 | K4: 8986 | L4: 2985
A5: 01//23 | B5: 03:00:00 | H5: 08/01/23 | I5: 00:45:00 | J5: 574 | K5: 9396 | L5: 3022
A6: 01//23 | B6: 04:00:00 | H6: 08/01/23 | I6: 01:00:00 | J6: 610 | K6: 9183 | L6: 2983
A7: 01//23 | B7: 05:00:00 | H7: 08/01/23 | I7: 01:15:00 | J7: 518 | K7: 9215 | L7: 2978
A8: 01//23 | B8: 06:00:00 | H8: 08/01/23 | I8: 01:30:00 | J8: 623 | K8: 9240 | L8: 3009
A9: 01//23 | B9: 07:00:00 | H9: 08/01/23 | I9: 01:45:00 | J9: 575 | K9: 9248 | L9: 3004
A10: 01//23 | B10: 08:00:00 | H10: 08/01/23 | I10: 02:00:00 | J10: 771 | K10: 9466 | L10: 3000
A11: 01//23 | B11: 09:00:00 | H11: 08/01/23 | I11: 02:15:00 | J11: 777 | K11: 9644 | L11: 3002
A12: 01//23 | B12: 10:00:00 | H12: 08/01/23 | I12: 02:30:00 | J12: 668 | K12: 9406 | L12: 3015
A13: 01//23 | B13: 11:00:00 | H13: 08/01/23 | I13: 02:45:00 | J13: 639 | K13: 9116 | L13: 3000
... A745: 31//23 | B745: 23:00:00 | H745: 08/08/23 | I745: 17:45:00 | J745: 2420 | K745: 78 | L745: 0
H746: 08/08/23 | I746: 18:00:00 | J746: 3417 | K746: 66 | L746: 0
H747: 08/08/23 | I747: 18:15:00 | J747: 3194 | K747: 59 | L747: 0
H748: 08/08/23 | I748: 18:30:00 | J748: 3644 | K748: 90 | L748: 0
H749: 08/08/23 | I749: 18:45:00 | J749: 3693 | K749: 93 | L749: 0
H750: 08/08/23 | I750: 19:00:00 | J750: 3091 | K750: 25 | L750: 0
H751: 08/08/23 | I751: 19:15:00 | J751: 3133 | K751: 67 | L751: 0
H752: 08/08/23 | I752: 19:30:00 | J752: 2958 | K752: 90 | L752: 0
H753: 08/08/23 | I753: 19:45:00 | J753: 2775 | K753: 78 | L753: 0
H754: 08/08/23 | I754: 20:00:00 | J754: 3229 | K754: 65 | L754: 0
H755: 08/08/23 | I755: 20:15:00 | J755: 3115 | K755: 78 | L755: 0
H756: 08/08/23 | I756: 20:30:00 | J756: 3335 | K756: 96 | L756: 0
H757: 08/08/23 | I757: 20:45:00 | J757: 3344 | K757: 209 | L757: 0
... H2977: 08/31/23 | I2977: 23:45:00 | J2977: 969 | K2977: 9092 | L2977: 3001

Sheet DHS2024
A1: $Date | B1: $Time | C1: IIN_LEISTUNG-NETZ | D1: IIN_LEISTUNG-REGELKUEHLKREIS | E1: IIAN_DTU_GEN_WIRKLEISTUNG | G1: 15min. | H1: $Date | I1: $Time | J1: IIN_LEISTUNG-NETZ | K1: IIN_LEISTUNG-REGELKUEHLKREIS | L1: IIAN_DTU_GEN_WIRKLEISTUNG
A2: 01//24 | B2: 00:00:00 | H2: 08/01/24 | I2: 00:00:00 | J2: 899 | K2: 22642 | L2: 8013
A3: 01//24 | B3: 01:00:00 | H3: 08/01/24 | I3: 00:15:00 | J3: 661 | K3: 22180 | L3: 7982
A4: 01//24 | B4: 02:00:00 | H4: 08/01/24 | I4: 00:30:00 | J4: 747 | K4: 22474 | L4: 8026
A5: 01//24 | B5: 03:00:00 | H5: 08/01/24 | I5: 00:45:00 | J5: 523 | K5: 22601 | L5: 8007
A6: 01//24 | B6: 04:00:00 | H6: 08/01/24 | I6: 01:00:00 | J6: 473 | K6: 23036 | L6: 7996
A7: 01//24 | B7: 05:00:00 | H7: 08/01/24 | I7: 01:15:00 | J7: 431 | K7: 22737 | L7: 7995
A8: 01//24 | B8: 06:00:00 | H8: 08/01/24 | I8: 01:30:00 | J8: 608 | K8: 22906 | L8: 8000
A9: 01//24 | B9: 07:00:00 | H9: 08/01/24 | I9: 01:45:00 | J9: 644 | K9: 22629 | L9: 8009
A10: 01//24 | B10: 08:00:00 | H10: 08/01/24 | I10: 02:00:00 | J10: 684 | K10: 22312 | L10: 7997
A11: 01//24 | B11: 09:00:00 | H11: 08/01/24 | I11: 02:15:00 | J11: 644 | K11: 22865 | L11: 7988
A12: 01//24 | B12: 10:00:00 | H12: 08/01/24 | I12: 02:30:00 | J12: 623 | K12: 22336 | L12: 7998
A13: 01//24 | B13: 11:00:00 | H13: 08/01/24 | I13: 02:45:00 | J13: 611 | K13: 22472 | L13: 8001
... A50: 03//24 | B50: 00:00:00 | H50: 08/01/24 | I50: 12:00:00 | J50: 2623 | K50: 20715 | L50: 8002
A51: 03//24 | B51: 01:00:00 | H51: 08/01/24 | I51: 12:15:00
A52: 03//24 | B52: 02:00:00 | H52: 08/01/24 | I52: 12:30:00
A53: 03//24 | B53: 03:00:00 | H53: 08/01/24 | I53: 12:45:00 | J53: 2780 | K53: 20520 | L53: 8000
A54: 03//24 | B54: 04:00:00 | H54: 08/01/24 | I54: 13:00:00 | J54: 2616 | K54: 21228 | L54: 7999
A55: 03//24 | B55: 05:00:00 | H55: 08/01/24 | I55: 13:15:00 | J55: 2779 | K55: 20312 | L55: 7996
A56: 03//24 | B56: 06:00:00 | H56: 08/01/24 | I56: 13:30:00 | J56: 2418 | K56: 20509 | L56: 8017
A57: 03//24 | B57: 07:00:00 | H57: 08/01/24 | I57: 13:45:00 | J57: 2325 | K57: 20796 | L57: 8003
A58: 03//24 | B58: 08:00:00 | H58: 08/01/24 | I58: 14:00:00 | J58: 2081 | K58: 20874 | L58: 8011
A59: 03//24 | B59: 09:00:00 | H59: 08/01/24 | I59: 14:15:00 | J59: 2070 | K59: 21833 | L59: 8005
A60: 03//24 | B60: 10:00:00 | H60: 08/01/24 | I60: 14:30:00 | J60: 3070 | K60: 19244 | L60: 7995
A61: 03//24 | B61: 11:00:00 | H61: 08/01/24 | I61: 14:45:00 | J61: 2955 | K61: 20113 | L61: 7990
A62: 03//24 | B62: 12:00:00 | H62: 08/01/24 | I62: 15:00:00 | J62: 2558 | K62: 20839 | L62: 8002
A63: 03//24 | B63: 13:00:00 | H63: 08/01/24 | I63: 15:15:00 | J63: 2923 | K63: 20047 | L63: 8004
A64: 03//24 | B64: 14:00:00 | H64: 08/01/24 | I64: 15:30:00 | J64: 2520 | K64: 21303 | L64: 7999
... A745: 31//24 | B745: 23:00:00 | H745: 08/08/24 | I745: 17:45:00 | J745: 2510 | K745: 20036 | L745: 7988
H746: 08/08/24 | I746: 18:00:00 | J746: 2308 | K746: 20532 | L746: 8013
H747: 08/08/24 | I747: 18:15:00 | J747: 2446 | K747: 21057 | L747: 7980
H748: 08/08/24 | I748: 18:30:00 | J748: 2304 | K748: 20965 | L748: 7999
H749: 08/08/24 | I749: 18:45:00 | J749: 1768 | K749: 20829 | L749: 7997
H750: 08/08/24 | I750: 19:00:00 | J750: 2462 | K750: 21057 | L750: 8010
H751: 08/08/24 | I751: 19:15:00 | J751: 2536 | K751: 19962 | L751: 7996
H752: 08/08/24 | I752: 19:30:00 | J752: 3045 | K752: 20069 | L752: 7995
H753: 08/08/24 | I753: 19:45:00 | J753: 3117 | K753: 20325 | L753: 8003
H754: 08/08/24 | I754: 20:00:00 | J754: 3240 | K754: 19669 | L754: 8002
H755: 08/08/24 | I755: 20:15:00 | J755: 2974 | K755: 20209 | L755: 8003
H756: 08/08/24 | I756: 20:30:00 | J756: 3300 | K756: 20004 | L756: 7943
...

Sheet DHS2025
A1: $Date | B1: $Time | C1: IIN_LEISTUNG-NETZ | D1: IIN_LEISTUNG-REGELKUEHLKREIS | E1: IIAN_DTU_GEN_WIRKLEISTUNG | G1: 15min. | H1: $Date | I1: $Time | J1: IIDATA_RKU_MWH | K1: IIDATA_N_MWH | L1: EE VSD
H2: 08/01/25 | I2: 00:00:00 | J2: 476662.3 | K2: 251673.9 | L2: 3.00522
H3: 08/01/25 | I3: 00:15:00 | J3: 476665.1 | K3: 251674.1 | L3: 0
H4: 08/01/25 | I4: 00:30:00 | J4: 476667.9 | K4: 251674.2 | L4: 0.56442
H5: 08/01/25 | I5: 00:45:00 | J5: 476671 | K5: 251674.4 | L5: 3.2844
H6: 08/01/25 | I6: 01:00:00 | J6: 476674.5 | K6: 251674.6 | L6: 4.03524
H7: 08/01/25 | I7: 01:15:00 | J7: 476677.5 | K7: 251674.8 | L7: 4.04076
H8: 08/01/25 | I8: 01:30:00 | J8: 476680.3 | K8: 251675 | L8: 4.038
H9: 08/01/25 | I9: 01:45:00 | J9: 476683.1 | K9: 251675.3 | L9: 4.03062
H10: 08/01/25 | I10: 02:00:00 | J10: 476686 | K10: 251675.5 | L10: 4.03812
H11: 08/01/25 | I11: 02:15:00 | J11: 476688.8 | K11: 251675.6 | L11: 4.03218
H12: 08/01/25 | I12: 02:30:00 | J12: 476691.7 | K12: 251675.8 | L12: 4.03854
H13: 08/01/25 | I13: 02:45:00 | J13: 476694.5 | K13: 251676.1 | L13: 4.03272
... H2978: 09/01/25 | I2978: 00:00:00 | J2978: 485306.5 | K2978: 253473.8 | L2978: 7.75
